Workbook

Sheet 一图流
A2: 宇通客车：巴菲特框架个股调研与安全边际 | B2: 宇通客车：巴菲特框架个股调研与安全边际 | C2: 宇通客车：巴菲特框架个股调研与安全边际 | D2: 宇通客车：巴菲特框架个股调研与安全边际 | E2: 宇通客车：巴菲特框架个股调研与安全边际 | F2: 宇通客车：巴菲特框架个股调研与安全边际 | G2: 宇通客车：巴菲特框架个股调研与安全边际 | H2: 宇通客车：巴菲特框架个股调研与安全边际 | I2: 宇通客车：巴菲特框架个股调研与安全边际 | J2: 宇通客车：巴菲特框架个股调研与安全边际 | K2: 宇通客车：巴菲特框架个股调研与安全边际 | L2: 宇通客车：巴菲特框架个股调研与安全边际 | M2: 宇通客车：巴菲特框架个股调研与安全边际 | N2: 宇通客车：巴菲特框架个股调研与安全边际
A3: 以最新披露的2026年三季报和9月产销快报为核心；行情抓取于 2026/10/16 16:11:44。情景： | B3: 以最新披露的2026年三季报和9月产销快报为核心；行情抓取于 2026/10/16 16:11:44。情景： | C3: 以最新披露的2026年三季报和9月产销快报为核心；行情抓取于 2026/10/16 16:11:44。情景： | D3: 以最新披露的2026年三季报和9月产销快报为核心；行情抓取于 2026/10/16 16:11:44。情景： | E3: 以最新披露的2026年三季报和9月产销快报为核心；行情抓取于 2026/10/16 16:11:44。情景： | F3: 以最新披露的2026年三季报和9月产销快报为核心；行情抓取于 2026/10/16 16:11:44。情景： | G3: 以最新披露的2026年三季报和9月产销快报为核心；行情抓取于 2026/10/16 16:11:44。情景： | H3: 以最新披露的2026年三季报和9月产销快报为核心；行情抓取于 2026/10/16 16:11:44。情景： | I3: 以最新披露的2026年三季报和9月产销快报为核心；行情抓取于 2026/10/16 16:11:44。情景： | J3: 以最新披露的2026年三季报和9月产销快报为核心；行情抓取于 2026/10/16 16:11:44。情景： | K3: 以最新披露的2026年三季报和9月产销快报为核心；行情抓取于 2026/10/16 16:11:44。情景： | L3: 以最新披露的2026年三季报和9月产销快报为核心；行情抓取于 2026/10/16 16:11:44。情景： | M3: 以最新披露的2026年三季报和9月产销快报为核心；行情抓取于 2026/10/16 16:11:44。情景： | N3: =估值模型!F5 -> 基准
A5: 当前价（元） | B5: 当前价（元） | C5: 当前价（元） | D5: 基准内在价值（元） | E5: 基准内在价值（元） | F5: 基准内在价值（元） | G5: 基准安全边际 | H5: 基准安全边际 | I5: 基准安全边际 | J5: 35%安全边际买入价（元） | K5: 35%安全边际买入价（元） | L5: 35%安全边际买入价（元） | M5: 当前动作 | N5: 当前动作
A6: =数据与来源!B7 -> 28.71 | D6: =估值模型!F27 -> 31.066391 | G6: =估值模型!F28 -> 0.075850178 | J6: =估值模型!F29 -> 20.193154 | M6: =IF(G6>=30%,"可分批",IF(G6>=20%,"小仓",IF(G6>=10%,"观察","等待"))) -> 等待
A10: 结论：继续观察，不追高。宇通是客车龙头，海外、产品结构与成本能力让其扣非利润在销量下滑时仍能增长；但当前折价不足以覆盖海外周期、汇率、质保和客户融资担保风险。 | B10: 结论：继续观察，不追高。宇通是客车龙头，海外、产品结构与成本能力让其扣非利润在销量下滑时仍能增长；但当前折价不足以覆盖海外周期、汇率、质保和客户融资担保风险。 | C10: 结论：继续观察，不追高。宇通是客车龙头，海外、产品结构与成本能力让其扣非利润在销量下滑时仍能增长；但当前折价不足以覆盖海外周期、汇率、质保和客户融资担保风险。 | D10: 结论：继续观察，不追高。宇通是客车龙头，海外、产品结构与成本能力让其扣非利润在销量下滑时仍能增长；但当前折价不足以覆盖海外周期、汇率、质保和客户融资担保风险。 | E10: 结论：继续观察，不追高。宇通是客车龙头，海外、产品结构与成本能力让其扣非利润在销量下滑时仍能增长；但当前折价不足以覆盖海外周期、汇率、质保和客户融资担保风险。 | F10: 结论：继续观察，不追高。宇通是客车龙头，海外、产品结构与成本能力让其扣非利润在销量下滑时仍能增长；但当前折价不足以覆盖海外周期、汇率、质保和客户融资担保风险。 | G10: 结论：继续观察，不追高。宇通是客车龙头，海外、产品结构与成本能力让其扣非利润在销量下滑时仍能增长；但当前折价不足以覆盖海外周期、汇率、质保和客户融资担保风险。 | H10: 结论：继续观察，不追高。宇通是客车龙头，海外、产品结构与成本能力让其扣非利润在销量下滑时仍能增长；但当前折价不足以覆盖海外周期、汇率、质保和客户融资担保风险。 | I10: 结论：继续观察，不追高。宇通是客车龙头，海外、产品结构与成本能力让其扣非利润在销量下滑时仍能增长；但当前折价不足以覆盖海外周期、汇率、质保和客户融资担保风险。 | J10: 结论：继续观察，不追高。宇通是客车龙头，海外、产品结构与成本能力让其扣非利润在销量下滑时仍能增长；但当前折价不足以覆盖海外周期、汇率、质保和客户融资担保风险。 | K10: 结论：继续观察，不追高。宇通是客车龙头，海外、产品结构与成本能力让其扣非利润在销量下滑时仍能增长；但当前折价不足以覆盖海外周期、汇率、质保和客户融资担保风险。 | L10: 结论：继续观察，不追高。宇通是客车龙头，海外、产品结构与成本能力让其扣非利润在销量下滑时仍能增长；但当前折价不足以覆盖海外周期、汇率、质保和客户融资担保风险。 | M10: 结论：继续观察，不追高。宇通是客车龙头，海外、产品结构与成本能力让其扣非利润在销量下滑时仍能增长；但当前折价不足以覆盖海外周期、汇率、质保和客户融资担保风险。 | N10: 结论：继续观察，不追高。宇通是客车龙头，海外、产品结构与成本能力让其扣非利润在销量下滑时仍能增长；但当前折价不足以覆盖海外周期、汇率、质保和客户融资担保风险。
A11: 结论：继续观察，不追高。宇通是客车龙头，海外、产品结构与成本能力让其扣非利润在销量下滑时仍能增长；但当前折价不足以覆盖海外周期、汇率、质保和客户融资担保风险。 | B11: 结论：继续观察，不追高。宇通是客车龙头，海外、产品结构与成本能力让其扣非利润在销量下滑时仍能增长；但当前折价不足以覆盖海外周期、汇率、质保和客户融资担保风险。 | C11: 结论：继续观察，不追高。宇通是客车龙头，海外、产品结构与成本能力让其扣非利润在销量下滑时仍能增长；但当前折价不足以覆盖海外周期、汇率、质保和客户融资担保风险。 | D11: 结论：继续观察，不追高。宇通是客车龙头，海外、产品结构与成本能力让其扣非利润在销量下滑时仍能增长；但当前折价不足以覆盖海外周期、汇率、质保和客户融资担保风险。 | E11: 结论：继续观察，不追高。宇通是客车龙头，海外、产品结构与成本能力让其扣非利润在销量下滑时仍能增长；但当前折价不足以覆盖海外周期、汇率、质保和客户融资担保风险。 | F11: 结论：继续观察，不追高。宇通是客车龙头，海外、产品结构与成本能力让其扣非利润在销量下滑时仍能增长；但当前折价不足以覆盖海外周期、汇率、质保和客户融资担保风险。 | G11: 结论：继续观察，不追高。宇通是客车龙头，海外、产品结构与成本能力让其扣非利润在销量下滑时仍能增长；但当前折价不足以覆盖海外周期、汇率、质保和客户融资担保风险。 | H11: 结论：继续观察，不追高。宇通是客车龙头，海外、产品结构与成本能力让其扣非利润在销量下滑时仍能增长；但当前折价不足以覆盖海外周期、汇率、质保和客户融资担保风险。 | I11: 结论：继续观察，不追高。宇通是客车龙头，海外、产品结构与成本能力让其扣非利润在销量下滑时仍能增长；但当前折价不足以覆盖海外周期、汇率、质保和客户融资担保风险。 | J11: 结论：继续观察，不追高。宇通是客车龙头，海外、产品结构与成本能力让其扣非利润在销量下滑时仍能增长；但当前折价不足以覆盖海外周期、汇率、质保和客户融资担保风险。 | K11: 结论：继续观察，不追高。宇通是客车龙头，海外、产品结构与成本能力让其扣非利润在销量下滑时仍能增长；但当前折价不足以覆盖海外周期、汇率、质保和客户融资担保风险。 | L11: 结论：继续观察，不追高。宇通是客车龙头，海外、产品结构与成本能力让其扣非利润在销量下滑时仍能增长；但当前折价不足以覆盖海外周期、汇率、质保和客户融资担保风险。 | M11: 结论：继续观察，不追高。宇通是客车龙头，海外、产品结构与成本能力让其扣非利润在销量下滑时仍能增长；但当前折价不足以覆盖海外周期、汇率、质保和客户融资担保风险。 | N11: 结论：继续观察，不追高。宇通是客车龙头，海外、产品结构与成本能力让其扣非利润在销量下滑时仍能增长；但当前折价不足以覆盖海外周期、汇率、质保和客户融资担保风险。
A13: 巴菲特8项快速筛选 | B13: 巴菲特8项快速筛选 | C13: 巴菲特8项快速筛选 | D13: 巴菲特8项快速筛选 | E13: 巴菲特8项快速筛选 | F13: 巴菲特8项快速筛选 | H13: 价格与三情景内在价值 | I13: 价格与三情景内在价值 | J13: 价格与三情景内在价值 | K13: 价格与三情景内在价值 | L13: 价格与三情景内在价值 | M13: 价格与三情景内在价值 | N13: 价格与三情景内在价值
A14: # | B14: 维度 | C14: 结果 | D14: 核心依据 | H14: 指标 | I14: 元/股
A15: 1 | B15: 能力圈 | C15: 通过 | D15: 收入来自客车销售，可追踪销量、单车价值和结构 | H15: 当前价 | I15: =数据与来源!B7 -> 28.71
A16: 2 | B16: 10年存续性 | C16: 通过 | D16: 客运需求长期存在，动力技术改变不消灭需求 | H16: 保守价值 | I16: =估值模型!E27 -> 18.205304
A17: 3 | B17: 护城河 | C17: 部分 | D17: 规模、品牌、研发、海外服务网络，但非不可复制 | H17: 基准价值 | I17: =估值模型!F27 -> 31.066391
A18: 4 | B18: 定价权 | C18: 部分 | D18: 招投标限制提价，高端与海外结构提供溢价 | H18: 积极价值 | I18: =估值模型!G27 -> 42.240647
A19: 5 | B19: 盈利质量 | C19: 通过 | D19: 十年累计现金转化高，单年波动需正常化
A20: 6 | B20: 债务安全 | C20: 通过 | D20: 净金融资产充足，营收降30%仍有缓冲
A21: 7 | B21: 管理诚信 | C21: 通过但监控 | D21: 无保留审计；关联交易、财务公司和担保需跟踪
A22: 8 | B22: 价格合理 | C22: 观察 | D22: 只有小幅折价，未达到要求安全边际
A24: 买价阶梯：基准情景 | B24: 买价阶梯：基准情景 | C24: 买价阶梯：基准情景 | D24: 买价阶梯：基准情景 | E24: 买价阶梯：基准情景 | F24: 买价阶梯：基准情景
A25: 档位 | B25: 价格 | C25: 较内在价值折价 | D25: 动作 | E25: 使用条件
A26: 当前 | B26: =数据与来源!B7 -> 28.71 | C26: =1-B26/估值模型!F27 -> 0.075850178 | D26: 观察 | E26: 相对估值不贵，但安全边际不足
A27: 首档 | B27: =估值模型!F27*(1-C27) -> 24.853113 | C27: 0.2 | D27: 极小仓 | E27: 基本面未恶化，且愿意承受周期波动
A28: 加仓档 | B28: =估值模型!F27*(1-C28) -> 23.299793 | C28: 0.25 | D28: 分批建仓 | E28: 销量、海外毛利率与现金回款仍成立
A29: 巴菲特档 | B29: =估值模型!F27*(1-C29) -> 20.193154 | C29: 0.35 | D29: 主要建仓 | E29: 先排除护城河破坏和治理问题
A30: 保守极限 | B30: =估值模型!F27*(1-C30) -> 17.086515 | C30: 0.45 | D30: 深度价值 | E30: 仅在悲观定价过度、公司仍健康时使用
A32: 核心数据 | B32: 核心数据 | C32: 核心数据 | D32: 核心数据 | E32: 核心数据 | F32: 核心数据
A33: 指标 | B33: 数值 | C33: 解读
A34: 2026Q1-3营收同比 | B34: -0.0209 | C34: 销量下滑拖累收入
A35: 2026Q1-3扣非净利同比 | B35: 0.1845 | C35: 产品/地区结构和成本改善
A36: 2026年1—9月销量同比 | B36: -0.0783 | C36: 大中客承压，轻客增长
A37: 2025年海外收入占主营比 | B37: 0.5781 | C37: 海外已是第一增长引擎 | H37: 最后一句 | I37: 最后一句 | J37: 最后一句 | K37: 最后一句 | L37: 最后一句 | M37: 最后一句 | N37: 最后一句
A38: 2025年大中客市占率 | B38: 0.3247 | C38: 龙头地位稳固 | H38: 好公司并不等于任何价格都是好投资。宇通当前更像“合理价格附近的好公司”，而不是“具有明显安全边际的机会”。 | I38: 好公司并不等于任何价格都是好投资。宇通当前更像“合理价格附近的好公司”，而不是“具有明显安全边际的机会”。 | J38: 好公司并不等于任何价格都是好投资。宇通当前更像“合理价格附近的好公司”，而不是“具有明显安全边际的机会”。 | K38: 好公司并不等于任何价格都是好投资。宇通当前更像“合理价格附近的好公司”，而不是“具有明显安全边际的机会”。 | L38: 好公司并不等于任何价格都是好投资。宇通当前更像“合理价格附近的好公司”，而不是“具有明显安全边际的机会”。 | M38: 好公司并不等于任何价格都是好投资。宇通当前更像“合理价格附近的好公司”，而不是“具有明显安全边际的机会”。 | N38: 好公司并不等于任何价格都是好投资。宇通当前更像“合理价格附近的好公司”，而不是“具有明显安全边际的机会”。
H39: 好公司并不等于任何价格都是好投资。宇通当前更像“合理价格附近的好公司”，而不是“具有明显安全边际的机会”。 | I39: 好公司并不等于任何价格都是好投资。宇通当前更像“合理价格附近的好公司”，而不是“具有明显安全边际的机会”。 | J39: 好公司并不等于任何价格都是好投资。宇通当前更像“合理价格附近的好公司”，而不是“具有明显安全边际的机会”。 | K39: 好公司并不等于任何价格都是好投资。宇通当前更像“合理价格附近的好公司”，而不是“具有明显安全边际的机会”。 | L39: 好公司并不等于任何价格都是好投资。宇通当前更像“合理价格附近的好公司”，而不是“具有明显安全边际的机会”。 | M39: 好公司并不等于任何价格都是好投资。宇通当前更像“合理价格附近的好公司”，而不是“具有明显安全边际的机会”。 | N39: 好公司并不等于任何价格都是好投资。宇通当前更像“合理价格附近的好公司”，而不是“具有明显安全边际的机会”。
H40: 好公司并不等于任何价格都是好投资。宇通当前更像“合理价格附近的好公司”，而不是“具有明显安全边际的机会”。 | I40: 好公司并不等于任何价格都是好投资。宇通当前更像“合理价格附近的好公司”，而不是“具有明显安全边际的机会”。 | J40: 好公司并不等于任何价格都是好投资。宇通当前更像“合理价格附近的好公司”，而不是“具有明显安全边际的机会”。 | K40: 好公司并不等于任何价格都是好投资。宇通当前更像“合理价格附近的好公司”，而不是“具有明显安全边际的机会”。 | L40: 好公司并不等于任何价格都是好投资。宇通当前更像“合理价格附近的好公司”，而不是“具有明显安全边际的机会”。 | M40: 好公司并不等于任何价格都是好投资。宇通当前更像“合理价格附近的好公司”，而不是“具有明显安全边际的机会”。 | N40: 好公司并不等于任何价格都是好投资。宇通当前更像“合理价格附近的好公司”，而不是“具有明显安全边际的机会”。
H41: 好公司并不等于任何价格都是好投资。宇通当前更像“合理价格附近的好公司”，而不是“具有明显安全边际的机会”。 | I41: 好公司并不等于任何价格都是好投资。宇通当前更像“合理价格附近的好公司”，而不是“具有明显安全边际的机会”。 | J41: 好公司并不等于任何价格都是好投资。宇通当前更像“合理价格附近的好公司”，而不是“具有明显安全边际的机会”。 | K41: 好公司并不等于任何价格都是好投资。宇通当前更像“合理价格附近的好公司”，而不是“具有明显安全边际的机会”。 | L41: 好公司并不等于任何价格都是好投资。宇通当前更像“合理价格附近的好公司”，而不是“具有明显安全边际的机会”。 | M41: 好公司并不等于任何价格都是好投资。宇通当前更像“合理价格附近的好公司”，而不是“具有明显安全边际的机会”。 | N41: 好公司并不等于任何价格都是好投资。宇通当前更像“合理价格附近的好公司”，而不是“具有明显安全边际的机会”。

Sheet 投资结论
A2: 宇通客车：投资结论 | B2: 宇通客车：投资结论 | C2: 宇通客车：投资结论 | D2: 宇通客车：投资结论 | E2: 宇通客车：投资结论 | F2: 宇通客车：投资结论 | G2: 宇通客车：投资结论 | H2: 宇通客车：投资结论 | I2: 宇通客车：投资结论 | J2: 宇通客车：投资结论 | K2: 宇通客车：投资结论 | L2: 宇通客车：投资结论
A3: 截至行情抓取时点的个股调研结论。情景： | B3: 截至行情抓取时点的个股调研结论。情景： | C3: 截至行情抓取时点的个股调研结论。情景： | D3: 截至行情抓取时点的个股调研结论。情景： | E3: 截至行情抓取时点的个股调研结论。情景： | F3: 截至行情抓取时点的个股调研结论。情景： | G3: 截至行情抓取时点的个股调研结论。情景： | H3: 截至行情抓取时点的个股调研结论。情景： | I3: 截至行情抓取时点的个股调研结论。情景： | J3: 截至行情抓取时点的个股调研结论。情景： | K3: 截至行情抓取时点的个股调研结论。情景： | L3: =估值模型!F5 -> 基准
A5: 结论 | B5: 结论 | C5: 结论 | D5: 结论 | E5: 结论 | F5: 结论 | G5: 结论 | H5: 结论 | I5: 结论 | J5: 结论 | K5: 结论 | L5: 结论
A6: 当前价 | E6: 内在价值 | I6: 继续观察。宇通是优质的客车龙头，但当前价与基准内在价值的差距不足以覆盖周期、汇率、质保和担保风险。 | J6: 继续观察。宇通是优质的客车龙头，但当前价与基准内在价值的差距不足以覆盖周期、汇率、质保和担保风险。 | K6: 继续观察。宇通是优质的客车龙头，但当前价与基准内在价值的差距不足以覆盖周期、汇率、质保和担保风险。 | L6: 继续观察。宇通是优质的客车龙头，但当前价与基准内在价值的差距不足以覆盖周期、汇率、质保和担保风险。
A7: =数据与来源!B7 -> 28.71 | E7: =估值模型!D27 -> 31.066391 | I7: 继续观察。宇通是优质的客车龙头，但当前价与基准内在价值的差距不足以覆盖周期、汇率、质保和担保风险。 | J7: 继续观察。宇通是优质的客车龙头，但当前价与基准内在价值的差距不足以覆盖周期、汇率、质保和担保风险。 | K7: 继续观察。宇通是优质的客车龙头，但当前价与基准内在价值的差距不足以覆盖周期、汇率、质保和担保风险。 | L7: 继续观察。宇通是优质的客车龙头，但当前价与基准内在价值的差距不足以覆盖周期、汇率、质保和担保风险。
A8: =IF(G8>=30%,"可分批买入",IF(G8>=20%,"小仓分批",IF(G8>=10%,"继续观察","等待更好买点"))) -> 等待更好买点 | E8: 安全边际 | G8: =估值模型!D28 -> 0.075850178 | I8: 继续观察。宇通是优质的客车龙头，但当前价与基准内在价值的差距不足以覆盖周期、汇率、质保和担保风险。 | J8: 继续观察。宇通是优质的客车龙头，但当前价与基准内在价值的差距不足以覆盖周期、汇率、质保和担保风险。 | K8: 继续观察。宇通是优质的客车龙头，但当前价与基准内在价值的差距不足以覆盖周期、汇率、质保和担保风险。 | L8: 继续观察。宇通是优质的客车龙头，但当前价与基准内在价值的差距不足以覆盖周期、汇率、质保和担保风险。
A10: 能力圈评估 | B10: 能力圈评估 | C10: 能力圈评估 | D10: 能力圈评估 | E10: 能力圈评估 | F10: 能力圈评估 | G10: 能力圈评估 | H10: 能力圈评估 | I10: 能力圈评估 | J10: 能力圈评估 | K10: 能力圈评估 | L10: 能力圈评估
A11: 能力圈内。公司通过销售大中轻型客车获取收入，利润受销量、单车价值、国内/海外结构、新能源渗透与成本控制影响。业务可解释，但订单和运营资本使单季度数据易波动。 | B11: 能力圈内。公司通过销售大中轻型客车获取收入，利润受销量、单车价值、国内/海外结构、新能源渗透与成本控制影响。业务可解释，但订单和运营资本使单季度数据易波动。 | C11: 能力圈内。公司通过销售大中轻型客车获取收入，利润受销量、单车价值、国内/海外结构、新能源渗透与成本控制影响。业务可解释，但订单和运营资本使单季度数据易波动。 | D11: 能力圈内。公司通过销售大中轻型客车获取收入，利润受销量、单车价值、国内/海外结构、新能源渗透与成本控制影响。业务可解释，但订单和运营资本使单季度数据易波动。 | E11: 能力圈内。公司通过销售大中轻型客车获取收入，利润受销量、单车价值、国内/海外结构、新能源渗透与成本控制影响。业务可解释，但订单和运营资本使单季度数据易波动。 | F11: 能力圈内。公司通过销售大中轻型客车获取收入，利润受销量、单车价值、国内/海外结构、新能源渗透与成本控制影响。业务可解释，但订单和运营资本使单季度数据易波动。 | G11: 能力圈内。公司通过销售大中轻型客车获取收入，利润受销量、单车价值、国内/海外结构、新能源渗透与成本控制影响。业务可解释，但订单和运营资本使单季度数据易波动。 | H11: 能力圈内。公司通过销售大中轻型客车获取收入，利润受销量、单车价值、国内/海外结构、新能源渗透与成本控制影响。业务可解释，但订单和运营资本使单季度数据易波动。 | I11: 能力圈内。公司通过销售大中轻型客车获取收入，利润受销量、单车价值、国内/海外结构、新能源渗透与成本控制影响。业务可解释，但订单和运营资本使单季度数据易波动。 | J11: 能力圈内。公司通过销售大中轻型客车获取收入，利润受销量、单车价值、国内/海外结构、新能源渗透与成本控制影响。业务可解释，但订单和运营资本使单季度数据易波动。 | K11: 能力圈内。公司通过销售大中轻型客车获取收入，利润受销量、单车价值、国内/海外结构、新能源渗透与成本控制影响。业务可解释，但订单和运营资本使单季度数据易波动。 | L11: 能力圈内。公司通过销售大中轻型客车获取收入，利润受销量、单车价值、国内/海外结构、新能源渗透与成本控制影响。业务可解释，但订单和运营资本使单季度数据易波动。
A12: 能力圈内。公司通过销售大中轻型客车获取收入，利润受销量、单车价值、国内/海外结构、新能源渗透与成本控制影响。业务可解释，但订单和运营资本使单季度数据易波动。 | B12: 能力圈内。公司通过销售大中轻型客车获取收入，利润受销量、单车价值、国内/海外结构、新能源渗透与成本控制影响。业务可解释，但订单和运营资本使单季度数据易波动。 | C12: 能力圈内。公司通过销售大中轻型客车获取收入，利润受销量、单车价值、国内/海外结构、新能源渗透与成本控制影响。业务可解释，但订单和运营资本使单季度数据易波动。 | D12: 能力圈内。公司通过销售大中轻型客车获取收入，利润受销量、单车价值、国内/海外结构、新能源渗透与成本控制影响。业务可解释，但订单和运营资本使单季度数据易波动。 | E12: 能力圈内。公司通过销售大中轻型客车获取收入，利润受销量、单车价值、国内/海外结构、新能源渗透与成本控制影响。业务可解释，但订单和运营资本使单季度数据易波动。 | F12: 能力圈内。公司通过销售大中轻型客车获取收入，利润受销量、单车价值、国内/海外结构、新能源渗透与成本控制影响。业务可解释，但订单和运营资本使单季度数据易波动。 | G12: 能力圈内。公司通过销售大中轻型客车获取收入，利润受销量、单车价值、国内/海外结构、新能源渗透与成本控制影响。业务可解释，但订单和运营资本使单季度数据易波动。 | H12: 能力圈内。公司通过销售大中轻型客车获取收入，利润受销量、单车价值、国内/海外结构、新能源渗透与成本控制影响。业务可解释，但订单和运营资本使单季度数据易波动。 | I12: 能力圈内。公司通过销售大中轻型客车获取收入，利润受销量、单车价值、国内/海外结构、新能源渗透与成本控制影响。业务可解释，但订单和运营资本使单季度数据易波动。 | J12: 能力圈内。公司通过销售大中轻型客车获取收入，利润受销量、单车价值、国内/海外结构、新能源渗透与成本控制影响。业务可解释，但订单和运营资本使单季度数据易波动。 | K12: 能力圈内。公司通过销售大中轻型客车获取收入，利润受销量、单车价值、国内/海外结构、新能源渗透与成本控制影响。业务可解释，但订单和运营资本使单季度数据易波动。 | L12: 能力圈内。公司通过销售大中轻型客车获取收入，利润受销量、单车价值、国内/海外结构、新能源渗透与成本控制影响。业务可解释，但订单和运营资本使单季度数据易波动。
A14: 关键假设 | B14: 关键假设 | C14: 关键假设 | D14: 关键假设 | E14: 关键假设 | F14: 关键假设 | G14: 关键假设 | H14: 关键假设 | I14: 关键假设 | J14: 关键假设 | K14: 关键假设 | L14: 关键假设
A15: 1 | B15: 海外客车需求在周期波动中仍能维持中低个位数增长，新能源与高价值产品占比不快速回落。
A16: 2 | B16: 公司能将销售毛利率维持在23%—25%附近，研发投入不被高分红挤压。
A17: 3 | B17: 正常化所有者收益约47亿元，而非直接使用2026Q1-3异常高的经营现金流。
A18: 4 | B18: 可持续每股现金分红约1.90元，低于2025财年的2.50元高点。
A19: 5 | B19: 净金融资产中只有80亿元可在基准情景计入估值，剩余部分作为运营和风险缓冲。
A21: 业务质量 | B21: 业务质量 | C21: 业务质量 | D21: 业务质量 | E21: 业务质量 | F21: 业务质量 | H21: 财务快照 | I21: 财务快照 | J21: 财务快照 | K21: 财务快照 | L21: 财务快照
A22: 维度 | B22: 评价 | C22: 结论 | H22: 指标 | I22: 值 | J22: 评价
A23: 护城河 | B23: 中等偏强 | C23: 规模、品牌、研发、海外服务网络；稳定偏扩宽 | H23: 10年平均ROE | I23: =财务十年!C6 -> 0.16946857 | J23: 优
A24: 管理层 | B24: 中上 | C24: 未见诚信否决项，资本配置偏股东回报 | H24: 10年平均近似ROIC | I24: =财务十年!E6 -> 0.29618075 | J24: 优，但受净现金调整影响
A25: 业务模式 | B25: 混合型 | C25: 优质制造业龙头，不是有无条件定价权的特许经营权 | H25: 累计现金转化率 | I25: =财务十年!G6 -> 1.3057913 | J25: 高，单年波动大
A26: 定价权 | B26: 有限 | C26: 招投标限制定价，海外与高端产品结构带来溢价 | H26: 正常化所有者收益 | I26: 47 | J26: 亿元，基准假设
A27: 制度性惯性 | B27: 轻度监控 | C27: 关联交易、财务公司、担保和非主业投资需跟踪 | H27: 债务安全 | I27: =数据与来源!B15 -> 126.0553 | J27: 净金融资产充足
A29: 估值与安全边际 | B29: 估值与安全边际 | C29: 估值与安全边际 | D29: 估值与安全边际 | E29: 估值与安全边际 | F29: 估值与安全边际 | G29: 估值与安全边际 | H29: 估值与安全边际 | I29: 估值与安全边际 | J29: 估值与安全边际 | K29: 估值与安全边际 | L29: 估值与安全边际
A30: 情景 | B30: 内在价值 | C30: 当前安全边际 | D30: 要求安全边际 | E30: 对应买入价 | F30: 使用建议
A31: 保守 | B31: =估值模型!E27 -> 18.205304 | C31: =估值模型!E28 -> -0.5770129 | D31: 0.45 | E31: =估值模型!E29 -> 10.012917 | F31: 只用于验证最坏情形，不以低估值自我安慰
A32: 基准 | B32: =估值模型!F27 -> 31.066391 | C32: =估值模型!F28 -> 0.075850178 | D32: 0.35 | E32: =估值模型!F29 -> 20.193154 | F32: 当前结论依据；只有接近要求买入价才有充分安全边际
A33: 积极 | B33: =估值模型!G27 -> 42.240647 | C33: =估值模型!G28 -> 0.32032292 | D33: 0.3 | E33: =估值模型!G29 -> 29.568453 | F33: 必须由海外高增长和保持高毛利率的事实验证
A34: 当前价格判断 | B34: =数据与来源!B7 -> 28.71 | F34: 基准情景仅有小幅折价，不符合巴菲特式30%—40%安全边际要求
A36: 关键风险 | B36: 关键风险 | C36: 关键风险 | D36: 关键风险 | E36: 关键风险 | F36: 关键风险 | H36: 监控指标 | I36: 监控指标 | J36: 监控指标 | K36: 监控指标 | L36: 监控指标
A37: 排名 | B37: 风险 | C37: 为什么重要 | H37: 频率 | I37: 指标 | J37: 触发信号
A38: 1 | B38: 海外需求/汇率 | C38: 海外收入已超过国内，毛利率更高，反转会同时影响增长和利润率 | H38: 每月 | I38: 大中轻客销量 | J38: 大中客连续6个月同比双位数下降
A39: 2 | B39: 质保和客户融资担保 | C39: 2026Q3产品质量保证预计负债55.43亿元，担保业务存在代偿可能 | H39: 每季 | I39: 扣非净利润与毛利率 | J39: 扣非转负或毛利率低于22%
A40: 3 | B40: 现金流假繁荣 | C40: 2026Q1-3经营现金流80.04亿元主要来自收款和采购支付节奏，不能当作永久盈利 | H40: 每季 | I40: 应收、存货、合同负债 | J40: 应收/存货增速持续高于收入
H41: 每季 | I41: 质保预计负债与担保代偿 | J41: 预计负债远快于收入或出现重大代偿
H42: 每年 | I42: 分红与研发资本支出 | J42: 高分红挤压研发/必要投资，或分红靠借债支撑
A44: 总体评估 | B44: 总体评估 | C44: 总体评估 | D44: 总体评估 | E44: 总体评估 | F44: 总体评估 | G44: 总体评估 | H44: 总体评估 | I44: 总体评估 | J44: 总体评估 | K44: 总体评估 | L44: 总体评估
A45: 宇通客车是值得长期跟踪的优质制造业龙头：护城河比普通整车厂更强，财务负债低，分红意愿强。但它仍受订单、政策、海外需求和汇率影响，不应以消费品特许经营权的倍数定价。当前价格只有小幅估值优势，还没有达到足以让人“睡得着”的安全边际；把更好的买点留给市场。 | B45: 宇通客车是值得长期跟踪的优质制造业龙头：护城河比普通整车厂更强，财务负债低，分红意愿强。但它仍受订单、政策、海外需求和汇率影响，不应以消费品特许经营权的倍数定价。当前价格只有小幅估值优势，还没有达到足以让人“睡得着”的安全边际；把更好的买点留给市场。 | C45: 宇通客车是值得长期跟踪的优质制造业龙头：护城河比普通整车厂更强，财务负债低，分红意愿强。但它仍受订单、政策、海外需求和汇率影响，不应以消费品特许经营权的倍数定价。当前价格只有小幅估值优势，还没有达到足以让人“睡得着”的安全边际；把更好的买点留给市场。 | D45: 宇通客车是值得长期跟踪的优质制造业龙头：护城河比普通整车厂更强，财务负债低，分红意愿强。但它仍受订单、政策、海外需求和汇率影响，不应以消费品特许经营权的倍数定价。当前价格只有小幅估值优势，还没有达到足以让人“睡得着”的安全边际；把更好的买点留给市场。 | E45: 宇通客车是值得长期跟踪的优质制造业龙头：护城河比普通整车厂更强，财务负债低，分红意愿强。但它仍受订单、政策、海外需求和汇率影响，不应以消费品特许经营权的倍数定价。当前价格只有小幅估值优势，还没有达到足以让人“睡得着”的安全边际；把更好的买点留给市场。 | F45: 宇通客车是值得长期跟踪的优质制造业龙头：护城河比普通整车厂更强，财务负债低，分红意愿强。但它仍受订单、政策、海外需求和汇率影响，不应以消费品特许经营权的倍数定价。当前价格只有小幅估值优势，还没有达到足以让人“睡得着”的安全边际；把更好的买点留给市场。 | G45: 宇通客车是值得长期跟踪的优质制造业龙头：护城河比普通整车厂更强，财务负债低，分红意愿强。但它仍受订单、政策、海外需求和汇率影响，不应以消费品特许经营权的倍数定价。当前价格只有小幅估值优势，还没有达到足以让人“睡得着”的安全边际；把更好的买点留给市场。 | H45: 宇通客车是值得长期跟踪的优质制造业龙头：护城河比普通整车厂更强，财务负债低，分红意愿强。但它仍受订单、政策、海外需求和汇率影响，不应以消费品特许经营权的倍数定价。当前价格只有小幅估值优势，还没有达到足以让人“睡得着”的安全边际；把更好的买点留给市场。 | I45: 宇通客车是值得长期跟踪的优质制造业龙头：护城河比普通整车厂更强，财务负债低，分红意愿强。但它仍受订单、政策、海外需求和汇率影响，不应以消费品特许经营权的倍数定价。当前价格只有小幅估值优势，还没有达到足以让人“睡得着”的安全边际；把更好的买点留给市场。 | J45: 宇通客车是值得长期跟踪的优质制造业龙头：护城河比普通整车厂更强，财务负债低，分红意愿强。但它仍受订单、政策、海外需求和汇率影响，不应以消费品特许经营权的倍数定价。当前价格只有小幅估值优势，还没有达到足以让人“睡得着”的安全边际；把更好的买点留给市场。 | K45: 宇通客车是值得长期跟踪的优质制造业龙头：护城河比普通整车厂更强，财务负债低，分红意愿强。但它仍受订单、政策、海外需求和汇率影响，不应以消费品特许经营权的倍数定价。当前价格只有小幅估值优势，还没有达到足以让人“睡得着”的安全边际；把更好的买点留给市场。 | L45: 宇通客车是值得长期跟踪的优质制造业龙头：护城河比普通整车厂更强，财务负债低，分红意愿强。但它仍受订单、政策、海外需求和汇率影响，不应以消费品特许经营权的倍数定价。当前价格只有小幅估值优势，还没有达到足以让人“睡得着”的安全边际；把更好的买点留给市场。
A46: 宇通客车是值得长期跟踪的优质制造业龙头：护城河比普通整车厂更强，财务负债低，分红意愿强。但它仍受订单、政策、海外需求和汇率影响，不应以消费品特许经营权的倍数定价。当前价格只有小幅估值优势，还没有达到足以让人“睡得着”的安全边际；把更好的买点留给市场。 | B46: 宇通客车是值得长期跟踪的优质制造业龙头：护城河比普通整车厂更强，财务负债低，分红意愿强。但它仍受订单、政策、海外需求和汇率影响，不应以消费品特许经营权的倍数定价。当前价格只有小幅估值优势，还没有达到足以让人“睡得着”的安全边际；把更好的买点留给市场。 | C46: 宇通客车是值得长期跟踪的优质制造业龙头：护城河比普通整车厂更强，财务负债低，分红意愿强。但它仍受订单、政策、海外需求和汇率影响，不应以消费品特许经营权的倍数定价。当前价格只有小幅估值优势，还没有达到足以让人“睡得着”的安全边际；把更好的买点留给市场。 | D46: 宇通客车是值得长期跟踪的优质制造业龙头：护城河比普通整车厂更强，财务负债低，分红意愿强。但它仍受订单、政策、海外需求和汇率影响，不应以消费品特许经营权的倍数定价。当前价格只有小幅估值优势，还没有达到足以让人“睡得着”的安全边际；把更好的买点留给市场。 | E46: 宇通客车是值得长期跟踪的优质制造业龙头：护城河比普通整车厂更强，财务负债低，分红意愿强。但它仍受订单、政策、海外需求和汇率影响，不应以消费品特许经营权的倍数定价。当前价格只有小幅估值优势，还没有达到足以让人“睡得着”的安全边际；把更好的买点留给市场。 | F46: 宇通客车是值得长期跟踪的优质制造业龙头：护城河比普通整车厂更强，财务负债低，分红意愿强。但它仍受订单、政策、海外需求和汇率影响，不应以消费品特许经营权的倍数定价。当前价格只有小幅估值优势，还没有达到足以让人“睡得着”的安全边际；把更好的买点留给市场。 | G46: 宇通客车是值得长期跟踪的优质制造业龙头：护城河比普通整车厂更强，财务负债低，分红意愿强。但它仍受订单、政策、海外需求和汇率影响，不应以消费品特许经营权的倍数定价。当前价格只有小幅估值优势，还没有达到足以让人“睡得着”的安全边际；把更好的买点留给市场。 | H46: 宇通客车是值得长期跟踪的优质制造业龙头：护城河比普通整车厂更强，财务负债低，分红意愿强。但它仍受订单、政策、海外需求和汇率影响，不应以消费品特许经营权的倍数定价。当前价格只有小幅估值优势，还没有达到足以让人“睡得着”的安全边际；把更好的买点留给市场。 | I46: 宇通客车是值得长期跟踪的优质制造业龙头：护城河比普通整车厂更强，财务负债低，分红意愿强。但它仍受订单、政策、海外需求和汇率影响，不应以消费品特许经营权的倍数定价。当前价格只有小幅估值优势，还没有达到足以让人“睡得着”的安全边际；把更好的买点留给市场。 | J46: 宇通客车是值得长期跟踪的优质制造业龙头：护城河比普通整车厂更强，财务负债低，分红意愿强。但它仍受订单、政策、海外需求和汇率影响，不应以消费品特许经营权的倍数定价。当前价格只有小幅估值优势，还没有达到足以让人“睡得着”的安全边际；把更好的买点留给市场。 | K46: 宇通客车是值得长期跟踪的优质制造业龙头：护城河比普通整车厂更强，财务负债低，分红意愿强。但它仍受订单、政策、海外需求和汇率影响，不应以消费品特许经营权的倍数定价。当前价格只有小幅估值优势，还没有达到足以让人“睡得着”的安全边际；把更好的买点留给市场。 | L46: 宇通客车是值得长期跟踪的优质制造业龙头：护城河比普通整车厂更强，财务负债低，分红意愿强。但它仍受订单、政策、海外需求和汇率影响，不应以消费品特许经营权的倍数定价。当前价格只有小幅估值优势，还没有达到足以让人“睡得着”的安全边际；把更好的买点留给市场。
A47: 宇通客车是值得长期跟踪的优质制造业龙头：护城河比普通整车厂更强，财务负债低，分红意愿强。但它仍受订单、政策、海外需求和汇率影响，不应以消费品特许经营权的倍数定价。当前价格只有小幅估值优势，还没有达到足以让人“睡得着”的安全边际；把更好的买点留给市场。 | B47: 宇通客车是值得长期跟踪的优质制造业龙头：护城河比普通整车厂更强，财务负债低，分红意愿强。但它仍受订单、政策、海外需求和汇率影响，不应以消费品特许经营权的倍数定价。当前价格只有小幅估值优势，还没有达到足以让人“睡得着”的安全边际；把更好的买点留给市场。 | C47: 宇通客车是值得长期跟踪的优质制造业龙头：护城河比普通整车厂更强，财务负债低，分红意愿强。但它仍受订单、政策、海外需求和汇率影响，不应以消费品特许经营权的倍数定价。当前价格只有小幅估值优势，还没有达到足以让人“睡得着”的安全边际；把更好的买点留给市场。 | D47: 宇通客车是值得长期跟踪的优质制造业龙头：护城河比普通整车厂更强，财务负债低，分红意愿强。但它仍受订单、政策、海外需求和汇率影响，不应以消费品特许经营权的倍数定价。当前价格只有小幅估值优势，还没有达到足以让人“睡得着”的安全边际；把更好的买点留给市场。 | E47: 宇通客车是值得长期跟踪的优质制造业龙头：护城河比普通整车厂更强，财务负债低，分红意愿强。但它仍受订单、政策、海外需求和汇率影响，不应以消费品特许经营权的倍数定价。当前价格只有小幅估值优势，还没有达到足以让人“睡得着”的安全边际；把更好的买点留给市场。 | F47: 宇通客车是值得长期跟踪的优质制造业龙头：护城河比普通整车厂更强，财务负债低，分红意愿强。但它仍受订单、政策、海外需求和汇率影响，不应以消费品特许经营权的倍数定价。当前价格只有小幅估值优势，还没有达到足以让人“睡得着”的安全边际；把更好的买点留给市场。 | G47: 宇通客车是值得长期跟踪的优质制造业龙头：护城河比普通整车厂更强，财务负债低，分红意愿强。但它仍受订单、政策、海外需求和汇率影响，不应以消费品特许经营权的倍数定价。当前价格只有小幅估值优势，还没有达到足以让人“睡得着”的安全边际；把更好的买点留给市场。 | H47: 宇通客车是值得长期跟踪的优质制造业龙头：护城河比普通整车厂更强，财务负债低，分红意愿强。但它仍受订单、政策、海外需求和汇率影响，不应以消费品特许经营权的倍数定价。当前价格只有小幅估值优势，还没有达到足以让人“睡得着”的安全边际；把更好的买点留给市场。 | I47: 宇通客车是值得长期跟踪的优质制造业龙头：护城河比普通整车厂更强，财务负债低，分红意愿强。但它仍受订单、政策、海外需求和汇率影响，不应以消费品特许经营权的倍数定价。当前价格只有小幅估值优势，还没有达到足以让人“睡得着”的安全边际；把更好的买点留给市场。 | J47: 宇通客车是值得长期跟踪的优质制造业龙头：护城河比普通整车厂更强，财务负债低，分红意愿强。但它仍受订单、政策、海外需求和汇率影响，不应以消费品特许经营权的倍数定价。当前价格只有小幅估值优势，还没有达到足以让人“睡得着”的安全边际；把更好的买点留给市场。 | K47: 宇通客车是值得长期跟踪的优质制造业龙头：护城河比普通整车厂更强，财务负债低，分红意愿强。但它仍受订单、政策、海外需求和汇率影响，不应以消费品特许经营权的倍数定价。当前价格只有小幅估值优势，还没有达到足以让人“睡得着”的安全边际；把更好的买点留给市场。 | L47: 宇通客车是值得长期跟踪的优质制造业龙头：护城河比普通整车厂更强，财务负债低，分红意愿强。但它仍受订单、政策、海外需求和汇率影响，不应以消费品特许经营权的倍数定价。当前价格只有小幅估值优势，还没有达到足以让人“睡得着”的安全边际；把更好的买点留给市场。

Sheet 估值模型
B2: 宇通客车：估值模型与买价阶梯 | C2: 宇通客车：估值模型与买价阶梯 | D2: 宇通客车：估值模型与买价阶梯 | E2: 宇通客车：估值模型与买价阶梯 | F2: 宇通客车：估值模型与买价阶梯 | G2: 宇通客车：估值模型与买价阶梯 | H2: 宇通客车：估值模型与买价阶梯 | I2: 宇通客车：估值模型与买价阶梯 | J2: 宇通客车：估值模型与买价阶梯 | K2: 宇通客车：估值模型与买价阶梯 | L2: 宇通客车：估值模型与买价阶梯 | M2: 宇通客车：估值模型与买价阶梯 | N2: 宇通客车：估值模型与买价阶梯
B3: 情景选择器驱动模型；核心加权估值叠加DCF、DDM、合理PB和资产底线交叉验证。蓝字可修改。 | C3: 情景选择器驱动模型；核心加权估值叠加DCF、DDM、合理PB和资产底线交叉验证。蓝字可修改。 | D3: 情景选择器驱动模型；核心加权估值叠加DCF、DDM、合理PB和资产底线交叉验证。蓝字可修改。 | E3: 情景选择器驱动模型；核心加权估值叠加DCF、DDM、合理PB和资产底线交叉验证。蓝字可修改。 | F3: 情景选择器驱动模型；核心加权估值叠加DCF、DDM、合理PB和资产底线交叉验证。蓝字可修改。 | G3: 情景选择器驱动模型；核心加权估值叠加DCF、DDM、合理PB和资产底线交叉验证。蓝字可修改。 | H3: 情景选择器驱动模型；核心加权估值叠加DCF、DDM、合理PB和资产底线交叉验证。蓝字可修改。 | I3: 情景选择器驱动模型；核心加权估值叠加DCF、DDM、合理PB和资产底线交叉验证。蓝字可修改。 | J3: 情景选择器驱动模型；核心加权估值叠加DCF、DDM、合理PB和资产底线交叉验证。蓝字可修改。 | K3: 情景选择器驱动模型；核心加权估值叠加DCF、DDM、合理PB和资产底线交叉验证。蓝字可修改。 | L3: 情景选择器驱动模型；核心加权估值叠加DCF、DDM、合理PB和资产底线交叉验证。蓝字可修改。 | M3: 情景选择器驱动模型；核心加权估值叠加DCF、DDM、合理PB和资产底线交叉验证。蓝字可修改。 | N3: 情景选择器驱动模型；核心加权估值叠加DCF、DDM、合理PB和资产底线交叉验证。蓝字可修改。
B5: 情景选择 | D5: 2 | F5: =CHOOSE(D5,"保守","基准","积极") -> 基准
B7: 核心假设 | C7: 核心假设 | D7: 核心假设 | E7: 核心假设 | F7: 核心假设 | G7: 核心假设 | H7: 核心假设 | J7: 当前价 | L7: 近12月股息 | N7: 财年2025股息
B8: 假设 | C8: 活跃值 | D8: 单位 | E8: 保守 | F8: 基准 | G8: 积极 | H8: 判断依据 | J8: =数据与来源!B7 -> 28.71 | L8: 2 | N8: 2.5
B9: 正常化所有者收益 | C9: =CHOOSE($D$5,E9,F9,G9) -> 47 | D9: 亿元 | E9: 35 | F9: 47 | G9: 57 | H9: 2023—2025年所有者收益均值约43.8亿元；TTM现金流异常高 | J9: 行情可在数据表中手工更新
B10: 1—5年增长率 | C10: =CHOOSE($D$5,E10,F10,G10) -> 0.04 | D10: % | E10: 0 | F10: 0.04 | G10: 0.07 | H10: 海外与结构升级对冲国内销量波动
B11: 6—10年增长率 | C11: =CHOOSE($D$5,E11,F11,G11) -> 0.03 | D11: % | E11: 0.01 | F11: 0.03 | G11: 0.04 | H11: 成熟制造业增长向名义GDP收敛
B12: 折现率 | C12: =CHOOSE($D$5,E12,F12,G12) -> 0.1 | D12: % | E12: 0.11 | F12: 0.1 | G12: 0.09 | H12: 无风险收益率+公司/行业不确定性溢价
B13: 永续增长率 | C13: =CHOOSE($D$5,E13,F13,G13) -> 0.02 | D13: % | E13: 0.01 | F13: 0.02 | G13: 0.03 | H13: 低于长期名义增长，避免高估终值
B14: 可计入估值的净现金 | C14: =CHOOSE($D$5,E14,F14,G14) -> 80 | D14: 亿元 | E14: 50 | F14: 80 | G14: 100 | H14: 保留运营现金，不将全部金融资产计入价值
B15: 总股本 | C15: =CHOOSE($D$5,E15,F15,G15) -> 22.139392 | D15: 亿股 | E15: 22.139392 | F15: 22.139392 | G15: 22.139392 | H15: 2026Q3
B16: 所有者收益倍数 | C16: =CHOOSE($D$5,E16,F16,G16) -> 13 | D16: 倍 | E16: 10 | F16: 13 | G16: 15 | H16: 制造业周期、中等偏强护城河
B17: 正常化EPS | C17: =CHOOSE($D$5,E17,F17,G17) -> 2.4 | D17: 元/股 | E17: 1.9 | F17: 2.4 | G17: 2.75 | H17: 2025 EPS 2.51元；2026TTM约2.46元
B18: 合理市盈率 | C18: =CHOOSE($D$5,E18,F18,G18) -> 13 | D18: 倍 | E18: 10 | F18: 13 | G18: 15 | H18: 参照成熟制造业与公司质量溢价
B19: 可持续每股股息 | C19: =CHOOSE($D$5,E19,F19,G19) -> 1.9 | D19: 元/股 | E19: 1.4 | F19: 1.9 | G19: 2.3 | H19: 近12月已实施2.00元；2025财年合计2.50元
B20: 要求股息率 | C20: =CHOOSE($D$5,E20,F20,G20) -> 0.062 | D20: % | E20: 0.08 | F20: 0.062 | G20: 0.055 | H20: 对分红波动和周期的补偿
B21: 要求安全边际 | C21: =CHOOSE($D$5,E21,F21,G21) -> 0.35 | D21: % | E21: 0.45 | F21: 0.35 | G21: 0.3 | H21: 巴菲特框架：不确定因素越多，折价要求越高
B22: 三方法估值与三情景比较 | C22: 三方法估值与三情景比较 | D22: 三方法估值与三情景比较 | E22: 三方法估值与三情景比较 | F22: 三方法估值与三情景比较 | G22: 三方法估值与三情景比较 | H22: 三方法估值与三情景比较
B23: 方法 | C23: 权重 | D23: 活跃情景 | E23: 保守 | F23: 基准 | G23: 积极
B24: 所有者收益倍数法 | C24: 0.45 | D24: =($C$9*$C$16+$C$14)/$C$15 -> 31.211336 | E24: =(E$9*E$16+E$14)/E$15 -> 18.067343 | F24: =(F$9*F$16+F$14)/F$15 -> 31.211336 | G24: =(G$9*G$16+G$14)/G$15 -> 43.135782
B25: 正常化盈利倍数法 | C25: 0.3 | D25: =$C$17*$C$18 -> 31.2 | E25: =E$17*E$18 -> 19 | F25: =F$17*F$18 -> 31.2 | G25: =G$17*G$18 -> 41.25
B26: 可持续股息率法 | C26: 0.25 | D26: =$C$19/$C$20 -> 30.645161 | E26: =E$19/E$20 -> 17.5 | F26: =F$19/F$20 -> 30.645161 | G26: =G$19/G$20 -> 41.818182
B27: 加权内在价值（元/股） | C27: 1 | D27: =SUMPRODUCT($C$24:$C$26,D24:D26) -> 31.066391 | E27: =SUMPRODUCT($C$24:$C$26,E24:E26) -> 18.205304 | F27: =SUMPRODUCT($C$24:$C$26,F24:F26) -> 31.066391 | G27: =SUMPRODUCT($C$24:$C$26,G24:G26) -> 42.240647
B28: 当前安全边际 | D28: =1-$J$8/D27 -> 0.075850178 | E28: =1-$J$8/E27 -> -0.5770129 | F28: =1-$J$8/F27 -> 0.075850178 | G28: =1-$J$8/G27 -> 0.32032292
B29: 巴菲特式买入价（元） | D29: =D27*(1-$C$21) -> 20.193154 | E29: =E27*(1-E$21) -> 10.012917 | F29: =F27*(1-F$21) -> 20.193154 | G29: =G27*(1-G$21) -> 29.568453
B32: 活跃情景DCF校验：10年所有者收益 | C32: 活跃情景DCF校验：10年所有者收益 | D32: 活跃情景DCF校验：10年所有者收益 | E32: 活跃情景DCF校验：10年所有者收益 | F32: 活跃情景DCF校验：10年所有者收益 | G32: 活跃情景DCF校验：10年所有者收益 | H32: 活跃情景DCF校验：10年所有者收益 | I32: 活跃情景DCF校验：10年所有者收益 | J32: 活跃情景DCF校验：10年所有者收益 | K32: 活跃情景DCF校验：10年所有者收益 | L32: 活跃情景DCF校验：10年所有者收益 | M32: 活跃情景DCF校验：10年所有者收益 | N32: 活跃情景DCF校验：10年所有者收益
B33: 年份 | C33: 0 | D33: 1 | E33: 2 | F33: 3 | G33: 4 | H33: 5 | I33: 6 | J33: 7 | K33: 8 | L33: 9 | M33: 10
B34: 所有者收益（亿元） | C34: =$C$9 -> 47 | D34: =C34*(1+IF(D$33<=5,$C$10,$C$11)) -> 48.88 | E34: =D34*(1+IF(E$33<=5,$C$10,$C$11)) -> 50.8352 | F34: =E34*(1+IF(F$33<=5,$C$10,$C$11)) -> 52.868608 | G34: =F34*(1+IF(G$33<=5,$C$10,$C$11)) -> 54.983352 | H34: =G34*(1+IF(H$33<=5,$C$10,$C$11)) -> 57.182686 | I34: =H34*(1+IF(I$33<=5,$C$10,$C$11)) -> 58.898167 | J34: =I34*(1+IF(J$33<=5,$C$10,$C$11)) -> 60.665112 | K34: =J34*(1+IF(K$33<=5,$C$10,$C$11)) -> 62.485065 | ... M34: =L34*(1+IF(M$33<=5,$C$10,$C$11)) -> 66.290406
B35: 折现因子 | C35: 1 | D35: =1/(1+$C$12)^D$33 -> 0.90909091 | E35: =1/(1+$C$12)^E$33 -> 0.82644628 | F35: =1/(1+$C$12)^F$33 -> 0.7513148 | G35: =1/(1+$C$12)^G$33 -> 0.68301346 | H35: =1/(1+$C$12)^H$33 -> 0.62092132 | I35: =1/(1+$C$12)^I$33 -> 0.56447393 | J35: =1/(1+$C$12)^J$33 -> 0.51315812 | K35: =1/(1+$C$12)^K$33 -> 0.46650738 | ... M35: =1/(1+$C$12)^M$33 -> 0.38554329
B36: 现值（亿元） | C36: 0 | D36: =D34*D35 -> 44.436364 | E36: =E34*E35 -> 42.012562 | F36: =F34*F35 -> 39.720968 | G36: =G34*G35 -> 37.554369 | H36: =H34*H35 -> 35.505949 | I36: =I34*I35 -> 33.24648 | J36: =J34*J35 -> 31.130795 | K36: =K34*K35 -> 29.149744 | ... M36: =M34*M35 -> 25.557821
B38: 终值（亿元） | D38: =M34*(1+$C$13)/($C$12-$C$13) -> 845.20267
B39: 终值现值（亿元） | D39: =D38*M35 -> 325.86222
B40: 股权价值（亿元） | D40: =SUM(D36:M36)+D39+$C$14 -> 751.47203
B41: DCF每股价值（元） | D41: =D40/$C$15 -> 33.942758
B42: 与加权估值差异 | D42: =D41-D27 -> 2.8763666
B44: 买价解读 | C44: 当前价低于基准内在价值并不自动等于有足够安全边际。对这类受需求、政策、汇率和出口结构影响的制造业，基准情景要求35%折价，对应的买入价才是真正的巴菲特式安全边际。
B45: 模型局限 | C45: DCF对折现率与永续增长率高度敏感，因此主结论采用所有者收益倍数、正常化盈利和可持续股息率的加权值，DCF仅用作校验。
B46: 使用方法 | C46: 修改D5的情景编号，或者修改E:G列假设，一图流和投资结论会同步更新。
B48: 补充估值交叉校验 | C48: 补充估值交叉校验 | D48: 补充估值交叉校验 | E48: 补充估值交叉校验 | F48: 补充估值交叉校验 | G48: 补充估值交叉校验 | H48: 补充估值交叉校验 | J48: DCF敏感性：永续增长 × 折现率 | K48: DCF敏感性：永续增长 × 折现率 | L48: DCF敏感性：永续增长 × 折现率 | M48: DCF敏感性：永续增长 × 折现率 | N48: DCF敏感性：永续增长 × 折现率
...

Sheet 财务十年
A2: 宇通客车：财务十年与所有者收益 | B2: 宇通客车：财务十年与所有者收益 | C2: 宇通客车：财务十年与所有者收益 | D2: 宇通客车：财务十年与所有者收益 | E2: 宇通客车：财务十年与所有者收益 | F2: 宇通客车：财务十年与所有者收益 | G2: 宇通客车：财务十年与所有者收益 | H2: 宇通客车：财务十年与所有者收益 | I2: 宇通客车：财务十年与所有者收益 | J2: 宇通客车：财务十年与所有者收益 | K2: 宇通客车：财务十年与所有者收益 | L2: 宇通客车：财务十年与所有者收益 | M2: 宇通客车：财务十年与所有者收益 | N2: 宇通客车：财务十年与所有者收益 | O2: 宇通客车：财务十年与所有者收益 | P2: 宇通客车：财务十年与所有者收益 | Q2: 宇通客车：财务十年与所有者收益 | R2: 宇通客车：财务十年与所有者收益 | S2: 宇通客车：财务十年与所有者收益 | T2: 宇通客车：财务十年与所有者收益 | U2: 宇通客车：财务十年与所有者收益 | V2: 宇通客车：财务十年与所有者收益 | W2: 宇通客车：财务十年与所有者收益
A3: 历史数据用于观察周期、现金转化和资本效率；ROIC为现金调整后近似值。情景选择： | B3: 历史数据用于观察周期、现金转化和资本效率；ROIC为现金调整后近似值。情景选择： | C3: 历史数据用于观察周期、现金转化和资本效率；ROIC为现金调整后近似值。情景选择： | D3: 历史数据用于观察周期、现金转化和资本效率；ROIC为现金调整后近似值。情景选择： | E3: 历史数据用于观察周期、现金转化和资本效率；ROIC为现金调整后近似值。情景选择： | F3: 历史数据用于观察周期、现金转化和资本效率；ROIC为现金调整后近似值。情景选择： | G3: 历史数据用于观察周期、现金转化和资本效率；ROIC为现金调整后近似值。情景选择： | H3: 历史数据用于观察周期、现金转化和资本效率；ROIC为现金调整后近似值。情景选择： | I3: 历史数据用于观察周期、现金转化和资本效率；ROIC为现金调整后近似值。情景选择： | J3: 历史数据用于观察周期、现金转化和资本效率；ROIC为现金调整后近似值。情景选择： | K3: 历史数据用于观察周期、现金转化和资本效率；ROIC为现金调整后近似值。情景选择： | L3: 历史数据用于观察周期、现金转化和资本效率；ROIC为现金调整后近似值。情景选择： | M3: 历史数据用于观察周期、现金转化和资本效率；ROIC为现金调整后近似值。情景选择： | N3: 历史数据用于观察周期、现金转化和资本效率；ROIC为现金调整后近似值。情景选择： | O3: 历史数据用于观察周期、现金转化和资本效率；ROIC为现金调整后近似值。情景选择： | P3: 历史数据用于观察周期、现金转化和资本效率；ROIC为现金调整后近似值。情景选择： | Q3: 历史数据用于观察周期、现金转化和资本效率；ROIC为现金调整后近似值。情景选择： | R3: 历史数据用于观察周期、现金转化和资本效率；ROIC为现金调整后近似值。情景选择： | S3: 历史数据用于观察周期、现金转化和资本效率；ROIC为现金调整后近似值。情景选择： | T3: 历史数据用于观察周期、现金转化和资本效率；ROIC为现金调整后近似值。情景选择： | U3: 历史数据用于观察周期、现金转化和资本效率；ROIC为现金调整后近似值。情景选择： | V3: 历史数据用于观察周期、现金转化和资本效率；ROIC为现金调整后近似值。情景选择： | W3: =估值模型!F5 -> 基准
A5: 营收CAGR | C5: 10年平均ROE | E5: 10年平均近似ROIC | G5: 累计现金转化率 | I5: 近3年平均所有者收益 | K5: 2026TTM所有者收益
A6: =(B18/B9)^(1/9)-1 -> 0.016191575 | C6: =AVERAGE(I9:I18) -> 0.16946857 | E6: =AVERAGE(J9:J18) -> 0.29618075 | G6: =SUM(E9:E18)/SUM(D9:D18) -> 1.3057913 | I6: =AVERAGE(G16:G18) -> 43.772271 | K6: =G19 -> 87.469718
A8: 期间 | B8: 营业收入 | C8: 毛利率 | D8: 归母净利润 | E8: 经营现金流 | F8: 资本开支 | G8: 所有者收益 | H8: 现金转化率 | I8: ROE | J8: 近似ROIC | K8: DPS | L8: 分红率
A9: =数据与来源!A24 -> 2016 | B9: =数据与来源!B24/100000000 -> 358.50442 | C9: =(数据与来源!B24-数据与来源!C24)/数据与来源!B24 -> 0.27821479 | D9: =数据与来源!G24/100000000 -> 40.437456 | E9: =数据与来源!H24/100000000 -> 35.323317 | F9: =数据与来源!I24/100000000 -> 4.4478207 | G9: =E9-F9 -> 30.875496 | H9: =E9/D9 -> 0.87352966 | I9: =(数据与来源!G24)/AVERAGE(数据与来源!K23,数据与来源!K24) -> 0.30382975 | J9: =(数据与来源!D24*(1-MIN(30%,MAX(0,数据与来源!F24/数据与来源!E24)))/AVERAGE(数据与来源!K23-数据与来源!L23,数据与来源!K24-数据与来源!L24)) -> 0.52882246 | K9: =数据与来源!M24 -> 1 | L9: =K9*数据与来源!B9*100000000/D9/100000000 -> 0.54749716
A10: =数据与来源!A25 -> 2017 | B10: =数据与来源!B25/100000000 -> 332.21949 | C10: =(数据与来源!B25-数据与来源!C25)/数据与来源!B25 -> 0.26317873 | D10: =数据与来源!G25/100000000 -> 31.291939 | E10: =数据与来源!H25/100000000 -> -17.489621 | F10: =数据与来源!I25/100000000 -> 7.3006796 | G10: =E10-F10 -> -24.790301 | H10: =E10/D10 -> -0.55891779 | I10: =(数据与来源!G25)/AVERAGE(数据与来源!K24,数据与来源!K25) -> 0.21370649 | J10: =(数据与来源!D25*(1-MIN(30%,MAX(0,数据与来源!F25/数据与来源!E25)))/AVERAGE(数据与来源!K24-数据与来源!L24,数据与来源!K25-数据与来源!L25)) -> 0.29629332 | K10: =数据与来源!M25 -> 0.5 | L10: =K10*数据与来源!B9*100000000/D10/100000000 -> 0.35375552
A11: =数据与来源!A26 -> 2018 | B11: =数据与来源!B26/100000000 -> 317.45845 | C11: =(数据与来源!B26-数据与来源!C26)/数据与来源!B26 -> 0.25325374 | D11: =数据与来源!G26/100000000 -> 23.014944 | E11: =数据与来源!H26/100000000 -> 25.77826 | F11: =数据与来源!I26/100000000 -> 10.58035 | G11: =E11-F11 -> 15.19791 | H11: =E11/D11 -> 1.1200662 | I11: =(数据与来源!G26)/AVERAGE(数据与来源!K25,数据与来源!K26) -> 0.14223426 | J11: =(数据与来源!D26*(1-MIN(30%,MAX(0,数据与来源!F26/数据与来源!E26)))/AVERAGE(数据与来源!K25-数据与来源!L25,数据与来源!K26-数据与来源!L26)) -> 0.16738699 | K11: =数据与来源!M26 -> 0.5 | L11: =K11*数据与来源!B9*100000000/D11/100000000 -> 0.48097863
A12: =数据与来源!A27 -> 2019 | B12: =数据与来源!B27/100000000 -> 304.91744 | C12: =(数据与来源!B27-数据与来源!C27)/数据与来源!B27 -> 0.24432854 | D12: =数据与来源!G27/100000000 -> 19.422558 | E12: =数据与来源!H27/100000000 -> 53.51506 | F12: =数据与来源!I27/100000000 -> 9.2739261 | G12: =E12-F12 -> 44.241134 | H12: =E12/D12 -> 2.7553044 | I12: =(数据与来源!G27)/AVERAGE(数据与来源!K26,数据与来源!K27) -> 0.11275276 | J12: =(数据与来源!D27*(1-MIN(30%,MAX(0,数据与来源!F27/数据与来源!E27)))/AVERAGE(数据与来源!K26-数据与来源!L26,数据与来源!K27-数据与来源!L27)) -> 0.14210122 | K12: =数据与来源!M27 -> 1 | L12: =K12*数据与来源!B9*100000000/D12/100000000 -> 1.1398803
A13: =数据与来源!A28 -> 2020 | B13: =数据与来源!B28/100000000 -> 217.05048 | C13: =(数据与来源!B28-数据与来源!C28)/数据与来源!B28 -> 0.174755 | D13: =数据与来源!G28/100000000 -> 5.1599026 | E13: =数据与来源!H28/100000000 -> 35.684733 | F13: =数据与来源!I28/100000000 -> 9.5700435 | G13: =E13-F13 -> 26.11469 | H13: =E13/D13 -> 6.9157766 | I13: =(数据与来源!G28)/AVERAGE(数据与来源!K27,数据与来源!K28) -> 0.031141869 | J13: =(数据与来源!D28*(1-MIN(30%,MAX(0,数据与来源!F28/数据与来源!E28)))/AVERAGE(数据与来源!K27-数据与来源!L27,数据与来源!K28-数据与来源!L28)) -> 0.027350892 | K13: =数据与来源!M28 -> 0.5 | L13: =K13*数据与来源!B9*100000000/D13/100000000 -> 2.1453304
A14: =数据与来源!A29 -> 2021 | B14: =数据与来源!B29/100000000 -> 232.33463 | C14: =(数据与来源!B29-数据与来源!C29)/数据与来源!B29 -> 0.18647452 | D14: =数据与来源!G29/100000000 -> 6.1378529 | E14: =数据与来源!H29/100000000 -> 7.1621471 | F14: =数据与来源!I29/100000000 -> 6.9180419 | G14: =E14-F14 -> 0.24410526 | H14: =E14/D14 -> 1.1668815 | I14: =(数据与来源!G29)/AVERAGE(数据与来源!K28,数据与来源!K29) -> 0.03987465 | J14: =(数据与来源!D29*(1-MIN(30%,MAX(0,数据与来源!F29/数据与来源!E29)))/AVERAGE(数据与来源!K28-数据与来源!L28,数据与来源!K29-数据与来源!L29)) -> 0.056303699 | K14: =数据与来源!M29 -> 0.5 | L14: =K14*数据与来源!B9*100000000/D14/100000000 -> 1.8035128
A15: =数据与来源!A30 -> 2022 | B15: =数据与来源!B30/100000000 -> 217.98961 | C15: =(数据与来源!B30-数据与来源!C30)/数据与来源!B30 -> 0.22826033 | D15: =数据与来源!G30/100000000 -> 7.5914076 | E15: =数据与来源!H30/100000000 -> 32.536048 | F15: =数据与来源!I30/100000000 -> 9.7565793 | G15: =E15-F15 -> 22.779469 | H15: =E15/D15 -> 4.2859045 | I15: =(数据与来源!G30)/AVERAGE(数据与来源!K29,数据与来源!K30) -> 0.050712212 | J15: =(数据与来源!D30*(1-MIN(30%,MAX(0,数据与来源!F30/数据与来源!E30)))/AVERAGE(数据与来源!K29-数据与来源!L29,数据与来源!K30-数据与来源!L30)) -> 0.081722481 | K15: =数据与来源!M30 -> 1 | L15: =K15*数据与来源!B9*100000000/D15/100000000 -> 2.9163751
A16: =数据与来源!A31 -> 2023 | B16: =数据与来源!B31/100000000 -> 270.41989 | C16: =(数据与来源!B31-数据与来源!C31)/数据与来源!B31 -> 0.22959411 | D16: =数据与来源!G31/100000000 -> 18.170842 | E16: =数据与来源!H31/100000000 -> 47.166977 | F16: =数据与来源!I31/100000000 -> 5.6703908 | G16: =E16-F16 -> 41.496586 | H16: =E16/D16 -> 2.5957508 | I16: =(数据与来源!G31)/AVERAGE(数据与来源!K30,数据与来源!K31) -> 0.12683525 | J16: =(数据与来源!D31*(1-MIN(30%,MAX(0,数据与来源!F31/数据与来源!E31)))/AVERAGE(数据与来源!K30-数据与来源!L30,数据与来源!K31-数据与来源!L31)) -> 0.23737948 | K16: =数据与来源!M31 -> 1.5 | L16: =K16*数据与来源!B9*100000000/D16/100000000 -> 1.8276032
A17: =数据与来源!A32 -> 2024 | B17: =数据与来源!B32/100000000 -> 372.17587 | C17: =(数据与来源!B32-数据与来源!C32)/数据与来源!B32 -> 0.22941431 | D17: =数据与来源!G32/100000000 -> 41.161944 | E17: =数据与来源!H32/100000000 -> 72.105903 | F17: =数据与来源!I32/100000000 -> 6.957593 | G17: =E17-F17 -> 65.14831 | H17: =E17/D17 -> 1.7517614 | I17: =(数据与来源!G32)/AVERAGE(数据与来源!K31,数据与来源!K32) -> 0.29704662 | J17: =(数据与来源!D32*(1-MIN(30%,MAX(0,数据与来源!F32/数据与来源!E32)))/AVERAGE(数据与来源!K31-数据与来源!L31,数据与来源!K32-数据与来源!L32)) -> 0.65159656 | K17: =数据与来源!M32 -> 1.5 | L17: =K17*数据与来源!B9*100000000/D17/100000000 -> 0.80679105
A18: =数据与来源!A33 -> 2025 | B18: =数据与来源!B33/100000000 -> 414.26174 | C18: =(数据与来源!B33-数据与来源!C33)/数据与来源!B33 -> 0.24141092 | D18: =数据与来源!G33/100000000 -> 55.54482 | E18: =数据与来源!H33/100000000 -> 31.966798 | F18: =数据与来源!I33/100000000 -> 7.2948812 | G18: =E18-F18 -> 24.671917 | H18: =E18/D18 -> 0.57551358 | I18: =(数据与来源!G33)/AVERAGE(数据与来源!K32,数据与来源!K33) -> 0.37655186 | J18: =(数据与来源!D33*(1-MIN(30%,MAX(0,数据与来源!F33/数据与来源!E33)))/AVERAGE(数据与来源!K32-数据与来源!L32,数据与来源!K33-数据与来源!L33)) -> 0.77285036 | K18: =数据与来源!M33 -> 2.5 | L18: =K18*数据与来源!B9*100000000/D18/100000000 -> 0.99646521
A19: =数据与来源!A34 -> 2026TTM | B19: =数据与来源!B34/100000000 -> 408.76128 | C19: =(数据与来源!B34-数据与来源!C34)/数据与来源!B34 -> 0.26001775 | D19: =数据与来源!G34/100000000 -> 54.456675 | E19: =数据与来源!H34/100000000 -> 94.049355 | F19: =数据与来源!I34/100000000 -> 6.5796376 | G19: =E19-F19 -> 87.469718 | H19: =E19/D19 -> 1.7270492 | I19: =(数据与来源!G34)/AVERAGE(数据与来源!K33,数据与来源!K34) -> 0.36149732 | J19: =(数据与来源!D34*(1-MIN(30%,MAX(0,数据与来源!F34/数据与来源!E34)))/AVERAGE(数据与来源!K33-数据与来源!L33,数据与来源!K34-数据与来源!L34)) -> 0.67239058 | K19: =数据与来源!M34 -> 2 | L19: =K19*数据与来源!B9*100000000/D19/100000000 -> 0.81310114
A22: 观察 | B22: 财务含义
A23: 盈利 | B23: 2023年起海外与产品结构改善，利润恢复快于营收；2026前三季度扣非利润仍增长18.45%
A24: 现金流 | B24: 2017年与2021年显示运营资本能让现金流剧烈波动；2026Q1-3的80.04亿元不宜直接年化
A25: 资本效率 | B25: 10年平均ROE与近似ROIC较高，但高分红使净资产基数偏低，应结合净现金和现金转化观察
A26: 分红 | B26: 2025财年每股合计派现2.50元，分红率约99.7%；2026年中期未分红，不应将上年高派息机械外推
A27: 结论 | B27: 财务质量优于普通周期制造业，但所有者收益必须正常化，不能以某个现金流高点估值

Sheet 巴菲特框架
A3: 宇通客车：巴菲特投资框架 | B3: 宇通客车：巴菲特投资框架 | C3: 宇通客车：巴菲特投资框架 | D3: 宇通客车：巴菲特投资框架 | E3: 宇通客车：巴菲特投资框架 | F3: 宇通客车：巴菲特投资框架 | G3: 宇通客车：巴菲特投资框架 | H3: 宇通客车：巴菲特投资框架 | I3: 宇通客车：巴菲特投资框架 | J3: 宇通客车：巴菲特投资框架 | K3: 宇通客车：巴菲特投资框架 | L3: 宇通客车：巴菲特投资框架 | M3: 宇通客车：巴菲特投资框架 | N3: 宇通客车：巴菲特投资框架
A4: 先过8项快速筛选，再看护城河、管理层、所有者收益、估值与风险。情景： | B4: 先过8项快速筛选，再看护城河、管理层、所有者收益、估值与风险。情景： | C4: 先过8项快速筛选，再看护城河、管理层、所有者收益、估值与风险。情景： | D4: 先过8项快速筛选，再看护城河、管理层、所有者收益、估值与风险。情景： | E4: 先过8项快速筛选，再看护城河、管理层、所有者收益、估值与风险。情景： | F4: 先过8项快速筛选，再看护城河、管理层、所有者收益、估值与风险。情景： | G4: 先过8项快速筛选，再看护城河、管理层、所有者收益、估值与风险。情景： | H4: 先过8项快速筛选，再看护城河、管理层、所有者收益、估值与风险。情景： | I4: 先过8项快速筛选，再看护城河、管理层、所有者收益、估值与风险。情景： | J4: 先过8项快速筛选，再看护城河、管理层、所有者收益、估值与风险。情景： | K4: 先过8项快速筛选，再看护城河、管理层、所有者收益、估值与风险。情景： | L4: 先过8项快速筛选，再看护城河、管理层、所有者收益、估值与风险。情景： | M4: 先过8项快速筛选，再看护城河、管理层、所有者收益、估值与风险。情景： | N4: =估值模型!F5 -> 基准
A6: 8项快速筛选 | B6: 8项快速筛选 | C6: 8项快速筛选 | D6: 8项快速筛选 | E6: 8项快速筛选 | F6: 8项快速筛选 | G6: 8项快速筛选 | H6: 8项快速筛选 | I6: 8项快速筛选 | J6: 8项快速筛选 | K6: 8项快速筛选 | L6: 8项快速筛选 | M6: 8项快速筛选 | N6: 8项快速筛选
A7: # | B7: 维度 | C7: 结果 | D7: 事实与判断
A8: 1 | B8: 能力圈 | C8: 通过 | D8: 业务是客车研发、制造和销售，利润来自销量、单车价格、产品/地区结构与成本控制。
A9: 2 | B9: 10年存续性 | C9: 通过 | D9: 公交、公路、旅游、团体通勤需求长期存在；能源形式改变不会消灭车辆需求。
A10: 3 | B10: 护城河 | C10: 部分 | D10: 规模、品牌、研发、海外服务网络和32.47%的2025年大中客市占率构成中等护城河，但同行可以追赶。
A11: 4 | B11: 定价权 | C11: 部分 | D11: B2B招投标与大客户采购限制提价；海外、新能源和高端车型结构改善提供一定溢价。
A12: 5 | B12: 盈利质量 | C12: 通过 | D12: 10年累计经营现金流/净利润高于100%，但单年受应收和采购节奏影响很大。
A13: 6 | B13: 债务安全 | C13: 通过 | D13: 2026Q3货币资金+交易性金融资产显著高于有息负债，收入下降30%仍有生存缓冲。
A14: 7 | B14: 管理层诚信 | C14: 通过但监控 | D14: 2025年审计意见为标准无保留，未发现否决性信号；关联采购、集团财务公司和客户融资担保需持续核查。
A15: 8 | B15: 价格合理性 | C15: 观察 | D15: 当前价低于基准价值不多，未达到35%的基准安全边际要求。
A17: 护城河与业务质量 | B17: 护城河与业务质量 | C17: 护城河与业务质量 | D17: 护城河与业务质量 | E17: 护城河与业务质量 | F17: 护城河与业务质量 | G17: 护城河与业务质量 | I17: 管理层与资本配置 | J17: 管理层与资本配置 | K17: 管理层与资本配置 | L17: 管理层与资本配置 | M17: 管理层与资本配置 | N17: 管理层与资本配置
A18: 类型 | B18: 强度 | C18: 趋势 | D18: 主要证据 | I18: 维度 | J18: 评价 | K18: 判断依据
A19: 规模/成本 | B19: 中强 | C19: 稳定 | D19: 大中客龙头、产品链完整、平台化研发和采购规模 | I19: 诚信 | J19: 中上 | K19: 标准无保留审计；未见明确财务造假或自利交易证据
A20: 品牌/服务 | B20: 中强 | C20: 扩宽 | D20: 海外配件库、经销与直销网络，累计出口各类客车超13.8万辆 | I20: 资本配置 | J20: 中上 | K20: 高分红尊重股东，2025财年派息约占净利润99.7%；但需避免过度分红影响竞争力
A21: 切换成本 | B21: 中等 | C21: 稳定 | D21: 车队运营、配件、售后和司机/维修体系有粘性，但客户仍可转向同行 | I21: 股东视角 | J21: 中上 | K21: 控股股东与其子公司合计持股约41.65%，长期利益一致；关联交易需保持透明
A22: 网络效应 | B22: 弱 | C22: 不适用 | D22: 销量增加不会直接让单个客户的车辆价值上升 | I22: 制度性惯性 | J22: 轻度监控 | K22: 未见大规模溢价并购；私募基金投资、集团财务公司与对外担保应持续跟踪
A23: 有效规模 | B23: 中等 | C23: 稳定 | D23: 客车市场容量有限，全球售后网络的固定投入限制新进者 | I23: 一美元测试 | J23: 部分通过 | K23: 2023年以来利润、海外收入和市值上升，但仍需观察高分红后再投资回报
A24: 综合 | B24: 中等偏强 | C24: 稳定偏扩宽 | D24: 更接近“高质量制造业龙头”，不是拥有无条件提价权的消费品特许经营权 | I24: 结论 | J24: 未见否决项 | K24: 诚信暂无一票否决信号，但治理结构比纯公众公司更复杂
A26: 反向思考：如何亏钱 | B26: 反向思考：如何亏钱 | C26: 反向思考：如何亏钱 | D26: 反向思考：如何亏钱 | E26: 反向思考：如何亏钱 | F26: 反向思考：如何亏钱 | G26: 反向思考：如何亏钱 | I26: 卖出条件逐项检查 | J26: 卖出条件逐项检查 | K26: 卖出条件逐项检查 | L26: 卖出条件逐项检查 | M26: 卖出条件逐项检查 | N26: 卖出条件逐项检查
A27: 路径 | B27: 可能性 | C27: 影响 | D27: 验证指标 | I27: 条件 | J27: 当前判断 | K27: 依据
A28: 海外高毛利增长反转 | B28: 中 | C28: 利润与估值双杀 | D28: 出口销量、海外收入增速、海外毛利率、汇率 | I28: 价格严重高估？ | J28: 否 | K28: 当前价与基准内在价值接近，谈不上严重高估
A29: 国内更新需求弱于预期 | B29: 中 | C29: 产能利用与现金回款承压 | D29: 大中客月销、合同负债、应收和库存 | I29: 护城河破坏？ | J29: 否 | K29: 市占率、出口网络和盈利结构暂未出现结构性破坏
A30: 产品质保/担保风险超预期 | B30: 中低但影响大 | C30: 现金支出与信用减值 | D30: 产品质量保证预计负债、对外担保实际余额与代偿 | I30: 管理层诚信问题？ | J30: 否 | K30: 未发现一票否决证据，但关联交易与担保仍需核查
I31: 显著更好机会？ | J31: 未比较 | K31: 需与个人组合中的现金、红利和其他候选股比较

Sheet 数据与来源
A2: 宇通客车：数据与来源 | B2: 宇通客车：数据与来源 | C2: 宇通客车：数据与来源 | D2: 宇通客车：数据与来源 | E2: 宇通客车：数据与来源 | F2: 宇通客车：数据与来源 | G2: 宇通客车：数据与来源 | H2: 宇通客车：数据与来源 | I2: 宇通客车：数据与来源 | J2: 宇通客车：数据与来源 | K2: 宇通客车：数据与来源 | L2: 宇通客车：数据与来源 | M2: 宇通客车：数据与来源 | N2: 宇通客车：数据与来源
A3: 金额默认为元；模型展示时换算为亿元。蓝字为可更新输入，黑字为公式。 | B3: 金额默认为元；模型展示时换算为亿元。蓝字为可更新输入，黑字为公式。 | C3: 金额默认为元；模型展示时换算为亿元。蓝字为可更新输入，黑字为公式。 | D3: 金额默认为元；模型展示时换算为亿元。蓝字为可更新输入，黑字为公式。 | E3: 金额默认为元；模型展示时换算为亿元。蓝字为可更新输入，黑字为公式。 | F3: 金额默认为元；模型展示时换算为亿元。蓝字为可更新输入，黑字为公式。 | G3: 金额默认为元；模型展示时换算为亿元。蓝字为可更新输入，黑字为公式。 | H3: 金额默认为元；模型展示时换算为亿元。蓝字为可更新输入，黑字为公式。 | I3: 金额默认为元；模型展示时换算为亿元。蓝字为可更新输入，黑字为公式。 | J3: 金额默认为元；模型展示时换算为亿元。蓝字为可更新输入，黑字为公式。 | K3: 金额默认为元；模型展示时换算为亿元。蓝字为可更新输入，黑字为公式。 | L3: 金额默认为元；模型展示时换算为亿元。蓝字为可更新输入，黑字为公式。 | M3: 金额默认为元；模型展示时换算为亿元。蓝字为可更新输入，黑字为公式。 | N3: 金额默认为元；模型展示时换算为亿元。蓝字为可更新输入，黑字为公式。
A5: 市场与资产负债快照 | B5: 市场与资产负债快照 | C5: 市场与资产负债快照 | D5: 市场与资产负债快照 | E5: 市场与资产负债快照 | F5: 市场与资产负债快照
A6: 指标 | B6: 值 | C6: 口径
A7: 当前价（元） | B7: 28.71 | C7: 东方财富延时行情，2026/10/16 16:11:44
A8: 昨收（元） | B8: 28.35 | C8: 已完成交易日收盘
A9: 总股本（亿股） | B9: 22.139392 | C9: 2026Q3
A10: 市值（亿元） | B10: =B7*B9 -> 635.62195 | C10: 当前价×总股本
A11: 货币资金（亿元） | B11: 76.530178 | C11: 2026-09-30
A12: 交易性金融资产（亿元） | B12: 51.738049 | C12: 2026-09-30
A13: 债权投资（亿元） | B13: 1.1922286 | C13: 2026-09-30
A14: 有息负债估算（亿元） | B14: 3.4051539 | C14: 短借+一年内到期+租赁负债
A15: 净金融资产（亿元） | B15: =B11+B12+B13-B14 -> 126.0553 | C15: 货币+交易金融资产+债权投资-有息负债
A16: 净金融资产/股（元） | B16: =B15/B9 -> 5.693711 | C16: 仅作财务安全垫参考
A17: 应收账款（亿元） | B17: 24.755643 | C17: 2026-09-30
A18: 存货（亿元） | B18: 39.276528 | C18: 2026-09-30
A19: 产品质量保证预计负债（亿元） | B19: 55.428178 | C19: 2026-09-30
A21: 2015—2025年度原始数据与TTM计算 | B21: 2015—2025年度原始数据与TTM计算 | C21: 2015—2025年度原始数据与TTM计算 | D21: 2015—2025年度原始数据与TTM计算 | E21: 2015—2025年度原始数据与TTM计算 | F21: 2015—2025年度原始数据与TTM计算 | G21: 2015—2025年度原始数据与TTM计算 | H21: 2015—2025年度原始数据与TTM计算 | I21: 2015—2025年度原始数据与TTM计算 | J21: 2015—2025年度原始数据与TTM计算 | K21: 2015—2025年度原始数据与TTM计算 | L21: 2015—2025年度原始数据与TTM计算 | M21: 2015—2025年度原始数据与TTM计算 | N21: 2015—2025年度原始数据与TTM计算
A22: 期间 | B22: 营业收入 | C22: 营业成本 | D22: 营业利润 | E22: 利润总额 | F22: 所得税 | G22: 归母净利润 | H22: 经营现金流净额 | I22: 资本开支 | J22: 总资产 | K22: 净资产 | L22: 货币资金 | M22: 每股现金分红 | N22: 数据来源
A23: 2015 | B23: 3.1210874e+10 | C23: 2.3305899e+10 | D23: 3.828283e+09 | E23: 4.1043449e+09 | F23: 5.1665576e+08 | G23: 3.5352159e+09 | H23: 6.0097405e+09 | I23: 1.3022399e+09 | J23: 3.0139131e+10 | K23: 1.2939385e+10 | L23: 6.6991645e+09 | M23: 1.5 | N23: 东方财富财务数据API，并以宇通客车定期报告复核
A24: 2016 | B24: 3.5850442e+10 | C24: 2.5876319e+10 | D24: 4.4087027e+09 | E24: 4.7822903e+09 | F24: 6.7995086e+08 | G24: 4.0437456e+09 | H24: 3.5323317e+09 | I24: 4.4478207e+08 | J24: 35153796066 | K24: 1.3679111e+10 | L24: 5.6163503e+09 | M24: 1 | N24: 东方财富财务数据API，并以宇通客车定期报告复核
A25: 2017 | B25: 3.3221949e+10 | C25: 2.4478638e+10 | D25: 3.6015528e+09 | E25: 3.6359452e+09 | F25: 4.6809927e+08 | G25: 3.1291939e+09 | H25: -1.7489621e+09 | I25: 7.3006796e+08 | J25: 3.6165406e+10 | K25: 1.5605858e+10 | L25: 2.4877074e+09 | M25: 0.5 | N25: 东方财富财务数据API，并以宇通客车定期报告复核
A26: 2018 | B26: 3.1745845e+10 | C26: 2.3706091e+10 | D26: 2.4679966e+09 | E26: 2546534780 | F26: 2.1815453e+08 | G26: 2.3014944e+09 | H26: 2.577826e+09 | I26: 1.058035e+09 | J26: 3.6799018e+10 | K26: 1.6756167e+10 | L26: 2.9120044e+09 | M26: 0.5 | N26: 东方财富财务数据API，并以宇通客车定期报告复核
A27: 2019 | B27: 3.0491744e+10 | C27: 2.3041741e+10 | D27: 2.0215161e+09 | E27: 2.0871057e+09 | F27: 1.2250849e+08 | G27: 1.9422558e+09 | H27: 5.351506e+09 | I27: 9.2739261e+08 | J27: 3.6706402e+10 | K27: 1.7695422e+10 | L27: 4.7578645e+09 | M27: 1 | N27: 东方财富财务数据API，并以宇通客车定期报告复核
A28: 2020 | B28: 2.1705048e+10 | C28: 1.7911983e+10 | D28: 3.0399601e+08 | E28: 3.47713e+08 | F28: -1.7036231e+08 | G28: 5.1599026e+08 | H28: 3.5684733e+09 | I28: 9.5700435e+08 | J28: 3.3311873e+10 | K28: 1.5442618e+10 | L28: 6.1508452e+09 | M28: 0.5 | N28: 东方财富财务数据API，并以宇通客车定期报告复核
A29: 2021 | B29: 2.3233463e+10 | C29: 1.8901014e+10 | D29: 5.3498643e+08 | E29: 5.4345705e+08 | F29: -82053699 | G29: 6.1378529e+08 | H29: 7.1621471e+08 | I29: 6.9180419e+08 | J29: 3.2165891e+10 | K29: 1.5343121e+10 | L29: 5.6312956e+09 | M29: 0.5 | N29: 东方财富财务数据API，并以宇通客车定期报告复核
A30: 2022 | B30: 2.1798961e+10 | C30: 1.6823123e+10 | D30: 7.0580643e+08 | E30: 7.077596e+08 | F30: -60045092 | G30: 7.5914076e+08 | H30: 3.2536048e+09 | I30: 9.7565793e+08 | J30: 2.9998383e+10 | K30: 1.4596049e+10 | L30: 7.0346239e+09 | M30: 1 | N30: 东方财富财务数据API，并以宇通客车定期报告复核
A31: 2023 | B31: 2.7041989e+10 | C31: 2.0833308e+10 | D31: 2.0358878e+09 | E31: 2.0780133e+09 | F31: 2.3850997e+08 | G31: 1.8170842e+09 | H31: 4.7166977e+09 | I31: 5.6703908e+08 | J31: 3.0856956e+10 | K31: 1.405662e+10 | L31: 6.4338087e+09 | M31: 1.5 | N31: 东方财富财务数据API，并以宇通客车定期报告复核
A32: 2024 | B32: 3.7217587e+10 | C32: 2.867934e+10 | D32: 4.6715631e+09 | E32: 4.7222052e+09 | F32: 5.6827944e+08 | G32: 4.1161944e+09 | H32: 7.2105903e+09 | I32: 6.957593e+08 | J32: 3.2150894e+10 | K32: 1.3657511e+10 | L32: 8.6670636e+09 | M32: 1.5 | N32: 东方财富财务数据API，并以宇通客车定期报告复核
A33: 2025 | B33: 4.1426174e+10 | C33: 3.1425443e+10 | D33: 6.4783028e+09 | E33: 6.5186946e+09 | F33: 8.9351831e+08 | G33: 5.554482e+09 | H33: 3.1966798e+09 | I33: 7.2948812e+08 | J33: 3.2990246e+10 | K33: 1.5844305e+10 | L33: 6.3679912e+09 | M33: 2.5 | N33: 东方财富财务数据API，并以宇通客车定期报告复核
A34: 2026TTM | B34: =B33+B39-B38 -> 4.0876128e+10 | C34: =C33+C39-C38 -> 3.0247609e+10 | D34: =D33+D39-D38 -> 6.190073e+09 | E34: =E33+E39-E38 -> 6.251629e+09 | F34: =F33+F39-F38 -> 7.8254999e+08 | G34: =G33+G39-G38 -> 5.4456675e+09 | H34: =H33+H39-H38 -> 9.4049355e+09 | I34: =I33+I39-I38 -> 6.5796376e+08 | J34: 3.298698e+10 | K34: 1.4284093e+10 | L34: 7.6530178e+09 | M34: 2 | N34: TTM=公司2025年+公司2026Q1-3-公司2025Q1-3；现金股息为近12个月已实施
A36: Q3累计数据：TTM计算桥 | B36: Q3累计数据：TTM计算桥 | C36: Q3累计数据：TTM计算桥 | D36: Q3累计数据：TTM计算桥 | E36: Q3累计数据：TTM计算桥 | F36: Q3累计数据：TTM计算桥 | G36: Q3累计数据：TTM计算桥 | H36: Q3累计数据：TTM计算桥 | I36: Q3累计数据：TTM计算桥 | J36: Q3累计数据：TTM计算桥
A37: 期间 | B37: 营业收入 | C37: 营业成本 | D37: 营业利润 | E37: 利润总额 | F37: 所得税 | G37: 归母净利润 | H37: 经营现金流净额 | I37: 资本开支 | J37: 来源
A38: 2025Q1-3 | B38: 2.6365918e+10 | C38: 2.047104e+10 | D38: 3.8324575e+09 | E38: 3.8552739e+09 | F38: 491182972 | G38: 3.29235e+09 | H38: 1.7961623e+09 | I38: 5.5364867e+08 | J38: 2025年第三季度报告
A39: 2026Q1-3 | B39: 2.5815872e+10 | C39: 1.9293206e+10 | D39: 3.5442277e+09 | E39: 3.5882083e+09 | F39: 3.8021465e+08 | G39: 3.1835356e+09 | H39: 8.0044181e+09 | I39: 4.8212432e+08 | J39: 2026年第三季度报告
A42: 来源台账 | B42: 来源台账 | C42: 来源台账 | D42: 来源台账 | E42: 来源台账 | F42: 来源台账
A43: 日期 | B43: 类型 | C43: 文档/数据 | D43: 主要用途 | E43: URL | F43: 本地备份
A44: 2026-10-15 | B44: 公司公告 | C44: 2026年第三季度报告 | D44: 最新业绩、资产负债、现金流 | E44: https://file.finance.sina.com.cn/211.154.219.97:9494/MRGG/CNSESH_STOCK/2026/2026-10/2026-10-15/12641310.PDF | F44: 资料/宇通客车_2026年第三季度报告.pdf
A45: 2026-10-09 | B45: 公司公告 | C45: 2026年9月份产销数据快报 | D45: 1—9月销量与车型结构 | E45: https://pdf.dfcfw.com/pdf/H2_AN202610081830207843_1.pdf | F45: 资料/宇通客车_2026年9月份产销数据快报.pdf
A46: 2026-08-11 | B46: 公司公告 | C46: 2026年半年度报告 | D46: 海外市场、研发、风险披露 | E46: https://static.cninfo.com.cn/finalpage/2026-08-11/1225466147.PDF | F46: 资料/宇通客车_2026年半年度报告.pdf
...
