Workbook

Sheet 说明
A1: 红利可持续性评分表 · 使用说明
A2: v1.0.0 · 2026-10-30 · 研究分级工具，不构成投资建议
A3: 定位
A4: 把红利从“高股息率”一个标签，拆成三条轨道：一般红利/类债、金融红利、质量防御。质量分和估值分分开，硬约束优先于加权分。
A6: 三条轨道
A7: 轨道 | B7: 适用 | C7: 核心问题 | D7: 评分方法 | E7: 权威来源 | F7: 备注
A8: 一般红利 / 类债 | B8: 非金融、稳定分红公司 | C8: FCF 能不能覆盖股息？ | D8: 六维质量分 + 硬约束 | E8: 本框架 | F8: 本表主评分区
A9: 金融红利 | B9: 银行、保险 | C9: 资本、资产质量、股息能否持续？ | D9: 银行 skill 四维评分 + DDM | E9: 银行估值skills | F9: 不套用 FCF 评分
A10: 质量防御 | B10: Visa、Mastercard、伯克希尔等 | C10: 生意质量能否穿越周期？ | D10: 五维质量分 + 估值分 | E10: 本框架 | F10: 与红利分开排序
A12: 评级
A13: 等级 | B13: 最终质量分 | C13: 含义 | D13: 研究动作
A14: A | B14: ≥80 | C14: 红利质量强 | D14: 进入核心研究池
A15: B | B15: 65–79 | C15: 合格 | D15: 持续跟踪
A16: C | B16: 50–64 | C16: 观察 | D16: 需要催化剂或改善证据
A17: D | B17: <50 | C17: 不满足红利标准 | D17: 不进入红利池
A18: NA | B18: 数据不足 / 负 FCF / 不适用 | C18: 不强行评分 | D18: 补数据或换方法
A20: 硬约束（优先于加权分）
A21: · FCF 派息率连续 2 年 >100% → 最终质量分上限 40。
A22: · 净负债 / EBITDA >4 倍 → 上限 30。
A23: · 近 5 年砍息 → 上限 50。
A24: · 5 年归母净利最大回撤 >70% → 上限 50。
A25: · 归母与普通股东利润差异 >20%（少数股东/治理侵蚀）→ 上限 60。
A26: · 硬约束触发后：最终质量分 = MIN(加权质量分, 上限)，不因为其他维度优秀而抵消。
A28: 总回报公式
A29: 税后股息率 = 股息率 × (1 − 适用税率)
A30: 总回报 = (1 + 税后股息率) × (1 + 价格回报) × (1 + 汇率变动) − 1
A31: 超额收益 = 总回报 − 本地 10 年期国债收益率
A33: 使用步骤
... A46: 本工作簿是“模板 + 已知硬数据示例”：空白 = 待填，不按 0 计算；六维未填满时质量分显示“数据不足”，不是 0 分。预填的 7 家一般红利、4 家银行、3 家质量防御只用于演示口径，不代表已完成评分。

Sheet 评分总表
A1: 评分总表 · 三条轨道总览
A2: 质量分与估值分分开；综合分 = 60% 质量 + 40% 估值；等级只代表研究优先级，不代表买卖建议。
A4: 序号 | B4: 标的 | C4: 代码 | D4: 市场 | E4: 轨道 | F4: 行业 | G4: 质量分 | H4: 估值分 | I4: 综合分 | J4: 等级 | K4: 股息率 | L4: 总回报 | M4: 总回报-10Y | N4: 硬约束 / 口径 | O4: 结论 | P4: 数据日期 | Q4: 备注
A5: 1 | B5: 工商银行 | C5: 601398.SH | D5: A股 | E5: 金融红利 | F5: 银行 | G5: ='金融红利'!J5 | H5: ='总回报'!T5 | I5: =IF(AND(ISNUMBER(G5),ISNUMBER(H5)),0.6*G5+0.4*H5,"") | J5: =IF(ISNUMBER(I5),IF(I5>=80,"A",IF(I5>=65,"B",IF(I5>=50,"C","D"))),"") | K5: ='总回报'!H5 | L5: ='总回报'!P5 | M5: ='总回报'!Q5 | N5: 银行资本/资产质量约束，见银行 skill | O5: 合理偏低；ROE 低于股权成本 | P5: 2026-10-30 | Q5: 银行类债；四维评分引用银行 skill
A6: 2 | B6: 平安银行 | C6: 000001.SZ | D6: A股 | E6: 金融红利 | F6: 银行 | G6: ='金融红利'!J6 | H6: ='总回报'!T6 | I6: =IF(AND(ISNUMBER(G6),ISNUMBER(H6)),0.6*G6+0.4*H6,"") | J6: =IF(ISNUMBER(I6),IF(I6>=80,"A",IF(I6>=65,"B",IF(I6>=50,"C","D"))),"") | K6: ='总回报'!H6 | L6: ='总回报'!P6 | M6: ='总回报'!Q6 | N6: 银行资本/资产质量约束，见银行 skill | O6: 合理偏贵；ROE 低于股权成本 | P6: 2026-10-30 | Q6: DDM 8.13，综合基准 11.03；现价 11.64
A7: 3 | B7: 美的集团 | C7: 000333.SZ | D7: A股 | E7: 一般红利 | F7: 家电 | G7: =IF('分红安全'!AD5="数据不足","数据不足",'分红安全'!AH5) | H7: ='总回报'!T7 | I7: =IF(AND(ISNUMBER(G7),ISNUMBER(H7)),0.6*G7+0.4*H7,"") | J7: =IF(ISNUMBER(I7),IF(I7>=80,"A",IF(I7>=65,"B",IF(I7>=50,"C","D"))),"") | K7: ='总回报'!H7 | L7: ='总回报'!P7 | M7: ='总回报'!Q7 | N7: ='分红安全'!AG5 | O7: 现价低于基准 22%，便宜 | P7: 2026-10-30 | Q7: 15 倍 PE；4.9% 股息率；净现金 455 亿
A8: 4 | B8: 贵州茅台 | C8: 600519.SH | D8: A股 | E8: 一般红利 | F8: 高端白酒 | G8: =IF('分红安全'!AD6="数据不足","数据不足",'分红安全'!AH6) | H8: ='总回报'!T8 | I8: =IF(AND(ISNUMBER(G8),ISNUMBER(H8)),0.6*G8+0.4*H8,"") | J8: =IF(ISNUMBER(I8),IF(I8>=80,"A",IF(I8>=65,"B",IF(I8>=50,"C","D"))),"") | K8: ='总回报'!H8 | L8: ='总回报'!P8 | M8: ='总回报'!Q8 | N8: ='分红安全'!AG6 | O8: 接近内在价值，合理 | P8: 2026-10-30 | Q8: 20.8 倍 PE；3.8% 股息率
A9: 5 | B9: 长江电力 | C9: 600900.SH | D9: A股 | E9: 一般红利 | F9: 水电 | G9: =IF('分红安全'!AD7="数据不足","数据不足",'分红安全'!AH7) | H9: ='总回报'!T9 | I9: =IF(AND(ISNUMBER(G9),ISNUMBER(H9)),0.6*G9+0.4*H9,"") | J9: =IF(ISNUMBER(I9),IF(I9>=80,"A",IF(I9>=65,"B",IF(I9>=50,"C","D"))),"") | K9: ='总回报'!H9 | L9: ='总回报'!P9 | M9: ='总回报'!Q9 | N9: ='分红安全'!AG7 | O9: 合理偏贵；好资产，价格在上沿 | P9: 2026-10-30 | Q9: 22.6 倍 PE；3.1% 股息率；基准 27.59
A10: 6 | B10: 中国神华 | C10: 601088.SH | D10: A股 | E10: 一般红利 | F10: 煤炭 | G10: =IF('分红安全'!AD8="数据不足","数据不足",'分红安全'!AH8) | H10: ='总回报'!T10 | I10: =IF(AND(ISNUMBER(G10),ISNUMBER(H10)),0.6*G10+0.4*H10,"") | J10: =IF(ISNUMBER(I10),IF(I10>=80,"A",IF(I10>=65,"B",IF(I10>=50,"C","D"))),"") | K10: ='总回报'!H10 | L10: ='总回报'!P10 | M10: ='总回报'!Q10 | N10: ='分红安全'!AG8 | O10: 昂贵；为周期高位盈利付费 | P10: 2026-10-30 | Q10: 20 倍 PE；3.8% 股息率；基准 36.64
A11: 7 | B11: 可口可乐 | C11: KO | D11: 美股 | E11: 一般红利 | F11: 必选消费 | G11: =IF('分红安全'!AD9="数据不足","数据不足",'分红安全'!AH9) | H11: ='总回报'!T11 | I11: =IF(AND(ISNUMBER(G11),ISNUMBER(H11)),0.6*G11+0.4*H11,"") | J11: =IF(ISNUMBER(I11),IF(I11>=80,"A",IF(I11>=65,"B",IF(I11>=50,"C","D"))),"") | K11: ='总回报'!H11 | L11: ='总回报'!P11 | M11: ='总回报'!Q11 | N11: ='分红安全'!AG9 | O11: 护城河仍在，估值略贵 | P11: 2026-10-30 | Q11: 27 倍 PE；股息率待填
A12: 8 | B12: 中国移动 | C12: 600941.SH | D12: A股 | E12: 一般红利 | F12: 运营商 | G12: =IF('分红安全'!AD10="数据不足","数据不足",'分红安全'!AH10) | H12: ='总回报'!T12 | I12: =IF(AND(ISNUMBER(G12),ISNUMBER(H12)),0.6*G12+0.4*H12,"") | J12: =IF(ISNUMBER(I12),IF(I12>=80,"A",IF(I12>=65,"B",IF(I12>=50,"C","D"))),"") | K12: ='总回报'!H12 | L12: ='总回报'!P12 | M12: ='总回报'!Q12 | N12: ='分红安全'!AG10 | O12: 待研究 | Q12: 观察池候选；资本开支见顶后分红提升
A13: 9 | B13: 宁沪高速 | C13: 600377.SH | D13: A股 | E13: 一般红利 | F13: 高速公路 | G13: =IF('分红安全'!AD11="数据不足","数据不足",'分红安全'!AH11) | H13: ='总回报'!T13 | I13: =IF(AND(ISNUMBER(G13),ISNUMBER(H13)),0.6*G13+0.4*H13,"") | J13: =IF(ISNUMBER(I13),IF(I13>=80,"A",IF(I13>=65,"B",IF(I13>=50,"C","D"))),"") | K13: ='总回报'!H13 | L13: ='总回报'!P13 | M13: ='总回报'!Q13 | N13: ='分红安全'!AG11 | O13: 待研究 | Q13: 观察池候选；类债现金流
A14: 10 | B14: 伯克希尔 | C14: BRK.B | D14: 美股 | E14: 质量防御 | F14: 综合控股 | G14: ='质量防御'!R5 | H14: ='总回报'!T14 | I14: =IF(AND(ISNUMBER(G14),ISNUMBER(H14)),0.6*G14+0.4*H14,"") | J14: =IF(ISNUMBER(I14),IF(I14>=80,"A",IF(I14>=65,"B",IF(I14>=50,"C","D"))),"") | K14: ='总回报'!H14 | L14: ='总回报'!P14 | M14: ='总回报'!Q14 | N14: ROIC / 资本强度约束，见质量防御 | O14: 合理区间上沿，安全边际不足 | P14: 2026-10-30 | Q14: 非股息型；现金与上市股权提供资产负债表防御
A15: 11 | B15: Visa | C15: V | D15: 美股 | E15: 质量防御 | F15: 支付 | G15: ='质量防御'!R6 | H15: ='总回报'!T15 | I15: =IF(AND(ISNUMBER(G15),ISNUMBER(H15)),0.6*G15+0.4*H15,"") | J15: =IF(ISNUMBER(I15),IF(I15>=80,"A",IF(I15>=65,"B",IF(I15>=50,"C","D"))),"") | K15: ='总回报'!H15 | L15: ='总回报'!P15 | M15: ='总回报'!Q15 | N15: ROIC / 资本强度约束，见质量防御 | O15: 合理偏低，安全边际不足 | P15: 2026-10-30 | Q15: 32.5 倍 PE；0.78% 股息率；DCF 424.63
A16: 12 | B16: 万事达卡 | C16: MA | D16: 美股 | E16: 质量防御 | F16: 支付 | G16: ='质量防御'!R7 | H16: ='总回报'!T16 | I16: =IF(AND(ISNUMBER(G16),ISNUMBER(H16)),0.6*G16+0.4*H16,"") | J16: =IF(ISNUMBER(I16),IF(I16>=80,"A",IF(I16>=65,"B",IF(I16>=50,"C","D"))),"") | K16: ='总回报'!H16 | L16: ='总回报'!P16 | M16: ='总回报'!Q16 | N16: ROIC / 资本强度约束，见质量防御 | O16: 合理偏低，安全边际不足 | P16: 2026-10-30 | Q16: 33.6 倍 PE；0.50% 股息率；DCF 666.31

Sheet 分红安全
A1: 一般红利 · 六维评分
A2: 蓝色=输入；灰色=公式；红色=硬约束
A4: 序号 | B4: 标的 | C4: 代码 | D4: 市场 | E4: 行业 | F4: 当前价 | G4: 2026E DPS | H4: 股本(亿股) | I4: 2026E 分红总额(亿元) | J4: 股息率 | K4: FY2025 FCF(亿元) | L4: FCF派息率 | M4: 3年平均FCF派息率 | N4: FCF覆盖得分 | O4: 净负债(亿元) | P4: EBITDA(亿元) | Q4: 净负债/EBITDA | R4: 资产负债表得分 | S4: 资本开支(亿元) | T4: 折旧摊销(亿元) | U4: capex/折旧 | V4: 资本开支得分 | W4: 5年净利最大回撤 | X4: 盈利周期性得分 | Y4: 近5年砍息次数 | Z4: 分红连续性得分 | AA4: 5年DPS CAGR | AB4: 治理得分 | AC4: 少数股东占比 | AD4: 质量分 | AE4: 连续2年>100% | AF4: 硬约束上限 | AG4: 硬约束原因 | AH4: 最终质量分 | AI4: 等级 | AJ4: 数据完整度 | AK4: 备注
A5: 1 | B5: 美的集团 | C5: 000333.SZ | D5: A股 | E5: 家电 | I5: =IF(OR(G5="",H5=""),"",G5*H5) | J5: =IF(OR(F5="",G5=""),"",G5/F5) | L5: =IF(OR(I5="",K5=""),"",I5/K5) | N5: =IF(AND(L5="",M5=""),"",IF(IF(M5<>"",M5,L5)<=0.5,95,IF(IF(M5<>"",M5,L5)<=0.7,82,IF(IF(M5<>"",M5,L5)<=0.9,67,IF(IF(M5<>"",M5,L5)<=1,50,25))))) | Q5: =IF(OR(O5="",P5=""),"",IF(P5<=0,"",O5/P5)) | R5: =IF(Q5="","",IF(Q5<=0,95,IF(Q5<=1,85,IF(Q5<=2,72,IF(Q5<=3,58,IF(Q5<=4,42,20)))))) | U5: =IF(OR(S5="",T5=""),"",S5/T5) | V5: =IF(U5="","",IF(U5<=0.8,90,IF(U5<=1.2,78,IF(U5<=1.8,62,IF(U5<=2.5,42,20))))) | X5: =IF(W5="","",IF(W5<=0.15,92,IF(W5<=0.3,78,IF(W5<=0.5,60,IF(W5<=0.7,40,20))))) | Z5: =IF(Y5="","",IF(Y5=0,90,IF(Y5=1,50,20))) | AD5: =IF(COUNT(N5,R5,V5,X5,Z5,AB5)<6,"数据不足",0.25*N5+0.2*R5+0.15*V5+0.15*X5+0.15*Z5+0.1*AB5) | AF5: =IF(AE5="是",40,IF(AND(Q5<>"",Q5>4),30,IF(AND(Y5<>"",Y5>=1),50,IF(AND(W5<>"",W5>0.7),50,IF(AND(AC5<>"",AC5>0.2),60,100))))) | AG5: =IF(AE5="是","FCF派息率连续2年>100%，上限40",IF(AND(Q5<>"",Q5>4),"净负债/EBITDA>4，上限30",IF(AND(Y5<>"",Y5>=1),"近5年砍息，上限50",IF(AND(W5<>"",W5>0.7),"5年净利回撤>70%，上限50",IF(AND(AC5<>"",AC5>0.2),"少数股东/治理侵蚀>20%，上限60",""))))) | AH5: =IF(AD5="数据不足","",MIN(AD5,AF5)) | AI5: =IF(AH5="","NA",IF(AH5>=80,"A",IF(AH5>=65,"B",IF(AH5>=50,"C","D")))) | AJ5: =COUNTA(F5,G5,H5,K5,O5,P5,S5,T5,W5,Y5,AB5,AC5)/12 | AK5: 股息率约4.9%；FCF/净负债/资本开支待填
A6: 2 | B6: 贵州茅台 | C6: 600519.SH | D6: A股 | E6: 高端白酒 | I6: =IF(OR(G6="",H6=""),"",G6*H6) | J6: =IF(OR(F6="",G6=""),"",G6/F6) | L6: =IF(OR(I6="",K6=""),"",I6/K6) | N6: =IF(AND(L6="",M6=""),"",IF(IF(M6<>"",M6,L6)<=0.5,95,IF(IF(M6<>"",M6,L6)<=0.7,82,IF(IF(M6<>"",M6,L6)<=0.9,67,IF(IF(M6<>"",M6,L6)<=1,50,25))))) | Q6: =IF(OR(O6="",P6=""),"",IF(P6<=0,"",O6/P6)) | R6: =IF(Q6="","",IF(Q6<=0,95,IF(Q6<=1,85,IF(Q6<=2,72,IF(Q6<=3,58,IF(Q6<=4,42,20)))))) | U6: =IF(OR(S6="",T6=""),"",S6/T6) | V6: =IF(U6="","",IF(U6<=0.8,90,IF(U6<=1.2,78,IF(U6<=1.8,62,IF(U6<=2.5,42,20))))) | X6: =IF(W6="","",IF(W6<=0.15,92,IF(W6<=0.3,78,IF(W6<=0.5,60,IF(W6<=0.7,40,20))))) | Z6: =IF(Y6="","",IF(Y6=0,90,IF(Y6=1,50,20))) | AD6: =IF(COUNT(N6,R6,V6,X6,Z6,AB6)<6,"数据不足",0.25*N6+0.2*R6+0.15*V6+0.15*X6+0.15*Z6+0.1*AB6) | AF6: =IF(AE6="是",40,IF(AND(Q6<>"",Q6>4),30,IF(AND(Y6<>"",Y6>=1),50,IF(AND(W6<>"",W6>0.7),50,IF(AND(AC6<>"",AC6>0.2),60,100))))) | AG6: =IF(AE6="是","FCF派息率连续2年>100%，上限40",IF(AND(Q6<>"",Q6>4),"净负债/EBITDA>4，上限30",IF(AND(Y6<>"",Y6>=1),"近5年砍息，上限50",IF(AND(W6<>"",W6>0.7),"5年净利回撤>70%，上限50",IF(AND(AC6<>"",AC6>0.2),"少数股东/治理侵蚀>20%，上限60",""))))) | AH6: =IF(AD6="数据不足","",MIN(AD6,AF6)) | AI6: =IF(AH6="","NA",IF(AH6>=80,"A",IF(AH6>=65,"B",IF(AH6>=50,"C","D")))) | AJ6: =COUNTA(F6,G6,H6,K6,O6,P6,S6,T6,W6,Y6,AB6,AC6)/12 | AK6: 股息率约3.8%；FCF/净负债/资本开支待填
A7: 3 | B7: 长江电力 | C7: 600900.SH | D7: A股 | E7: 水电 | F7: 29.74 | G7: 0.92 | H7: 244.68218 | I7: =IF(OR(G7="",H7=""),"",G7*H7) | J7: =IF(OR(F7="",G7=""),"",G7/F7) | L7: =IF(OR(I7="",K7=""),"",I7/K7) | N7: =IF(AND(L7="",M7=""),"",IF(IF(M7<>"",M7,L7)<=0.5,95,IF(IF(M7<>"",M7,L7)<=0.7,82,IF(IF(M7<>"",M7,L7)<=0.9,67,IF(IF(M7<>"",M7,L7)<=1,50,25))))) | O7: 2734.9 | Q7: =IF(OR(O7="",P7=""),"",IF(P7<=0,"",O7/P7)) | R7: =IF(Q7="","",IF(Q7<=0,95,IF(Q7<=1,85,IF(Q7<=2,72,IF(Q7<=3,58,IF(Q7<=4,42,20)))))) | U7: =IF(OR(S7="",T7=""),"",S7/T7) | V7: =IF(U7="","",IF(U7<=0.8,90,IF(U7<=1.2,78,IF(U7<=1.8,62,IF(U7<=2.5,42,20))))) | X7: =IF(W7="","",IF(W7<=0.15,92,IF(W7<=0.3,78,IF(W7<=0.5,60,IF(W7<=0.7,40,20))))) | Z7: =IF(Y7="","",IF(Y7=0,90,IF(Y7=1,50,20))) | AD7: =IF(COUNT(N7,R7,V7,X7,Z7,AB7)<6,"数据不足",0.25*N7+0.2*R7+0.15*V7+0.15*X7+0.15*Z7+0.1*AB7) | AF7: =IF(AE7="是",40,IF(AND(Q7<>"",Q7>4),30,IF(AND(Y7<>"",Y7>=1),50,IF(AND(W7<>"",W7>0.7),50,IF(AND(AC7<>"",AC7>0.2),60,100))))) | AG7: =IF(AE7="是","FCF派息率连续2年>100%，上限40",IF(AND(Q7<>"",Q7>4),"净负债/EBITDA>4，上限30",IF(AND(Y7<>"",Y7>=1),"近5年砍息，上限50",IF(AND(W7<>"",W7>0.7),"5年净利回撤>70%，上限50",IF(AND(AC7<>"",AC7>0.2),"少数股东/治理侵蚀>20%，上限60",""))))) | AH7: =IF(AD7="数据不足","",MIN(AD7,AF7)) | AI7: =IF(AH7="","NA",IF(AH7>=80,"A",IF(AH7>=65,"B",IF(AH7>=50,"C","D")))) | AJ7: =COUNTA(F7,G7,H7,K7,O7,P7,S7,T7,W7,Y7,AB7,AC7)/12 | AK7: 净负债2734.9亿元；少数股东119.8亿元；FCF/EBITDA/资本开支待填
A8: 4 | B8: 中国神华 | C8: 601088.SH | D8: A股 | E8: 煤炭 | F8: 51.99 | G8: 1.95 | H8: 216.89434 | I8: =IF(OR(G8="",H8=""),"",G8*H8) | J8: =IF(OR(F8="",G8=""),"",G8/F8) | K8: 266.59 | L8: =IF(OR(I8="",K8=""),"",I8/K8) | N8: =IF(AND(L8="",M8=""),"",IF(IF(M8<>"",M8,L8)<=0.5,95,IF(IF(M8<>"",M8,L8)<=0.7,82,IF(IF(M8<>"",M8,L8)<=0.9,67,IF(IF(M8<>"",M8,L8)<=1,50,25))))) | O8: 285.9 | Q8: =IF(OR(O8="",P8=""),"",IF(P8<=0,"",O8/P8)) | R8: =IF(Q8="","",IF(Q8<=0,95,IF(Q8<=1,85,IF(Q8<=2,72,IF(Q8<=3,58,IF(Q8<=4,42,20)))))) | U8: =IF(OR(S8="",T8=""),"",S8/T8) | V8: =IF(U8="","",IF(U8<=0.8,90,IF(U8<=1.2,78,IF(U8<=1.8,62,IF(U8<=2.5,42,20))))) | X8: =IF(W8="","",IF(W8<=0.15,92,IF(W8<=0.3,78,IF(W8<=0.5,60,IF(W8<=0.7,40,20))))) | Z8: =IF(Y8="","",IF(Y8=0,90,IF(Y8=1,50,20))) | AD8: =IF(COUNT(N8,R8,V8,X8,Z8,AB8)<6,"数据不足",0.25*N8+0.2*R8+0.15*V8+0.15*X8+0.15*Z8+0.1*AB8) | AF8: =IF(AE8="是",40,IF(AND(Q8<>"",Q8>4),30,IF(AND(Y8<>"",Y8>=1),50,IF(AND(W8<>"",W8>0.7),50,IF(AND(AC8<>"",AC8>0.2),60,100))))) | AG8: =IF(AE8="是","FCF派息率连续2年>100%，上限40",IF(AND(Q8<>"",Q8>4),"净负债/EBITDA>4，上限30",IF(AND(Y8<>"",Y8>=1),"近5年砍息，上限50",IF(AND(W8<>"",W8>0.7),"5年净利回撤>70%，上限50",IF(AND(AC8<>"",AC8>0.2),"少数股东/治理侵蚀>20%，上限60",""))))) | AH8: =IF(AD8="数据不足","",MIN(AD8,AF8)) | AI8: =IF(AH8="","NA",IF(AH8>=80,"A",IF(AH8>=65,"B",IF(AH8>=50,"C","D")))) | AJ8: =COUNTA(F8,G8,H8,K8,O8,P8,S8,T8,W8,Y8,AB8,AC8)/12 | AK8: FY2025 FCF 266.59亿元；2026E DPS 1.95元；单年FCF派息率约159%，需核连续性与资本开支口径
A9: 5 | B9: 可口可乐 | C9: KO | D9: 美股 | E9: 必选消费 | I9: =IF(OR(G9="",H9=""),"",G9*H9) | J9: =IF(OR(F9="",G9=""),"",G9/F9) | L9: =IF(OR(I9="",K9=""),"",I9/K9) | N9: =IF(AND(L9="",M9=""),"",IF(IF(M9<>"",M9,L9)<=0.5,95,IF(IF(M9<>"",M9,L9)<=0.7,82,IF(IF(M9<>"",M9,L9)<=0.9,67,IF(IF(M9<>"",M9,L9)<=1,50,25))))) | Q9: =IF(OR(O9="",P9=""),"",IF(P9<=0,"",O9/P9)) | R9: =IF(Q9="","",IF(Q9<=0,95,IF(Q9<=1,85,IF(Q9<=2,72,IF(Q9<=3,58,IF(Q9<=4,42,20)))))) | U9: =IF(OR(S9="",T9=""),"",S9/T9) | V9: =IF(U9="","",IF(U9<=0.8,90,IF(U9<=1.2,78,IF(U9<=1.8,62,IF(U9<=2.5,42,20))))) | X9: =IF(W9="","",IF(W9<=0.15,92,IF(W9<=0.3,78,IF(W9<=0.5,60,IF(W9<=0.7,40,20))))) | Z9: =IF(Y9="","",IF(Y9=0,90,IF(Y9=1,50,20))) | AD9: =IF(COUNT(N9,R9,V9,X9,Z9,AB9)<6,"数据不足",0.25*N9+0.2*R9+0.15*V9+0.15*X9+0.15*Z9+0.1*AB9) | AF9: =IF(AE9="是",40,IF(AND(Q9<>"",Q9>4),30,IF(AND(Y9<>"",Y9>=1),50,IF(AND(W9<>"",W9>0.7),50,IF(AND(AC9<>"",AC9>0.2),60,100))))) | AG9: =IF(AE9="是","FCF派息率连续2年>100%，上限40",IF(AND(Q9<>"",Q9>4),"净负债/EBITDA>4，上限30",IF(AND(Y9<>"",Y9>=1),"近5年砍息，上限50",IF(AND(W9<>"",W9>0.7),"5年净利回撤>70%，上限50",IF(AND(AC9<>"",AC9>0.2),"少数股东/治理侵蚀>20%，上限60",""))))) | AH9: =IF(AD9="数据不足","",MIN(AD9,AF9)) | AI9: =IF(AH9="","NA",IF(AH9>=80,"A",IF(AH9>=65,"B",IF(AH9>=50,"C","D")))) | AJ9: =COUNTA(F9,G9,H9,K9,O9,P9,S9,T9,W9,Y9,AB9,AC9)/12 | AK9: PE约27倍；股息率/FCF待填
A10: 6 | B10: 中国移动 | C10: 600941.SH | D10: A股 | E10: 运营商 | I10: =IF(OR(G10="",H10=""),"",G10*H10) | J10: =IF(OR(F10="",G10=""),"",G10/F10) | L10: =IF(OR(I10="",K10=""),"",I10/K10) | N10: =IF(AND(L10="",M10=""),"",IF(IF(M10<>"",M10,L10)<=0.5,95,IF(IF(M10<>"",M10,L10)<=0.7,82,IF(IF(M10<>"",M10,L10)<=0.9,67,IF(IF(M10<>"",M10,L10)<=1,50,25))))) | Q10: =IF(OR(O10="",P10=""),"",IF(P10<=0,"",O10/P10)) | R10: =IF(Q10="","",IF(Q10<=0,95,IF(Q10<=1,85,IF(Q10<=2,72,IF(Q10<=3,58,IF(Q10<=4,42,20)))))) | U10: =IF(OR(S10="",T10=""),"",S10/T10) | V10: =IF(U10="","",IF(U10<=0.8,90,IF(U10<=1.2,78,IF(U10<=1.8,62,IF(U10<=2.5,42,20))))) | X10: =IF(W10="","",IF(W10<=0.15,92,IF(W10<=0.3,78,IF(W10<=0.5,60,IF(W10<=0.7,40,20))))) | Z10: =IF(Y10="","",IF(Y10=0,90,IF(Y10=1,50,20))) | AD10: =IF(COUNT(N10,R10,V10,X10,Z10,AB10)<6,"数据不足",0.25*N10+0.2*R10+0.15*V10+0.15*X10+0.15*Z10+0.1*AB10) | AF10: =IF(AE10="是",40,IF(AND(Q10<>"",Q10>4),30,IF(AND(Y10<>"",Y10>=1),50,IF(AND(W10<>"",W10>0.7),50,IF(AND(AC10<>"",AC10>0.2),60,100))))) | AG10: =IF(AE10="是","FCF派息率连续2年>100%，上限40",IF(AND(Q10<>"",Q10>4),"净负债/EBITDA>4，上限30",IF(AND(Y10<>"",Y10>=1),"近5年砍息，上限50",IF(AND(W10<>"",W10>0.7),"5年净利回撤>70%，上限50",IF(AND(AC10<>"",AC10>0.2),"少数股东/治理侵蚀>20%，上限60",""))))) | AH10: =IF(AD10="数据不足","",MIN(AD10,AF10)) | AI10: =IF(AH10="","NA",IF(AH10>=80,"A",IF(AH10>=65,"B",IF(AH10>=50,"C","D")))) | AJ10: =COUNTA(F10,G10,H10,K10,O10,P10,S10,T10,W10,Y10,AB10,AC10)/12 | AK10: 待研究；观察池候选
A11: 7 | B11: 宁沪高速 | C11: 600377.SH | D11: A股 | E11: 高速公路 | I11: =IF(OR(G11="",H11=""),"",G11*H11) | J11: =IF(OR(F11="",G11=""),"",G11/F11) | L11: =IF(OR(I11="",K11=""),"",I11/K11) | N11: =IF(AND(L11="",M11=""),"",IF(IF(M11<>"",M11,L11)<=0.5,95,IF(IF(M11<>"",M11,L11)<=0.7,82,IF(IF(M11<>"",M11,L11)<=0.9,67,IF(IF(M11<>"",M11,L11)<=1,50,25))))) | Q11: =IF(OR(O11="",P11=""),"",IF(P11<=0,"",O11/P11)) | R11: =IF(Q11="","",IF(Q11<=0,95,IF(Q11<=1,85,IF(Q11<=2,72,IF(Q11<=3,58,IF(Q11<=4,42,20)))))) | U11: =IF(OR(S11="",T11=""),"",S11/T11) | V11: =IF(U11="","",IF(U11<=0.8,90,IF(U11<=1.2,78,IF(U11<=1.8,62,IF(U11<=2.5,42,20))))) | X11: =IF(W11="","",IF(W11<=0.15,92,IF(W11<=0.3,78,IF(W11<=0.5,60,IF(W11<=0.7,40,20))))) | Z11: =IF(Y11="","",IF(Y11=0,90,IF(Y11=1,50,20))) | AD11: =IF(COUNT(N11,R11,V11,X11,Z11,AB11)<6,"数据不足",0.25*N11+0.2*R11+0.15*V11+0.15*X11+0.15*Z11+0.1*AB11) | AF11: =IF(AE11="是",40,IF(AND(Q11<>"",Q11>4),30,IF(AND(Y11<>"",Y11>=1),50,IF(AND(W11<>"",W11>0.7),50,IF(AND(AC11<>"",AC11>0.2),60,100))))) | AG11: =IF(AE11="是","FCF派息率连续2年>100%，上限40",IF(AND(Q11<>"",Q11>4),"净负债/EBITDA>4，上限30",IF(AND(Y11<>"",Y11>=1),"近5年砍息，上限50",IF(AND(W11<>"",W11>0.7),"5年净利回撤>70%，上限50",IF(AND(AC11<>"",AC11>0.2),"少数股东/治理侵蚀>20%，上限60",""))))) | AH11: =IF(AD11="数据不足","",MIN(AD11,AF11)) | AI11: =IF(AH11="","NA",IF(AH11>=80,"A",IF(AH11>=65,"B",IF(AH11>=50,"C","D")))) | AJ11: =COUNTA(F11,G11,H11,K11,O11,P11,S11,T11,W11,Y11,AB11,AC11)/12 | AK11: 待研究；观察池候选

Sheet 金融红利
A1: 金融红利 · 银行/保险引用区
A2: 银行不套用 FCF 六维评分；四维评分与 DDM 引用银行 skill。综合分固定权重：盈利 30 / 风险资本 30 / 估值 25 / 股息 15。保险暂标记待补。
A4: 序号 | B4: 标的 | C4: 代码 | D4: 市场 | E4: 类型 | F4: 盈利质量 | G4: 风险资本 | H4: 估值 | I4: 股息 | J4: 银行 skill 综合分 | K4: DDM防御价值 | L4: 现价 | M4: DDM安全边际 | N4: 股息率 | O4: 估值分 | P4: 结论 | Q4: 数据日期 | R4: 备注
A5: 1 | B5: 工商银行 | C5: 601398.SH | D5: A股 | E5: 银行 | J5: =IF(COUNT(F5:I5)<4,"数据不足",0.3*F5+0.3*G5+0.25*H5+0.15*I5) | M5: =IF(OR(K5="",L5=""),"",1-L5/K5) | N5: 0.036 | O5: =IF(M5="","",IF(M5>=0.2,95,IF(M5>=0.05,80,IF(M5>=-0.05,60,IF(M5>=-0.2,40,20))))) | P5: 合理偏低；ROE 低于股权成本 | Q5: 2026-10-30 | R5: 引用银行 skill 四维评分；DDM/RI 基准待填
A6: 2 | B6: 平安银行 | C6: 000001.SZ | D6: A股 | E6: 银行 | J6: =IF(COUNT(F6:I6)<4,"数据不足",0.3*F6+0.3*G6+0.25*H6+0.15*I6) | M6: =IF(OR(K6="",L6=""),"",1-L6/K6) | N6: 0.056 | O6: =IF(M6="","",IF(M6>=0.2,95,IF(M6>=0.05,80,IF(M6>=-0.05,60,IF(M6>=-0.2,40,20))))) | P6: 合理偏贵；ROE 低于股权成本 | Q6: 2026-10-30 | R6: DDM 8.13，综合基准 11.03；现价 11.64
A7: 3 | B7: 北京银行 | C7: 601169.SH | D7: A股 | E7: 银行 | J7: =IF(COUNT(F7:I7)<4,"数据不足",0.3*F7+0.3*G7+0.25*H7+0.15*I7) | M7: =IF(OR(K7="",L7=""),"",1-L7/K7) | O7: =IF(M7="","",IF(M7>=0.2,95,IF(M7>=0.05,80,IF(M7>=-0.05,60,IF(M7>=-0.2,40,20))))) | P7: 待引用银行 skill | R7: 旧 Excel 10 表，需按 11 表规范复核
A8: 4 | B8: 宁波银行 | C8: 002142.SZ | D8: A股 | E8: 银行 | J8: =IF(COUNT(F8:I8)<4,"数据不足",0.3*F8+0.3*G8+0.25*H8+0.15*I8) | M8: =IF(OR(K8="",L8=""),"",1-L8/K8) | O8: =IF(M8="","",IF(M8>=0.2,95,IF(M8>=0.05,80,IF(M8>=-0.05,60,IF(M8>=-0.2,40,20))))) | P8: 待引用银行 skill | R8: 旧 Excel 10 表，需按 11 表规范复核

Sheet 质量防御
A1: 质量防御 · 五维评分
A2: 质量分 60% + 估值分 40%
A4: 序号 | B4: 标的 | C4: 代码 | D4: 市场 | E4: 类型 | F4: ROIC | G4: WACC | H4: ROIC-WACC | I4: ROIC得分 | J4: 资本强度 | K4: 资本强度得分 | L4: 5年FCF波动 | M4: 现金流稳定性得分 | N4: 净现金/市值 | O4: 资产负债表得分 | P4: 回购收益率 | Q4: 股东回报得分 | R4: 质量分 | S4: DCF基准价 | T4: 现价 | U4: 安全边际 | V4: 估值分 | W4: 综合分 | X4: 等级 | Y4: 结论 | Z4: 数据日期 | AA4: 备注
A5: 1 | B5: 伯克希尔 | C5: BRK.B | D5: 美股 | E5: 综合控股 | H5: =IF(OR(F5="",G5=""),"",F5-G5) | I5: =IF(H5="","",IF(H5>=0.15,95,IF(H5>=0.1,85,IF(H5>=0.05,70,IF(H5>=0,50,20))))) | K5: =IF(J5="","",IF(J5<=0.03,95,IF(J5<=0.06,82,IF(J5<=0.1,65,IF(J5<=0.15,45,25))))) | M5: =IF(L5="","",IF(L5<=0.1,95,IF(L5<=0.2,82,IF(L5<=0.3,65,IF(L5<=0.5,45,25))))) | O5: =IF(N5="","",IF(N5>=0.1,95,IF(N5>=0.05,85,IF(N5>=0,70,IF(N5>=-0.05,55,30))))) | Q5: =IF(P5="","",IF(P5>=0.03,95,IF(P5>=0.02,85,IF(P5>=0.01,70,IF(P5>0,55,40))))) | R5: =IF(COUNT(I5,K5,M5,O5,Q5)<5,"数据不足",0.3*I5+0.2*K5+0.2*M5+0.15*O5+0.15*Q5) | U5: =IF(OR(S5="",T5=""),"",1-T5/S5) | V5: =IF(U5="","",IF(U5>=0.2,95,IF(U5>=0.05,80,IF(U5>=-0.05,60,IF(U5>=-0.2,40,20))))) | W5: =IF(AND(ISNUMBER(R5),ISNUMBER(V5)),0.6*R5+0.4*V5,"") | X5: =IF(ISNUMBER(W5),IF(W5>=80,"A",IF(W5>=65,"B",IF(W5>=50,"C","D"))),"") | Y5: 合理区间上沿，安全边际不足 | Z5: 2026-10-30 | AA5: 非股息型；现金与上市股权提供资产负债表防御
A6: 2 | B6: Visa | C6: V | D6: 美股 | E6: 支付 | H6: =IF(OR(F6="",G6=""),"",F6-G6) | I6: =IF(H6="","",IF(H6>=0.15,95,IF(H6>=0.1,85,IF(H6>=0.05,70,IF(H6>=0,50,20))))) | K6: =IF(J6="","",IF(J6<=0.03,95,IF(J6<=0.06,82,IF(J6<=0.1,65,IF(J6<=0.15,45,25))))) | M6: =IF(L6="","",IF(L6<=0.1,95,IF(L6<=0.2,82,IF(L6<=0.3,65,IF(L6<=0.5,45,25))))) | O6: =IF(N6="","",IF(N6>=0.1,95,IF(N6>=0.05,85,IF(N6>=0,70,IF(N6>=-0.05,55,30))))) | Q6: =IF(P6="","",IF(P6>=0.03,95,IF(P6>=0.02,85,IF(P6>=0.01,70,IF(P6>0,55,40))))) | R6: =IF(COUNT(I6,K6,M6,O6,Q6)<5,"数据不足",0.3*I6+0.2*K6+0.2*M6+0.15*O6+0.15*Q6) | S6: 424.63 | T6: 400.6 | U6: =IF(OR(S6="",T6=""),"",1-T6/S6) | V6: =IF(U6="","",IF(U6>=0.2,95,IF(U6>=0.05,80,IF(U6>=-0.05,60,IF(U6>=-0.2,40,20))))) | W6: =IF(AND(ISNUMBER(R6),ISNUMBER(V6)),0.6*R6+0.4*V6,"") | X6: =IF(ISNUMBER(W6),IF(W6>=80,"A",IF(W6>=65,"B",IF(W6>=50,"C","D"))),"") | Y6: 合理偏低，安全边际不足 | Z6: 2026-10-30 | AA6: PE 32.5x；股息率 0.78%；回购为主
A7: 3 | B7: 万事达卡 | C7: MA | D7: 美股 | E7: 支付 | H7: =IF(OR(F7="",G7=""),"",F7-G7) | I7: =IF(H7="","",IF(H7>=0.15,95,IF(H7>=0.1,85,IF(H7>=0.05,70,IF(H7>=0,50,20))))) | K7: =IF(J7="","",IF(J7<=0.03,95,IF(J7<=0.06,82,IF(J7<=0.1,65,IF(J7<=0.15,45,25))))) | M7: =IF(L7="","",IF(L7<=0.1,95,IF(L7<=0.2,82,IF(L7<=0.3,65,IF(L7<=0.5,45,25))))) | O7: =IF(N7="","",IF(N7>=0.1,95,IF(N7>=0.05,85,IF(N7>=0,70,IF(N7>=-0.05,55,30))))) | Q7: =IF(P7="","",IF(P7>=0.03,95,IF(P7>=0.02,85,IF(P7>=0.01,70,IF(P7>0,55,40))))) | R7: =IF(COUNT(I7,K7,M7,O7,Q7)<5,"数据不足",0.3*I7+0.2*K7+0.2*M7+0.15*O7+0.15*Q7) | S7: 666.31 | T7: 610.31 | U7: =IF(OR(S7="",T7=""),"",1-T7/S7) | V7: =IF(U7="","",IF(U7>=0.2,95,IF(U7>=0.05,80,IF(U7>=-0.05,60,IF(U7>=-0.2,40,20))))) | W7: =IF(AND(ISNUMBER(R7),ISNUMBER(V7)),0.6*R7+0.4*V7,"") | X7: =IF(ISNUMBER(W7),IF(W7>=80,"A",IF(W7>=65,"B",IF(W7>=50,"C","D"))),"") | Y7: 合理偏低，安全边际不足 | Z7: 2026-10-30 | AA7: PE 33.6x；股息率 0.50%；回购为主

Sheet 总回报
A1: 总回报 · 税后股息 + 价格 + 汇率 − 10Y
A2: 税率、价格回报、汇率必须填写后，总回报才计算；空缺不是 0。10Y 为本地 10 年期国债收益率。
A4: 序号 | B4: 标的 | C4: 代码 | D4: 市场 | E4: 币种 | F4: 现价 | G4: 2026E DPS | H4: 股息率 | I4: 本地10Y | J4: 股息-10Y | K4: 预期DPS增长 | L4: 预期价格回报 | M4: 汇率变动 | N4: 税率 | O4: 税后股息率 | P4: 税后总回报 | Q4: 总回报-10Y | R4: 估值基准价 | S4: 安全边际 | T4: 估值分 | U4: 数据日期 | V4: 备注
A5: 1 | B5: 工商银行 | C5: 601398.SH | D5: A股 | E5: CNY | H5: =IF(AND(F5<>"",G5<>""),G5/F5,0.036) | I5: 0.0162 | J5: =IF(OR(H5="",I5=""),"",H5-I5) | O5: =IF(OR(H5="",N5=""),"",H5*(1-N5)) | P5: =IF(OR(O5="",L5="",M5=""),"",(1+O5)*(1+L5)*(1+M5)-1) | Q5: =IF(OR(P5="",I5=""),"",P5-I5) | S5: =IF(OR(R5="",F5=""),"",1-F5/R5) | T5: =IF(AND(Q5="",S5=""),"",IF(AND(Q5<>"",S5<>""),0.5*IF(Q5>=0.06,95,IF(Q5>=0.04,82,IF(Q5>=0.02,68,IF(Q5>=0,52,IF(Q5>=-0.02,38,20)))))+0.5*IF(S5>=0.2,95,IF(S5>=0.05,80,IF(S5>=-0.05,60,IF(S5>=-0.2,40,20)))),IF(S5<>"",IF(S5>=0.2,95,IF(S5>=0.05,80,IF(S5>=-0.05,60,IF(S5>=-0.2,40,20)))),IF(Q5>=0.06,95,IF(Q5>=0.04,82,IF(Q5>=0.02,68,IF(Q5>=0,52,IF(Q5>=-0.02,38,20)))))))) | U5: 2026-10-30 | V5: 股息率 3.6%；价格/DPS 待填
A6: 2 | B6: 平安银行 | C6: 000001.SZ | D6: A股 | E6: CNY | F6: 11.64 | G6: 0.65 | H6: =IF(AND(F6<>"",G6<>""),G6/F6,"") | I6: 0.0162 | J6: =IF(OR(H6="",I6=""),"",H6-I6) | O6: =IF(OR(H6="",N6=""),"",H6*(1-N6)) | P6: =IF(OR(O6="",L6="",M6=""),"",(1+O6)*(1+L6)*(1+M6)-1) | Q6: =IF(OR(P6="",I6=""),"",P6-I6) | R6: 11.03 | S6: =IF(OR(R6="",F6=""),"",1-F6/R6) | T6: =IF(AND(Q6="",S6=""),"",IF(AND(Q6<>"",S6<>""),0.5*IF(Q6>=0.06,95,IF(Q6>=0.04,82,IF(Q6>=0.02,68,IF(Q6>=0,52,IF(Q6>=-0.02,38,20)))))+0.5*IF(S6>=0.2,95,IF(S6>=0.05,80,IF(S6>=-0.05,60,IF(S6>=-0.2,40,20)))),IF(S6<>"",IF(S6>=0.2,95,IF(S6>=0.05,80,IF(S6>=-0.05,60,IF(S6>=-0.2,40,20)))),IF(Q6>=0.06,95,IF(Q6>=0.04,82,IF(Q6>=0.02,68,IF(Q6>=0,52,IF(Q6>=-0.02,38,20)))))))) | U6: 2026-10-30 | V6: 综合基准 11.03；税率待填
A7: 3 | B7: 美的集团 | C7: 000333.SZ | D7: A股 | E7: CNY | H7: =IF(AND(F7<>"",G7<>""),G7/F7,0.049) | I7: 0.0162 | J7: =IF(OR(H7="",I7=""),"",H7-I7) | O7: =IF(OR(H7="",N7=""),"",H7*(1-N7)) | P7: =IF(OR(O7="",L7="",M7=""),"",(1+O7)*(1+L7)*(1+M7)-1) | Q7: =IF(OR(P7="",I7=""),"",P7-I7) | S7: =IF(OR(R7="",F7=""),"",1-F7/R7) | T7: =IF(AND(Q7="",S7=""),"",IF(AND(Q7<>"",S7<>""),0.5*IF(Q7>=0.06,95,IF(Q7>=0.04,82,IF(Q7>=0.02,68,IF(Q7>=0,52,IF(Q7>=-0.02,38,20)))))+0.5*IF(S7>=0.2,95,IF(S7>=0.05,80,IF(S7>=-0.05,60,IF(S7>=-0.2,40,20)))),IF(S7<>"",IF(S7>=0.2,95,IF(S7>=0.05,80,IF(S7>=-0.05,60,IF(S7>=-0.2,40,20)))),IF(Q7>=0.06,95,IF(Q7>=0.04,82,IF(Q7>=0.02,68,IF(Q7>=0,52,IF(Q7>=-0.02,38,20)))))))) | U7: 2026-10-30 | V7: 股息率约4.9%；价格/DPS待填
A8: 4 | B8: 贵州茅台 | C8: 600519.SH | D8: A股 | E8: CNY | H8: =IF(AND(F8<>"",G8<>""),G8/F8,0.038) | I8: 0.0162 | J8: =IF(OR(H8="",I8=""),"",H8-I8) | O8: =IF(OR(H8="",N8=""),"",H8*(1-N8)) | P8: =IF(OR(O8="",L8="",M8=""),"",(1+O8)*(1+L8)*(1+M8)-1) | Q8: =IF(OR(P8="",I8=""),"",P8-I8) | S8: =IF(OR(R8="",F8=""),"",1-F8/R8) | T8: =IF(AND(Q8="",S8=""),"",IF(AND(Q8<>"",S8<>""),0.5*IF(Q8>=0.06,95,IF(Q8>=0.04,82,IF(Q8>=0.02,68,IF(Q8>=0,52,IF(Q8>=-0.02,38,20)))))+0.5*IF(S8>=0.2,95,IF(S8>=0.05,80,IF(S8>=-0.05,60,IF(S8>=-0.2,40,20)))),IF(S8<>"",IF(S8>=0.2,95,IF(S8>=0.05,80,IF(S8>=-0.05,60,IF(S8>=-0.2,40,20)))),IF(Q8>=0.06,95,IF(Q8>=0.04,82,IF(Q8>=0.02,68,IF(Q8>=0,52,IF(Q8>=-0.02,38,20)))))))) | U8: 2026-10-30 | V8: 股息率约3.8%；价格/DPS待填
A9: 5 | B9: 长江电力 | C9: 600900.SH | D9: A股 | E9: CNY | F9: 29.74 | G9: 0.92 | H9: =IF(AND(F9<>"",G9<>""),G9/F9,"") | I9: 0.0162 | J9: =IF(OR(H9="",I9=""),"",H9-I9) | O9: =IF(OR(H9="",N9=""),"",H9*(1-N9)) | P9: =IF(OR(O9="",L9="",M9=""),"",(1+O9)*(1+L9)*(1+M9)-1) | Q9: =IF(OR(P9="",I9=""),"",P9-I9) | R9: 27.59 | S9: =IF(OR(R9="",F9=""),"",1-F9/R9) | T9: =IF(AND(Q9="",S9=""),"",IF(AND(Q9<>"",S9<>""),0.5*IF(Q9>=0.06,95,IF(Q9>=0.04,82,IF(Q9>=0.02,68,IF(Q9>=0,52,IF(Q9>=-0.02,38,20)))))+0.5*IF(S9>=0.2,95,IF(S9>=0.05,80,IF(S9>=-0.05,60,IF(S9>=-0.2,40,20)))),IF(S9<>"",IF(S9>=0.2,95,IF(S9>=0.05,80,IF(S9>=-0.05,60,IF(S9>=-0.2,40,20)))),IF(Q9>=0.06,95,IF(Q9>=0.04,82,IF(Q9>=0.02,68,IF(Q9>=0,52,IF(Q9>=-0.02,38,20)))))))) | U9: 2026-10-30 | V9: DCF/DDM 基准 27.59；税率待填
A10: 6 | B10: 中国神华 | C10: 601088.SH | D10: A股 | E10: CNY | F10: 51.99 | G10: 1.95 | H10: =IF(AND(F10<>"",G10<>""),G10/F10,"") | I10: 0.0162 | J10: =IF(OR(H10="",I10=""),"",H10-I10) | O10: =IF(OR(H10="",N10=""),"",H10*(1-N10)) | P10: =IF(OR(O10="",L10="",M10=""),"",(1+O10)*(1+L10)*(1+M10)-1) | Q10: =IF(OR(P10="",I10=""),"",P10-I10) | R10: 36.64 | S10: =IF(OR(R10="",F10=""),"",1-F10/R10) | T10: =IF(AND(Q10="",S10=""),"",IF(AND(Q10<>"",S10<>""),0.5*IF(Q10>=0.06,95,IF(Q10>=0.04,82,IF(Q10>=0.02,68,IF(Q10>=0,52,IF(Q10>=-0.02,38,20)))))+0.5*IF(S10>=0.2,95,IF(S10>=0.05,80,IF(S10>=-0.05,60,IF(S10>=-0.2,40,20)))),IF(S10<>"",IF(S10>=0.2,95,IF(S10>=0.05,80,IF(S10>=-0.05,60,IF(S10>=-0.2,40,20)))),IF(Q10>=0.06,95,IF(Q10>=0.04,82,IF(Q10>=0.02,68,IF(Q10>=0,52,IF(Q10>=-0.02,38,20)))))))) | U10: 2026-10-30 | V10: 三法基准 36.64；税率待填
A11: 7 | B11: 可口可乐 | C11: KO | D11: 美股 | E11: USD | H11: =IF(AND(F11<>"",G11<>""),G11/F11,"") | I11: 0.049 | J11: =IF(OR(H11="",I11=""),"",H11-I11) | O11: =IF(OR(H11="",N11=""),"",H11*(1-N11)) | P11: =IF(OR(O11="",L11="",M11=""),"",(1+O11)*(1+L11)*(1+M11)-1) | Q11: =IF(OR(P11="",I11=""),"",P11-I11) | S11: =IF(OR(R11="",F11=""),"",1-F11/R11) | T11: =IF(AND(Q11="",S11=""),"",IF(AND(Q11<>"",S11<>""),0.5*IF(Q11>=0.06,95,IF(Q11>=0.04,82,IF(Q11>=0.02,68,IF(Q11>=0,52,IF(Q11>=-0.02,38,20)))))+0.5*IF(S11>=0.2,95,IF(S11>=0.05,80,IF(S11>=-0.05,60,IF(S11>=-0.2,40,20)))),IF(S11<>"",IF(S11>=0.2,95,IF(S11>=0.05,80,IF(S11>=-0.05,60,IF(S11>=-0.2,40,20)))),IF(Q11>=0.06,95,IF(Q11>=0.04,82,IF(Q11>=0.02,68,IF(Q11>=0,52,IF(Q11>=-0.02,38,20)))))))) | U11: 2026-10-30 | V11: PE 27x；价格/DPS待填
A12: 8 | B12: 中国移动 | C12: 600941.SH | D12: A股 | E12: CNY | H12: =IF(AND(F12<>"",G12<>""),G12/F12,"") | I12: 0.0162 | J12: =IF(OR(H12="",I12=""),"",H12-I12) | O12: =IF(OR(H12="",N12=""),"",H12*(1-N12)) | P12: =IF(OR(O12="",L12="",M12=""),"",(1+O12)*(1+L12)*(1+M12)-1) | Q12: =IF(OR(P12="",I12=""),"",P12-I12) | S12: =IF(OR(R12="",F12=""),"",1-F12/R12) | T12: =IF(AND(Q12="",S12=""),"",IF(AND(Q12<>"",S12<>""),0.5*IF(Q12>=0.06,95,IF(Q12>=0.04,82,IF(Q12>=0.02,68,IF(Q12>=0,52,IF(Q12>=-0.02,38,20)))))+0.5*IF(S12>=0.2,95,IF(S12>=0.05,80,IF(S12>=-0.05,60,IF(S12>=-0.2,40,20)))),IF(S12<>"",IF(S12>=0.2,95,IF(S12>=0.05,80,IF(S12>=-0.05,60,IF(S12>=-0.2,40,20)))),IF(Q12>=0.06,95,IF(Q12>=0.04,82,IF(Q12>=0.02,68,IF(Q12>=0,52,IF(Q12>=-0.02,38,20)))))))) | U12: 2026-10-30 | V12: 待研究
A13: 9 | B13: 宁沪高速 | C13: 600377.SH | D13: A股 | E13: CNY | H13: =IF(AND(F13<>"",G13<>""),G13/F13,"") | I13: 0.0162 | J13: =IF(OR(H13="",I13=""),"",H13-I13) | O13: =IF(OR(H13="",N13=""),"",H13*(1-N13)) | P13: =IF(OR(O13="",L13="",M13=""),"",(1+O13)*(1+L13)*(1+M13)-1) | Q13: =IF(OR(P13="",I13=""),"",P13-I13) | S13: =IF(OR(R13="",F13=""),"",1-F13/R13) | T13: =IF(AND(Q13="",S13=""),"",IF(AND(Q13<>"",S13<>""),0.5*IF(Q13>=0.06,95,IF(Q13>=0.04,82,IF(Q13>=0.02,68,IF(Q13>=0,52,IF(Q13>=-0.02,38,20)))))+0.5*IF(S13>=0.2,95,IF(S13>=0.05,80,IF(S13>=-0.05,60,IF(S13>=-0.2,40,20)))),IF(S13<>"",IF(S13>=0.2,95,IF(S13>=0.05,80,IF(S13>=-0.05,60,IF(S13>=-0.2,40,20)))),IF(Q13>=0.06,95,IF(Q13>=0.04,82,IF(Q13>=0.02,68,IF(Q13>=0,52,IF(Q13>=-0.02,38,20)))))))) | U13: 2026-10-30 | V13: 待研究
A14: 10 | B14: 伯克希尔 | C14: BRK.B | D14: 美股 | E14: USD | H14: =IF(AND(F14<>"",G14<>""),G14/F14,"") | I14: 0.049 | J14: =IF(OR(H14="",I14=""),"",H14-I14) | O14: =IF(OR(H14="",N14=""),"",H14*(1-N14)) | P14: =IF(OR(O14="",L14="",M14=""),"",(1+O14)*(1+L14)*(1+M14)-1) | Q14: =IF(OR(P14="",I14=""),"",P14-I14) | S14: =IF(OR(R14="",F14=""),"",1-F14/R14) | T14: =IF(AND(Q14="",S14=""),"",IF(AND(Q14<>"",S14<>""),0.5*IF(Q14>=0.06,95,IF(Q14>=0.04,82,IF(Q14>=0.02,68,IF(Q14>=0,52,IF(Q14>=-0.02,38,20)))))+0.5*IF(S14>=0.2,95,IF(S14>=0.05,80,IF(S14>=-0.05,60,IF(S14>=-0.2,40,20)))),IF(S14<>"",IF(S14>=0.2,95,IF(S14>=0.05,80,IF(S14>=-0.05,60,IF(S14>=-0.2,40,20)))),IF(Q14>=0.06,95,IF(Q14>=0.04,82,IF(Q14>=0.02,68,IF(Q14>=0,52,IF(Q14>=-0.02,38,20)))))))) | U14: 2026-10-30 | V14: 非股息型；价格/DCF待填
A15: 11 | B15: Visa | C15: V | D15: 美股 | E15: USD | F15: 400.6 | H15: =IF(AND(F15<>"",G15<>""),G15/F15,0.0078) | I15: 0.049 | J15: =IF(OR(H15="",I15=""),"",H15-I15) | O15: =IF(OR(H15="",N15=""),"",H15*(1-N15)) | P15: =IF(OR(O15="",L15="",M15=""),"",(1+O15)*(1+L15)*(1+M15)-1) | Q15: =IF(OR(P15="",I15=""),"",P15-I15) | R15: 424.63 | S15: =IF(OR(R15="",F15=""),"",1-F15/R15) | T15: =IF(AND(Q15="",S15=""),"",IF(AND(Q15<>"",S15<>""),0.5*IF(Q15>=0.06,95,IF(Q15>=0.04,82,IF(Q15>=0.02,68,IF(Q15>=0,52,IF(Q15>=-0.02,38,20)))))+0.5*IF(S15>=0.2,95,IF(S15>=0.05,80,IF(S15>=-0.05,60,IF(S15>=-0.2,40,20)))),IF(S15<>"",IF(S15>=0.2,95,IF(S15>=0.05,80,IF(S15>=-0.05,60,IF(S15>=-0.2,40,20)))),IF(Q15>=0.06,95,IF(Q15>=0.04,82,IF(Q15>=0.02,68,IF(Q15>=0,52,IF(Q15>=-0.02,38,20)))))))) | U15: 2026-10-30 | V15: 股息率0.78%；DCF 424.63
A16: 12 | B16: 万事达卡 | C16: MA | D16: 美股 | E16: USD | F16: 610.31 | H16: =IF(AND(F16<>"",G16<>""),G16/F16,0.005) | I16: 0.049 | J16: =IF(OR(H16="",I16=""),"",H16-I16) | O16: =IF(OR(H16="",N16=""),"",H16*(1-N16)) | P16: =IF(OR(O16="",L16="",M16=""),"",(1+O16)*(1+L16)*(1+M16)-1) | Q16: =IF(OR(P16="",I16=""),"",P16-I16) | R16: 666.31 | S16: =IF(OR(R16="",F16=""),"",1-F16/R16) | T16: =IF(AND(Q16="",S16=""),"",IF(AND(Q16<>"",S16<>""),0.5*IF(Q16>=0.06,95,IF(Q16>=0.04,82,IF(Q16>=0.02,68,IF(Q16>=0,52,IF(Q16>=-0.02,38,20)))))+0.5*IF(S16>=0.2,95,IF(S16>=0.05,80,IF(S16>=-0.05,60,IF(S16>=-0.2,40,20)))),IF(S16<>"",IF(S16>=0.2,95,IF(S16>=0.05,80,IF(S16>=-0.05,60,IF(S16>=-0.2,40,20)))),IF(Q16>=0.06,95,IF(Q16>=0.04,82,IF(Q16>=0.02,68,IF(Q16>=0,52,IF(Q16>=-0.02,38,20)))))))) | U16: 2026-10-30 | V16: 股息率0.50%；DCF 666.31

Sheet 组合监控
A1: 组合监控 · 从单票到配置
A2: 示例约束，不是投资建议。权重、行业、利率敏感度、相关性、触发条件一起看。
A4: 标的 | B4: 类型 | C4: 行业 | D4: 目标权重 | E4: 当前权重 | F4: 股息率 | G4: 总回报 | H4: 利率敏感度 | I4: 相关性桶 | J4: 流动性 | K4: 最大回撤 | L4: 风险标签 | M4: 备注
A5: 工商银行 | B5: 金融红利 | C5: 银行 | F5: ='总回报'!H5 | G5: ='总回报'!P5
A6: 平安银行 | B6: 金融红利 | C6: 银行 | F6: ='总回报'!H6 | G6: ='总回报'!P6
A7: 美的集团 | B7: 一般红利 | C7: 家电 | F7: ='总回报'!H7 | G7: ='总回报'!P7
A8: 贵州茅台 | B8: 一般红利 | C8: 消费 | F8: ='总回报'!H8 | G8: ='总回报'!P8
A9: 长江电力 | B9: 一般红利/类债 | C9: 公用事业 | F9: ='总回报'!H9 | G9: ='总回报'!P9
A10: 中国神华 | B10: 一般红利 | C10: 煤炭 | F10: ='总回报'!H10 | G10: ='总回报'!P10
A11: 可口可乐 | B11: 一般红利 | C11: 消费 | F11: ='总回报'!H11 | G11: ='总回报'!P11
A12: 中国移动 | B12: 一般红利 | C12: 运营商 | F12: ='总回报'!H12 | G12: ='总回报'!P12
A13: 宁沪高速 | B13: 一般红利 | C13: 高速公路 | F13: ='总回报'!H13 | G13: ='总回报'!P13
A14: 伯克希尔 | B14: 质量防御 | C14: 控股 | F14: ='总回报'!H14 | G14: ='总回报'!P14
A15: Visa | B15: 质量防御 | C15: 支付 | F15: ='总回报'!H15 | G15: ='总回报'!P15
A16: 万事达卡 | B16: 质量防御 | C16: 支付 | F16: ='总回报'!H16 | G16: ='总回报'!P16
A18: 汇总
A19: 红利/类债合计 | C19: =SUMIF($B$5:$B$16,"*红利*",$D$5:$D$16)
A20: 质量防御合计 | C20: =SUMIF($B$5:$B$16,"质量防御",$D$5:$D$16)
A21: 最大单一权重 | C21: =MAX(D5:D16)
A22: 加权股息率 | C22: =IF(SUM(D5:D16)=0,"",SUMPRODUCT(D5:D16,F5:F16)/SUM(D5:D16))
A23: 加权总回报 | C23: =IF(SUM(D5:D16)=0,"",SUMPRODUCT(D5:D16,G5:G16)/SUM(D5:D16))
A24: 高利率敏感度占比 | C24: =IF(SUM(D5:D16)=0,"",SUMIF(H5:H16,"高",D5:D16)/SUM(D5:D16))
A25: 权重合计检查 | C25: =IF(ABS(SUM(D5:D16)-1)<0.001,"100%","未到 100%")
A28: 行业集中度
A29: 行业 | B29: 目标权重
A30: 银行 | B30: =SUMIF($C$5:$C$16,A30,$D$5:$D$16)
A31: 煤炭 | B31: =SUMIF($C$5:$C$16,A31,$D$5:$D$16)
A32: 公用事业 | B32: =SUMIF($C$5:$C$16,A32,$D$5:$D$16)
A33: 消费 | B33: =SUMIF($C$5:$C$16,A33,$D$5:$D$16)
A34: 支付 | B34: =SUMIF($C$5:$C$16,A34,$D$5:$D$16)
A35: 控股 | B35: =SUMIF($C$5:$C$16,A35,$D$5:$D$16)
A36: 家电 | B36: =SUMIF($C$5:$C$16,A36,$D$5:$D$16)
A37: 运营商 | B37: =SUMIF($C$5:$C$16,A37,$D$5:$D$16)
A38: 高速公路 | B38: =SUMIF($C$5:$C$16,A38,$D$5:$D$16)
A41: 触发条件
A42: 检查项 | B42: 状态 | C42: 动作
A43: 砍息 / 派息下调 | B43: 正常 | C43: 回到单票报告复核
A44: FCF 派息率连续 2 年 >100% | B44: 待核 | C44: 检查 FCF 口径与资本开支
A45: 净负债/EBITDA >4x | B45: 待核 | C45: 检查资产负债表与评级
A46: 现价高于基准价值 20% | B46: 待核 | C46: 减仓/不追高讨论
...

Sheet 数据与来源
A1: 数据与来源 · 证据账本
A2: 每个关键数字至少记录：来源、发布日、期间、原始值/单位、状态。状态可选：硬数据/软数据/假设/计算/待核。
A4: 标的 | B4: 字段 | C4: 数值 | D4: 单位 | E4: 来源 | F4: 发布日 | G4: 期间 | H4: 链接/附件 | I4: 状态 | J4: 备注
A5: 长江电力 | B5: 当前价 | C5: 29.74 | D5: 元/股 | E5: 腾讯行情 | F5: 2026-10-30 | G5: 2026-10-30 | I5: 硬数据 | J5: 收盘价口径
A6: 长江电力 | B6: 2026E DPS | C6: 0.92 | D6: 元/股 | E6: 公司公告/模型 | F6: 2026-10-30 | G6: 2026E | I6: 假设 | J6: 待按最新公告复核
A7: 长江电力 | B7: 净负债 | C7: 2734.9 | D7: 亿元 | E7: 2026 中报 | F7: 2026-08-31 | G7: 2026H1 | I7: 硬数据 | J7: 有息负债−货币资金口径待核
A8: 长江电力 | B8: FY2025 FCF | D8: 亿元 | E8: FY2025 年报 | G8: FY2025 | I8: 待核 | J8: 经营现金流−购建固定资产等支付的现金
A9: 中国神华 | B9: FY2025 FCF | C9: 266.59 | D9: 亿元 | E9: FY2025 年报 / 煤炭 skill | F9: 2026-10-30 | G9: FY2025 | I9: 硬数据 | J9: 煤炭 skill 锁死口径
A10: 中国神华 | B10: 2026E DPS | C10: 1.95 | D10: 元/股 | E10: 模型 | F10: 2026-10-30 | G10: 2026E | I10: 假设 | J10: 需按最新公告复核
A11: 中国神华 | B11: 净负债 | C11: 285.9 | D11: 亿元 | E11: 2026 中报 | F11: 2026-08-31 | G11: 2026H1 | I11: 硬数据 | J11: 有息负债−货币资金口径待核
A12: 平安银行 | B12: 当前价 | C12: 11.64 | D12: 元/股 | E12: 腾讯行情 | F12: 2026-10-30 | G12: 2026-10-30 | I12: 硬数据 | J12: 收盘价口径
A13: 平安银行 | B13: 综合基准 | C13: 11.03 | D13: 元/股 | E13: 巴菲特框架研究 | F13: 2026-10-30 | G13: 2026-10-30 | I13: 计算 | J13: RI 70% + DDM 30%
A14: 工商银行 | B14: 股息率 | C14: 0.036 | D14: % | E14: 巴菲特框架研究 | F14: 2026-10-29 | G14: 2026E | I14: 计算 | J14: 前瞻股息率
A15: Visa | B15: 当前价 | C15: 400.6 | D15: 美元/股 | E15: 腾讯行情 | F15: 2026-10-29 | G15: 2026-10-29 | I15: 硬数据 | J15: 收盘价口径
A16: Visa | B16: DCF 基准 | C16: 424.63 | D16: 美元/股 | E16: 巴菲特框架研究 | F16: 2026-10-29 | G16: 2026-10-29 | I16: 计算 | J16: DCF 基准情景
A17: 万事达卡 | B17: 当前价 | C17: 610.31 | D17: 美元/股 | E17: 腾讯行情 | F17: 2026-10-29 | G17: 2026-10-29 | I17: 硬数据 | J17: 收盘价口径
A18: 万事达卡 | B18: DCF 基准 | C18: 666.31 | D18: 美元/股 | E18: 巴菲特框架研究 | F18: 2026-10-29 | G18: 2026-10-29 | I18: 计算 | J18: DCF 基准情景
A19: 中国 10Y | B19: 10 年期国债收益率 | C19: 0.0162 | D19: % | E19: WebSearch | F19: 2026-10-30 | G19: 2026-10-30 | I19: 硬数据 | J19: 本地无风险利率
A20: 美国 10Y | B20: 10 年期国债收益率 | C20: 0.049 | D20: % | E20: WebSearch | F20: 2026-10-30 | G20: 2026-10-30 | I20: 硬数据 | J20: 本地无风险利率

Sheet 检查
A1: 自动检查
A2: 公式结果需在 Excel 中重算后查看；本页只做结构检查，不替代人工复核。
A4: 检查项 | B4: 结果 | C4: 状态 | D4: 说明
A5: 六维权重合计 | B5: =SUM(0.25,0.2,0.15,0.15,0.15,0.1) | C5: =IF(ABS(B5-1)<0.0001,"OK","CHECK") | D5: 应为 100%
A6: 质量分越界数量 | B6: =COUNTIF('分红安全'!AD5:AD11,">100")+COUNTIF('分红安全'!AD5:AD11,"<0") | C6: =IF(B6=0,"OK","CHECK") | D6: 质量分应在 0–100
A7: 最终质量分越界 | B7: =COUNTIF('分红安全'!AH5:AH11,">100")+COUNTIF('分红安全'!AH5:AH11,"<0") | C7: =IF(B7=0,"OK","CHECK") | D7: 硬约束后的分数应在 0–100
A8: 硬约束上限越界 | B8: =COUNTIF('分红安全'!AF5:AF11,">100")+COUNTIF('分红安全'!AF5:AF11,"<0") | C8: =IF(B8=0,"OK","CHECK") | D8: 上限应为 0–100
A9: 数据完整度 <80%（含待研究） | B9: =COUNTIF('分红安全'!AJ5:AJ11,"<0.8") | C9: =IF(B9=0,"OK","CHECK") | D9: 模板阶段为正常；完成研究后应清零
A10: 重复代码 | B10: =SUMPRODUCT(--(COUNTIF('评分总表'!C5:C16,'评分总表'!C5:C16)>1)) | C10: =IF(B10=0,"OK","CHECK") | D10: 同一代码不应重复
A11: 缺少数据日期 | B11: =COUNTBLANK('评分总表'!P5:P16) | C11: =IF(B11=0,"OK","CHECK") | D11: 待研究行可留空
A12: 总回报估值分越界 | B12: =COUNTIF('总回报'!T5:T16,">100")+COUNTIF('总回报'!T5:T16,"<0") | C12: =IF(B12=0,"OK","CHECK") | D12: 估值分应在 0–100
A13: 组合权重合计 | B13: =SUM('组合监控'!D5:D16) | C13: =IF(ABS(B13-1)<0.001,"OK","CHECK") | D13: 建仓前为 0 属正常；建仓后应为 100%
A14: 组合权重为负 | B14: =COUNTIF('组合监控'!D5:D16,"<0") | C14: =IF(B14=0,"OK","CHECK") | D14: 不允许负权重
A15: 免责声明 | B15: 本表只做研究分级，不构成投资建议 | C15: OK | D15: 输出前保留
