Workbook

Sheet 一图流
A1: 海尔智家（600690.SH / 06690.HK）· 巴菲特框架调研与估值 · 一图流
A2: ="研究日 2026-10-20 ｜ 股价：2026-10-20收盘 ｜ 最新财报：2026年中报(截至06-30) ｜ 币种：人民币 ｜ 当前情景："&估值模型!D4&"（可在估值模型C4切换）" -> 研究日 2026-10-20 ｜ 股价：2026-10-20收盘 ｜ 最新财报：2026年中报(截至06-30) ｜ 币种：人民币 ｜ 当前情景：基准（可在估值模型C4切换）
A4: A股现价 | C4: H股现价(折人民币) | E4: 加权内在价值 | G4: A股安全边际 | I4: H股安全边际 | K4: LTM股息率(A/H税前)
A5: =数据与来源!$B$7 -> 20.11 | C5: =数据与来源!$B$10 -> 17.07698 | E5: =估值模型!F63 -> 24.409113 | G5: =估值模型!F65 -> 0.17612737 | I5: =估值模型!F68 -> 0.30038506 | K5: =分红与回报!B16 -> 0.057718051
A6: 元/股 · 10-20收盘 | C6: ="港元19.64 · 较A股"&TEXT(数据与来源!$B$11,"0.0%") -> 港元19.64 · 较A股-15.1% | E6: ="区间 "&TEXT(估值模型!C63,"0.0")&" – "&TEXT(估值模型!E63,"0.0")&" 元" -> 区间 17.0 – 33.5 元 | G6: ="要求≥"&TEXT(估值模型!C29,"0%")&" · 观察价"&TEXT(估值模型!F69,"0.00") -> 要求≥25% · 观察价18.31 | I6: 港股通个人股息税20% | K6: ="H股 "&TEXT(分红与回报!C16,"0.00%")&" · 税后 "&TEXT(分红与回报!C18,"0.00%") -> H股 6.80% · 税后 5.44%
A8: 核心结论：价格有吸引力，但需条件验证（A股：观察/小仓分批；H股：更具性价比）。海尔是全球白电龙头，冰洗份额第一、海外收入占一半，利润能稳定变成现金（5年累计CFO为归母净利1.48倍），资产负债表净现金，派息率从33%提到55%并承诺2026年≥58%。但2026年上半年归母净利-14.3%（汇兑、北美关税与需求、国内补贴退坡），护城河是“规模+渠道”型而非定价权型。按所有者收益DCF、正常化PE、股息率三法，基准加权价值约24.4元/股：A股20.11元约有18%的安全边际、未达25%要求；H股折人民币约17.1元，折价约30%，但个人港股通股息税20%会吃掉部分收益。
A9: ="动作提示（随情景/股价自动变化）："&IF(估值模型!F65>=估值模型!C29,"A股已达要求安全边际，可按计划分批",IF(估值模型!F65>=0.1,"A股有折价但未达要求：观察或小仓，等三季报验证；A股条件观察价约"&TEXT(估值模型!F69,"0.00")&"元",IF(估值模型!F65>=0,"A股接近合理价值：观察，不追高","A股高于估值：回避")))&" ｜ H股安全边际 "&TEXT(估值模型!F68,"0%") -> 动作提示（随情景/股价自动变化）：A股有折价但未达要求：观察或小仓，等三季报验证；A股条件观察价约18.31元 ｜ H股安全边际 30%
A11: 生意与巴菲特八问 | G11: 估值三法 × 三情景（元/股）
A12: # | B12: 问题 | D12: 结论 | E12: 一句话依据 | G12: 方法 | I12: 悲观 | J12: 基准 | K12: 乐观 | L12: 权重
A13: 1 | B13: 能解释怎么赚钱吗？ | D13: 通过 | E13: 收入/产品/地区清晰 | G13: 所有者收益DCF | I13: =估值模型!C51 -> 15.638112 | J13: =估值模型!D51 -> 25.630742 | K13: =估值模型!E51 -> 38.439416 | L13: =估值模型!C25 -> 0.4
A14: 2 | B14: 十年后仍有需求吗？ | D14: 通过 | E14: 必需耐用品，更新刚性 | G14: 正常化PE | I14: =估值模型!C55 -> 17.833827 | J14: =估值模型!D55 -> 23.994604 | K14: =估值模型!E55 -> 31.02005 | L14: =估值模型!C26 -> 0.3
A15: 3 | B15: 对手难复制什么？ | D15: 存疑 | E15: 规模+渠道，空调偏弱 | G15: 股息率锚 | I15: =估值模型!C59 -> 17.833827 | J15: =估值模型!D59 -> 23.194783 | K15: =估值模型!E59 -> 29.542905 | L15: =估值模型!C27 -> 0.3
A16: 4 | B16: 有定价或成本优势吗？ | D16: 存疑 | E16: 高端撑毛利，关税难转嫁 | G16: 加权价值 | I16: =估值模型!C63 -> 16.955541 | J16: =估值模型!D63 -> 24.409113 | K16: =估值模型!E63 -> 33.544653
A17: 5 | B17: 利润能变现金吗？ | D17: 通过 | E17: 5年CFO≈1.48×净利 | G17: A股安全边际 | I17: =估值模型!C65 -> -0.18604297 | J17: =估值模型!D65 -> 0.17612737 | K17: =估值模型!E65 -> 0.40050058
A18: 6 | B18: 压力情景能存活吗？ | D18: 通过 | E18: 净现金约161亿 | G18: H股安全边际 | I18: =估值模型!C68 -> -0.0071622096 | J18: =估值模型!D68 -> 0.30038506 | K18: =估值模型!E68 -> 0.49091797
A19: 7 | B19: 管理层可信吗？ | D19: 存疑 | E19: 分红兑现；关联方需跟踪 | G19: 条件观察价 | I19: =估值模型!C69 -> 12.716656 | J19: =估值模型!D69 -> 18.306835 | K19: =估值模型!E69 -> 25.15849
A20: 8 | B20: 价格有余地吗？ | D20: 存疑 | E20: A折价约18%，H约30% | G20: 现价隐含PE | I20: =估值模型!C70 -> 11.276323 | J20: =估值模型!D70 -> 10.057261 | K20: =估值模型!E70 -> 9.0760652
A22: 关键数据（亿元）
A23: 2025营收 | B23: 2025归母净利 | C23: TTM归母净利 | D23: 2026H1营收同比 | E23: 2026H1归母同比 | F23: 2025 ROE(加权) | G23: 2025 CFO/净利 | H23: 所有者收益(3年均) | I23: 净金融资产 | J23: 2025派息率 | K23: TTM PE | L23: PB
A24: =财务五年!F6 -> 3023.4678 | B24: =财务五年!F12 -> 195.52798 | C24: =财务五年!I12 -> 178.36057 | D24: =财务五年!H7 -> -0.027981796 | E24: =财务五年!H13 -> -0.14266945 | F24: =财务五年!F17 -> 0.1698 | G24: =财务五年!F21 -> 1.2896306 | H24: =AVERAGE(财务五年!D25:F25) -> 143.28987 | I24: =财务五年!H36 -> 161.29653 | J24: =分红与回报!F9 -> 0.54750472 | K24: =同业比较!E5 -> 10.43164 | L24: =同业比较!G5 -> 1.5546615
A26: 图表：价格贵吗？业绩变好了没？利润变现金了吗？分红稳吗？
A59: 三大风险（永久损失路径） | G59: 关键监控与触发线
A60: ① 北美利润池：关税成本+需求疲弱使GEA利润率下台阶（商誉集中在海外并购） | G60: 三季报单季收入同比 ≥0；毛利率 ≥26%
A61: ② 国内价格战：补贴退坡后行业量价齐跌（9月零售额-13%、均价-11%） | G61: TTM扣非归母 <160亿 → 切换悲观情景
A62: ③ 成本与资本开支：铜/冷媒涨价、汇兑损失，资本开支长期高于折旧 | G62: CFO/净利 <1.0x 或 净金融资产 <50亿 → 复核
A63: 详见“风险与跟踪”表；三季报预计10月底前披露 | G63: 2026年度派息率 <58% → 红利逻辑受损
A65: 免责声明：本表为基于公开资料的研究框架与条件估值，不构成投资建议；情景价值不是收益承诺。财务数据为披露事实，估值参数为分析假设，结论为研究判断。

Sheet 估值模型
A1: 估值模型：所有者收益DCF + 正常化PE + 股息率锚
A2: 唯一的假设输入区在本表（浅黄底蓝字）。改C4情景（1悲观/2基准/3乐观）即可联动一图流。金额单位：亿元；每股：元。PE法与股息率法共享“正常化净利润”假设，二者不是完全独立的证据。
C3: 输入/可改 | D3: 公式计算 | E3: 跨表引用 | F3: 分析假设 | G3: 风险/警示
A4: 情景选择（1=悲观 2=基准 3=乐观） | C4: 2 | D4: =CHOOSE(C4,"悲观","基准","乐观") -> 基准
A6: 1. 核心假设（三情景由经营驱动推出）
A7: 参数 | B7: 单位 | C7: 悲观 | D7: 基准 | E7: 乐观 | F7: 当前情景 | G7: 依据（事实→判断）
A8: 正常化归母净利润 | B8: 亿元 | C8: 165 | D8: 185 | E8: 205 | F8: =CHOOSE($C$4,C8,D8,E8) -> 185 | G8: 事实：2025年195.5；TTM 178.4；TTM扣非162.0；管理层目标2026年收入、净利(含关税退款)大致持平。判断：北美关税与国内补贴退坡压制，基准取185（略低于目标）。悲观=扣非TTM附近；乐观=恢复并小幅超过2025。
A9: 正常化所有者收益（第1年基数） | B9: 亿元 | C9: 125 | D9: 145 | E9: 170 | F9: =CHOOSE($C$4,C9,D9,E9) -> 145 | G9: 事实：所有者收益代理(扣全部资本开支与租赁)2023-2025为140/141/149，TTM约127。判断：海外工厂建设期资本开支高于折旧，扣全部开支偏保守；基准取三年均值附近145；乐观假设扩产期结束、资本开支回落至折旧水平。
A10: 第1–5年增速 | B10: % | C10: 0 | D10: 0.03 | E10: 0.05 | F10: =CHOOSE($C$4,C10,D10,E10) -> 0.03 | G10: 成熟家电：国内存量竞争+海外新兴市场增长。2021–2025收入CAGR约7.4%，但2026上半年转负。
A11: 第6–10年增速 | B11: % | C11: 0.01 | D11: 0.02 | E11: 0.03 | F11: =CHOOSE($C$4,C11,D11,E11) -> 0.02 | G11: 向名义GDP收敛
A12: 永续增速 | B12: % | C12: 0.015 | D12: 0.02 | E12: 0.025 | F12: =CHOOSE($C$4,C12,D12,E12) -> 0.02 | G12: 低于长期名义增长，避免终值高估
A13: 股权成本 Ke（折现率） | B13: % | C13: 0.1 | D13: 0.09 | E13: 0.085 | F13: =CHOOSE($C$4,C13,D13,E13) -> 0.09 | G13: 无风险利率约1.8–2%（中国10年国债）+ 股权风险溢价；加上海外/关税/汇率与控股股东治理折价。公司净现金，所有者收益≈股东现金流，统一用Ke。
A14: 长期股权投资计入比例 | B14: % | C14: 0.3 | D14: 0.5 | E14: 0.7 | F14: =CHOOSE($C$4,C14,D14,E14) -> 0.5 | G14: 长期股权投资约218.6亿，其投资收益不在现金流中；联营公司流动性与关联属性打折计入。
A15: 净金融资产计入比例 | B15: % | C15: 0 | D15: 0.35 | E15: 0.7 | F15: =CHOOSE($C$4,C15,D15,E15) -> 0.35 | G15: 2026-06-30净金融资产约161亿(不含租赁)，但大额应付票据/应付账款是经营占款，现金有季节性，不全额计入。
A16: 合理PE（对正常化利润） | B16: 倍 | C16: 10 | D16: 12 | E16: 14 | F16: =CHOOSE($C$4,C16,D16,E16) -> 12 | G16: 成熟制造+中等护城河+海外占比约50%的周期性；参考自身近年与美的/格力区间，不套“好公司20倍”。
A17: 可持续派息率 | B17: % | C17: 0.55 | D17: 0.58 | E17: 0.6 | F17: =CHOOSE($C$4,C17,D17,E17) -> 0.58 | G17: 事实：2025年55%；公司规划2026年≥58%、2027–2028年≥60%。
A18: 要求税前股息率 | B18: % | C18: 0.055 | D18: 0.05 | E18: 0.045 | F18: =CHOOSE($C$4,C18,D18,E18) -> 0.05 | G18: 红利投资者对低增长家电龙头的收益要求；A股个人持有>1年免股息税。
A19: 估值用股数 | B19: 亿股 | C19: =数据与来源!$B$15 -> 92.520804 | D19: =数据与来源!$B$15 -> 92.520804 | E19: =数据与来源!$B$15 -> 92.520804 | F19: =数据与来源!$B$15 -> 92.520804 | G19: 扣回购专户后的在外股数
A20: 长期股权投资账面(2026-06-30) | B20: 亿元 | C20: =数据与来源!$I$58/100000000 -> 218.57256 | D20: =数据与来源!$I$58/100000000 -> 218.57256 | E20: =数据与来源!$I$58/100000000 -> 218.57256 | F20: =数据与来源!$I$58/100000000 -> 218.57256 | G20: 资产负债表
A21: 净金融资产(2026-06-30，不含租赁) | B21: 亿元 | C21: =财务五年!H36 -> 161.29653 | D21: =财务五年!H36 -> 161.29653 | E21: =财务五年!H36 -> 161.29653 | F21: =财务五年!H36 -> 161.29653 | G21: 现金+交易性金融资产−有息负债(宽口径)
A23: 2. 方法权重与安全边际要求
A24: 项目 | C24: 取值 | G24: 说明
A25: 所有者收益DCF 权重 | C25: 0.4 | G25: 最贴近巴菲特“现金流折现”思路，但对资本开支假设敏感
A26: 正常化PE 权重 | C26: 0.3 | G26: 市场常用锚，依赖正常化利润判断
A27: 股息率锚 权重 | C27: 0.3 | G27: 红利投资者视角；与PE法共享利润假设
A28: 权重合计（须=100%） | C28: =SUM(C25:C27) -> 1
A29: 要求安全边际 | C29: 0.25 | G29: 制造业+关税/汇率+补贴退坡不确定性；低于宇通/银行常用30–35%的原因：现金流与分红更稳。可自行调整
A31: 3. 方法一：所有者收益两阶段DCF（亿元）
A32: 年份 | B32: t | C32: 悲观 | D32: 基准 | E32: 乐观 | F32: 当前情景 | G32: 说明
A33: 第1年（2027E） | B33: 1 | C33: =C$9*(1+C$10)^$B33 -> 125 | D33: =D$9*(1+D$10)^$B33 -> 149.35 | E33: =E$9*(1+E$10)^$B33 -> 178.5 | F33: =CHOOSE($C$4,C33,D33,E33) -> 149.35 | G33: 第1–5年按g1增长，第6–10年按g2增长
A34: 第2年（2028E） | B34: 2 | C34: =C$9*(1+C$10)^$B34 -> 125 | D34: =D$9*(1+D$10)^$B34 -> 153.8305 | E34: =E$9*(1+E$10)^$B34 -> 187.425 | F34: =CHOOSE($C$4,C34,D34,E34) -> 153.8305
A35: 第3年（2029E） | B35: 3 | C35: =C$9*(1+C$10)^$B35 -> 125 | D35: =D$9*(1+D$10)^$B35 -> 158.44541 | E35: =E$9*(1+E$10)^$B35 -> 196.79625 | F35: =CHOOSE($C$4,C35,D35,E35) -> 158.44541
A36: 第4年（2030E） | B36: 4 | C36: =C$9*(1+C$10)^$B36 -> 125 | D36: =D$9*(1+D$10)^$B36 -> 163.19878 | E36: =E$9*(1+E$10)^$B36 -> 206.63606 | F36: =CHOOSE($C$4,C36,D36,E36) -> 163.19878
A37: 第5年（2031E） | B37: 5 | C37: =C$9*(1+C$10)^$B37 -> 125 | D37: =D$9*(1+D$10)^$B37 -> 168.09474 | E37: =E$9*(1+E$10)^$B37 -> 216.96787 | F37: =CHOOSE($C$4,C37,D37,E37) -> 168.09474
A38: 第6年（2032E） | B38: 6 | C38: =C$9*(1+C$10)^5*(1+C$11)^($B38-5) -> 126.25 | D38: =D$9*(1+D$10)^5*(1+D$11)^($B38-5) -> 171.45664 | E38: =E$9*(1+E$10)^5*(1+E$11)^($B38-5) -> 223.4769 | F38: =CHOOSE($C$4,C38,D38,E38) -> 171.45664
A39: 第7年（2033E） | B39: 7 | C39: =C$9*(1+C$10)^5*(1+C$11)^($B39-5) -> 127.5125 | D39: =D$9*(1+D$10)^5*(1+D$11)^($B39-5) -> 174.88577 | E39: =E$9*(1+E$10)^5*(1+E$11)^($B39-5) -> 230.18121 | F39: =CHOOSE($C$4,C39,D39,E39) -> 174.88577
A40: 第8年（2034E） | B40: 8 | C40: =C$9*(1+C$10)^5*(1+C$11)^($B40-5) -> 128.78762 | D40: =D$9*(1+D$10)^5*(1+D$11)^($B40-5) -> 178.38348 | E40: =E$9*(1+E$10)^5*(1+E$11)^($B40-5) -> 237.08664 | F40: =CHOOSE($C$4,C40,D40,E40) -> 178.38348
A41: 第9年（2035E） | B41: 9 | C41: =C$9*(1+C$10)^5*(1+C$11)^($B41-5) -> 130.0755 | D41: =D$9*(1+D$10)^5*(1+D$11)^($B41-5) -> 181.95115 | E41: =E$9*(1+E$10)^5*(1+E$11)^($B41-5) -> 244.19924 | F41: =CHOOSE($C$4,C41,D41,E41) -> 181.95115
A42: 第10年（2036E） | B42: 10 | C42: =C$9*(1+C$10)^5*(1+C$11)^($B42-5) -> 131.37626 | D42: =D$9*(1+D$10)^5*(1+D$11)^($B42-5) -> 185.59018 | E42: =E$9*(1+E$10)^5*(1+E$11)^($B42-5) -> 251.52522 | F42: =CHOOSE($C$4,C42,D42,E42) -> 185.59018
A43: 10年现金流现值 | C43: =SUMPRODUCT(C33:C42/(1+C$13)^$B$33:$B$42) -> 776.44358 | D43: =SUMPRODUCT(D33:D42/(1+D$13)^$B$33:$B$42) -> 1063.3053 | E43: =SUMPRODUCT(E33:E42/(1+E$13)^$B$33:$B$42) -> 1390.0859 | F43: =CHOOSE($C$4,C43,D43,E43) -> 1063.3053 | G43: 按年末折现
...

Sheet 估值敏感性
A1: 估值敏感性：哪个变量最关键？
A2: 每格都是真实公式计算（元/股）。绿色=达到要求安全边际（≤条件观察价对应的现价），浅绿=高于A股现价，红色=低于A股现价。DCF表使用“基准”情景的现金流路径，只改动行列变量。
A3: A股现价 | B3: =数据与来源!$B$7 -> 20.11 | C3: 要求安全边际 | E3: =估值模型!C29 -> 0.25 | F3: 达标价值线 | G3: =B3/(1-E3) -> 26.813333
A5: 表1 DCF每股价值：股权成本Ke × 永续增速g（基准现金流）
A6: Ke ↓ / g → | B6: 0.01 | C6: 0.015 | D6: 0.02 | E6: 0.025 | F6: 0.03
A7: 0.08 | B7: =((SUMPRODUCT(估值模型!$D$33:$D$42/(1+$A7)^估值模型!$B$33:$B$42)+估值模型!$D$42*(1+B$6)/($A7-B$6)/(1+$A7)^10)*1+估值模型!$D$48+估值模型!$D$49)/估值模型!$D$19 -> 27.235394 | C7: =((SUMPRODUCT(估值模型!$D$33:$D$42/(1+$A7)^估值模型!$B$33:$B$42)+估值模型!$D$42*(1+C$6)/($A7-C$6)/(1+$A7)^10)*1+估值模型!$D$48+估值模型!$D$49)/估值模型!$D$19 -> 28.338102 | D7: =((SUMPRODUCT(估值模型!$D$33:$D$42/(1+$A7)^估值模型!$B$33:$B$42)+估值模型!$D$42*(1+D$6)/($A7-D$6)/(1+$A7)^10)*1+估值模型!$D$48+估值模型!$D$49)/估值模型!$D$19 -> 29.624594 | E7: =((SUMPRODUCT(估值模型!$D$33:$D$42/(1+$A7)^估值模型!$B$33:$B$42)+估值模型!$D$42*(1+E$6)/($A7-E$6)/(1+$A7)^10)*1+估值模型!$D$48+估值模型!$D$49)/估值模型!$D$19 -> 31.144994 | F7: =((SUMPRODUCT(估值模型!$D$33:$D$42/(1+$A7)^估值模型!$B$33:$B$42)+估值模型!$D$42*(1+F$6)/($A7-F$6)/(1+$A7)^10)*1+估值模型!$D$48+估值模型!$D$49)/估值模型!$D$19 -> 32.969474 | J7: 读法：基准Ke 9%、g 2%对应估值模型的DCF基准值。Ke每降0.5个百分点，价值约升8–10%；这是DCF最大的不确定性来源。
A8: 0.085 | B8: =((SUMPRODUCT(估值模型!$D$33:$D$42/(1+$A8)^估值模型!$B$33:$B$42)+估值模型!$D$42*(1+B$6)/($A8-B$6)/(1+$A8)^10)*1+估值模型!$D$48+估值模型!$D$49)/估值模型!$D$19 -> 25.499398 | C8: =((SUMPRODUCT(估值模型!$D$33:$D$42/(1+$A8)^估值模型!$B$33:$B$42)+估值模型!$D$42*(1+C$6)/($A8-C$6)/(1+$A8)^10)*1+估值模型!$D$48+估值模型!$D$49)/估值模型!$D$19 -> 26.416164 | D8: =((SUMPRODUCT(估值模型!$D$33:$D$42/(1+$A8)^估值模型!$B$33:$B$42)+估值模型!$D$42*(1+D$6)/($A8-D$6)/(1+$A8)^10)*1+估值模型!$D$48+估值模型!$D$49)/估值模型!$D$19 -> 27.473972 | E8: =((SUMPRODUCT(估值模型!$D$33:$D$42/(1+$A8)^估值模型!$B$33:$B$42)+估值模型!$D$42*(1+E$6)/($A8-E$6)/(1+$A8)^10)*1+估值模型!$D$48+估值模型!$D$49)/估值模型!$D$19 -> 28.70808 | F8: =((SUMPRODUCT(估值模型!$D$33:$D$42/(1+$A8)^估值模型!$B$33:$B$42)+估值模型!$D$42*(1+F$6)/($A8-F$6)/(1+$A8)^10)*1+估值模型!$D$48+估值模型!$D$49)/估值模型!$D$19 -> 30.166572
A9: 0.09 | B9: =((SUMPRODUCT(估值模型!$D$33:$D$42/(1+$A9)^估值模型!$B$33:$B$42)+估值模型!$D$42*(1+B$6)/($A9-B$6)/(1+$A9)^10)*1+估值模型!$D$48+估值模型!$D$49)/估值模型!$D$19 -> 23.981482 | C9: =((SUMPRODUCT(估值模型!$D$33:$D$42/(1+$A9)^估值模型!$B$33:$B$42)+估值模型!$D$42*(1+C$6)/($A9-C$6)/(1+$A9)^10)*1+估值模型!$D$48+估值模型!$D$49)/估值模型!$D$19 -> 24.751137 | D9: =((SUMPRODUCT(估值模型!$D$33:$D$42/(1+$A9)^估值模型!$B$33:$B$42)+估值模型!$D$42*(1+D$6)/($A9-D$6)/(1+$A9)^10)*1+估值模型!$D$48+估值模型!$D$49)/估值模型!$D$19 -> 25.630742 | E9: =((SUMPRODUCT(估值模型!$D$33:$D$42/(1+$A9)^估值模型!$B$33:$B$42)+估值模型!$D$42*(1+E$6)/($A9-E$6)/(1+$A9)^10)*1+估值模型!$D$48+估值模型!$D$49)/估值模型!$D$19 -> 26.645671 | F9: =((SUMPRODUCT(估值模型!$D$33:$D$42/(1+$A9)^估值模型!$B$33:$B$42)+估值模型!$D$42*(1+F$6)/($A9-F$6)/(1+$A9)^10)*1+估值模型!$D$48+估值模型!$D$49)/估值模型!$D$19 -> 27.829755
A10: 0.095 | B10: =((SUMPRODUCT(估值模型!$D$33:$D$42/(1+$A10)^估值模型!$B$33:$B$42)+估值模型!$D$42*(1+B$6)/($A10-B$6)/(1+$A10)^10)*1+估值模型!$D$48+估值模型!$D$49)/估值模型!$D$19 -> 22.643123 | C10: =((SUMPRODUCT(估值模型!$D$33:$D$42/(1+$A10)^估值模型!$B$33:$B$42)+估值模型!$D$42*(1+C$6)/($A10-C$6)/(1+$A10)^10)*1+估值模型!$D$48+估值模型!$D$49)/估值模型!$D$19 -> 23.294826 | D10: =((SUMPRODUCT(估值模型!$D$33:$D$42/(1+$A10)^估值模型!$B$33:$B$42)+估值模型!$D$42*(1+D$6)/($A10-D$6)/(1+$A10)^10)*1+估值模型!$D$48+估值模型!$D$49)/估值模型!$D$19 -> 24.033423 | E10: =((SUMPRODUCT(估值模型!$D$33:$D$42/(1+$A10)^估值模型!$B$33:$B$42)+估值模型!$D$42*(1+E$6)/($A10-E$6)/(1+$A10)^10)*1+估值模型!$D$48+估值模型!$D$49)/估值模型!$D$19 -> 24.877533 | F10: =((SUMPRODUCT(估值模型!$D$33:$D$42/(1+$A10)^估值模型!$B$33:$B$42)+估值模型!$D$42*(1+F$6)/($A10-F$6)/(1+$A10)^10)*1+估值模型!$D$48+估值模型!$D$49)/估值模型!$D$19 -> 25.851507
A11: 0.1 | B11: =((SUMPRODUCT(估值模型!$D$33:$D$42/(1+$A11)^估值模型!$B$33:$B$42)+估值模型!$D$42*(1+B$6)/($A11-B$6)/(1+$A11)^10)*1+估值模型!$D$48+估值模型!$D$49)/估值模型!$D$19 -> 21.454361 | C11: =((SUMPRODUCT(估值模型!$D$33:$D$42/(1+$A11)^估值模型!$B$33:$B$42)+估值模型!$D$42*(1+C$6)/($A11-C$6)/(1+$A11)^10)*1+估值模型!$D$48+估值模型!$D$49)/估值模型!$D$19 -> 22.010381 | D11: =((SUMPRODUCT(估值模型!$D$33:$D$42/(1+$A11)^估值模型!$B$33:$B$42)+估值模型!$D$42*(1+D$6)/($A11-D$6)/(1+$A11)^10)*1+估值模型!$D$48+估值模型!$D$49)/估值模型!$D$19 -> 22.635903 | E11: =((SUMPRODUCT(估值模型!$D$33:$D$42/(1+$A11)^估值模型!$B$33:$B$42)+估值模型!$D$42*(1+E$6)/($A11-E$6)/(1+$A11)^10)*1+估值模型!$D$48+估值模型!$D$49)/估值模型!$D$19 -> 23.344827 | F11: =((SUMPRODUCT(估值模型!$D$33:$D$42/(1+$A11)^估值模型!$B$33:$B$42)+估值模型!$D$42*(1+F$6)/($A11-F$6)/(1+$A11)^10)*1+估值模型!$D$48+估值模型!$D$49)/估值模型!$D$19 -> 24.155027
A12: 0.11 | B12: =((SUMPRODUCT(估值模型!$D$33:$D$42/(1+$A12)^估值模型!$B$33:$B$42)+估值模型!$D$42*(1+B$6)/($A12-B$6)/(1+$A12)^10)*1+估值模型!$D$48+估值模型!$D$49)/估值模型!$D$19 -> 19.435752 | C12: =((SUMPRODUCT(估值模型!$D$33:$D$42/(1+$A12)^估值模型!$B$33:$B$42)+估值模型!$D$42*(1+C$6)/($A12-C$6)/(1+$A12)^10)*1+估值模型!$D$48+估值模型!$D$49)/估值模型!$D$19 -> 19.848472 | D12: =((SUMPRODUCT(估值模型!$D$33:$D$42/(1+$A12)^估值模型!$B$33:$B$42)+估值模型!$D$42*(1+D$6)/($A12-D$6)/(1+$A12)^10)*1+估值模型!$D$48+估值模型!$D$49)/估值模型!$D$19 -> 20.307049 | E12: =((SUMPRODUCT(估值模型!$D$33:$D$42/(1+$A12)^估值模型!$B$33:$B$42)+估值模型!$D$42*(1+E$6)/($A12-E$6)/(1+$A12)^10)*1+估值模型!$D$48+估值模型!$D$49)/估值模型!$D$19 -> 20.819577 | F12: =((SUMPRODUCT(估值模型!$D$33:$D$42/(1+$A12)^估值模型!$B$33:$B$42)+估值模型!$D$42*(1+F$6)/($A12-F$6)/(1+$A12)^10)*1+估值模型!$D$48+估值模型!$D$49)/估值模型!$D$19 -> 21.39617
A14: 表2 DCF每股价值：所有者收益基数 × Ke（g=基准）
A15: 所有者收益(亿) ↓ / Ke → | B15: 0.08 | C15: 0.085 | D15: 0.09 | E15: 0.1 | F15: 0.11
A16: 115 | B16: =((SUMPRODUCT(估值模型!$D$33:$D$42/(1+B$15)^估值模型!$B$33:$B$42)+估值模型!$D$42*(1+估值模型!$D$12)/(B$15-估值模型!$D$12)/(1+B$15)^10)*$A16/估值模型!$D$9+估值模型!$D$48+估值模型!$D$49)/估值模型!$D$19 -> 23.865998 | C16: =((SUMPRODUCT(估值模型!$D$33:$D$42/(1+C$15)^估值模型!$B$33:$B$42)+估值模型!$D$42*(1+估值模型!$D$12)/(C$15-估值模型!$D$12)/(1+C$15)^10)*$A16/估值模型!$D$9+估值模型!$D$48+估值模型!$D$49)/估值模型!$D$19 -> 22.160332 | D16: =((SUMPRODUCT(估值模型!$D$33:$D$42/(1+D$15)^估值模型!$B$33:$B$42)+估值模型!$D$42*(1+估值模型!$D$12)/(D$15-估值模型!$D$12)/(1+D$15)^10)*$A16/估值模型!$D$9+估值模型!$D$48+估值模型!$D$49)/估值模型!$D$19 -> 20.698461 | E16: =((SUMPRODUCT(估值模型!$D$33:$D$42/(1+E$15)^估值模型!$B$33:$B$42)+估值模型!$D$42*(1+估值模型!$D$12)/(E$15-估值模型!$D$12)/(1+E$15)^10)*$A16/估值模型!$D$9+估值模型!$D$48+估值模型!$D$49)/估值模型!$D$19 -> 18.323243 | F16: =((SUMPRODUCT(估值模型!$D$33:$D$42/(1+F$15)^估值模型!$B$33:$B$42)+估值模型!$D$42*(1+估值模型!$D$12)/(F$15-估值模型!$D$12)/(1+F$15)^10)*$A16/估值模型!$D$9+估值模型!$D$48+估值模型!$D$49)/估值模型!$D$19 -> 16.476221 | J16: 读法：所有者收益每变动10亿元，每股价值约变动1.1–1.5元。关键是海外扩产结束后资本开支能否回落、关税成本能否转嫁。
A17: 125 | B17: =((SUMPRODUCT(估值模型!$D$33:$D$42/(1+B$15)^估值模型!$B$33:$B$42)+估值模型!$D$42*(1+估值模型!$D$12)/(B$15-估值模型!$D$12)/(1+B$15)^10)*$A17/估值模型!$D$9+估值模型!$D$48+估值模型!$D$49)/估值模型!$D$19 -> 25.78553 | C17: =((SUMPRODUCT(估值模型!$D$33:$D$42/(1+C$15)^估值模型!$B$33:$B$42)+估值模型!$D$42*(1+估值模型!$D$12)/(C$15-估值模型!$D$12)/(1+C$15)^10)*$A17/估值模型!$D$9+估值模型!$D$48+估值模型!$D$49)/估值模型!$D$19 -> 23.931545 | D17: =((SUMPRODUCT(估值模型!$D$33:$D$42/(1+D$15)^估值模型!$B$33:$B$42)+估值模型!$D$42*(1+估值模型!$D$12)/(D$15-估值模型!$D$12)/(1+D$15)^10)*$A17/估值模型!$D$9+估值模型!$D$48+估值模型!$D$49)/估值模型!$D$19 -> 22.342554 | E17: =((SUMPRODUCT(估值模型!$D$33:$D$42/(1+E$15)^估值模型!$B$33:$B$42)+估值模型!$D$42*(1+估值模型!$D$12)/(E$15-估值模型!$D$12)/(1+E$15)^10)*$A17/估值模型!$D$9+估值模型!$D$48+估值模型!$D$49)/估值模型!$D$19 -> 19.760796 | F17: =((SUMPRODUCT(估值模型!$D$33:$D$42/(1+F$15)^估值模型!$B$33:$B$42)+估值模型!$D$42*(1+估值模型!$D$12)/(F$15-估值模型!$D$12)/(1+F$15)^10)*$A17/估值模型!$D$9+估值模型!$D$48+估值模型!$D$49)/估值模型!$D$19 -> 17.753164
A18: 135 | B18: =((SUMPRODUCT(估值模型!$D$33:$D$42/(1+B$15)^估值模型!$B$33:$B$42)+估值模型!$D$42*(1+估值模型!$D$12)/(B$15-估值模型!$D$12)/(1+B$15)^10)*$A18/估值模型!$D$9+估值模型!$D$48+估值模型!$D$49)/估值模型!$D$19 -> 27.705062 | C18: =((SUMPRODUCT(估值模型!$D$33:$D$42/(1+C$15)^估值模型!$B$33:$B$42)+估值模型!$D$42*(1+估值模型!$D$12)/(C$15-估值模型!$D$12)/(1+C$15)^10)*$A18/估值模型!$D$9+估值模型!$D$48+估值模型!$D$49)/估值模型!$D$19 -> 25.702759 | D18: =((SUMPRODUCT(估值模型!$D$33:$D$42/(1+D$15)^估值模型!$B$33:$B$42)+估值模型!$D$42*(1+估值模型!$D$12)/(D$15-估值模型!$D$12)/(1+D$15)^10)*$A18/估值模型!$D$9+估值模型!$D$48+估值模型!$D$49)/估值模型!$D$19 -> 23.986648 | E18: =((SUMPRODUCT(估值模型!$D$33:$D$42/(1+E$15)^估值模型!$B$33:$B$42)+估值模型!$D$42*(1+估值模型!$D$12)/(E$15-估值模型!$D$12)/(1+E$15)^10)*$A18/估值模型!$D$9+估值模型!$D$48+估值模型!$D$49)/估值模型!$D$19 -> 21.198349 | F18: =((SUMPRODUCT(估值模型!$D$33:$D$42/(1+F$15)^估值模型!$B$33:$B$42)+估值模型!$D$42*(1+估值模型!$D$12)/(F$15-估值模型!$D$12)/(1+F$15)^10)*$A18/估值模型!$D$9+估值模型!$D$48+估值模型!$D$49)/估值模型!$D$19 -> 19.030106
A19: 145 | B19: =((SUMPRODUCT(估值模型!$D$33:$D$42/(1+B$15)^估值模型!$B$33:$B$42)+估值模型!$D$42*(1+估值模型!$D$12)/(B$15-估值模型!$D$12)/(1+B$15)^10)*$A19/估值模型!$D$9+估值模型!$D$48+估值模型!$D$49)/估值模型!$D$19 -> 29.624594 | C19: =((SUMPRODUCT(估值模型!$D$33:$D$42/(1+C$15)^估值模型!$B$33:$B$42)+估值模型!$D$42*(1+估值模型!$D$12)/(C$15-估值模型!$D$12)/(1+C$15)^10)*$A19/估值模型!$D$9+估值模型!$D$48+估值模型!$D$49)/估值模型!$D$19 -> 27.473972 | D19: =((SUMPRODUCT(估值模型!$D$33:$D$42/(1+D$15)^估值模型!$B$33:$B$42)+估值模型!$D$42*(1+估值模型!$D$12)/(D$15-估值模型!$D$12)/(1+D$15)^10)*$A19/估值模型!$D$9+估值模型!$D$48+估值模型!$D$49)/估值模型!$D$19 -> 25.630742 | E19: =((SUMPRODUCT(估值模型!$D$33:$D$42/(1+E$15)^估值模型!$B$33:$B$42)+估值模型!$D$42*(1+估值模型!$D$12)/(E$15-估值模型!$D$12)/(1+E$15)^10)*$A19/估值模型!$D$9+估值模型!$D$48+估值模型!$D$49)/估值模型!$D$19 -> 22.635903 | F19: =((SUMPRODUCT(估值模型!$D$33:$D$42/(1+F$15)^估值模型!$B$33:$B$42)+估值模型!$D$42*(1+估值模型!$D$12)/(F$15-估值模型!$D$12)/(1+F$15)^10)*$A19/估值模型!$D$9+估值模型!$D$48+估值模型!$D$49)/估值模型!$D$19 -> 20.307049
A20: 155 | B20: =((SUMPRODUCT(估值模型!$D$33:$D$42/(1+B$15)^估值模型!$B$33:$B$42)+估值模型!$D$42*(1+估值模型!$D$12)/(B$15-估值模型!$D$12)/(1+B$15)^10)*$A20/估值模型!$D$9+估值模型!$D$48+估值模型!$D$49)/估值模型!$D$19 -> 31.544126 | C20: =((SUMPRODUCT(估值模型!$D$33:$D$42/(1+C$15)^估值模型!$B$33:$B$42)+估值模型!$D$42*(1+估值模型!$D$12)/(C$15-估值模型!$D$12)/(1+C$15)^10)*$A20/估值模型!$D$9+估值模型!$D$48+估值模型!$D$49)/估值模型!$D$19 -> 29.245185 | D20: =((SUMPRODUCT(估值模型!$D$33:$D$42/(1+D$15)^估值模型!$B$33:$B$42)+估值模型!$D$42*(1+估值模型!$D$12)/(D$15-估值模型!$D$12)/(1+D$15)^10)*$A20/估值模型!$D$9+估值模型!$D$48+估值模型!$D$49)/估值模型!$D$19 -> 27.274836 | E20: =((SUMPRODUCT(估值模型!$D$33:$D$42/(1+E$15)^估值模型!$B$33:$B$42)+估值模型!$D$42*(1+估值模型!$D$12)/(E$15-估值模型!$D$12)/(1+E$15)^10)*$A20/估值模型!$D$9+估值模型!$D$48+估值模型!$D$49)/估值模型!$D$19 -> 24.073456 | F20: =((SUMPRODUCT(估值模型!$D$33:$D$42/(1+F$15)^估值模型!$B$33:$B$42)+估值模型!$D$42*(1+估值模型!$D$12)/(F$15-估值模型!$D$12)/(1+F$15)^10)*$A20/估值模型!$D$9+估值模型!$D$48+估值模型!$D$49)/估值模型!$D$19 -> 21.583992
A21: 170 | B21: =((SUMPRODUCT(估值模型!$D$33:$D$42/(1+B$15)^估值模型!$B$33:$B$42)+估值模型!$D$42*(1+估值模型!$D$12)/(B$15-估值模型!$D$12)/(1+B$15)^10)*$A21/估值模型!$D$9+估值模型!$D$48+估值模型!$D$49)/估值模型!$D$19 -> 34.423423 | C21: =((SUMPRODUCT(估值模型!$D$33:$D$42/(1+C$15)^估值模型!$B$33:$B$42)+估值模型!$D$42*(1+估值模型!$D$12)/(C$15-估值模型!$D$12)/(1+C$15)^10)*$A21/估值模型!$D$9+估值模型!$D$48+估值模型!$D$49)/估值模型!$D$19 -> 31.902004 | D21: =((SUMPRODUCT(估值模型!$D$33:$D$42/(1+D$15)^估值模型!$B$33:$B$42)+估值模型!$D$42*(1+估值模型!$D$12)/(D$15-估值模型!$D$12)/(1+D$15)^10)*$A21/估值模型!$D$9+估值模型!$D$48+估值模型!$D$49)/估值模型!$D$19 -> 29.740977 | E21: =((SUMPRODUCT(估值模型!$D$33:$D$42/(1+E$15)^估值模型!$B$33:$B$42)+估值模型!$D$42*(1+估值模型!$D$12)/(E$15-估值模型!$D$12)/(1+E$15)^10)*$A21/估值模型!$D$9+估值模型!$D$48+估值模型!$D$49)/估值模型!$D$19 -> 26.229786 | F21: =((SUMPRODUCT(估值模型!$D$33:$D$42/(1+F$15)^估值模型!$B$33:$B$42)+估值模型!$D$42*(1+估值模型!$D$12)/(F$15-估值模型!$D$12)/(1+F$15)^10)*$A21/估值模型!$D$9+估值模型!$D$48+估值模型!$D$49)/估值模型!$D$19 -> 23.499405
A22: 185 | B22: =((SUMPRODUCT(估值模型!$D$33:$D$42/(1+B$15)^估值模型!$B$33:$B$42)+估值模型!$D$42*(1+估值模型!$D$12)/(B$15-估值模型!$D$12)/(1+B$15)^10)*$A22/估值模型!$D$9+估值模型!$D$48+估值模型!$D$49)/估值模型!$D$19 -> 37.302721 | C22: =((SUMPRODUCT(估值模型!$D$33:$D$42/(1+C$15)^估值模型!$B$33:$B$42)+估值模型!$D$42*(1+估值模型!$D$12)/(C$15-估值模型!$D$12)/(1+C$15)^10)*$A22/估值模型!$D$9+估值模型!$D$48+估值模型!$D$49)/估值模型!$D$19 -> 34.558824 | D22: =((SUMPRODUCT(估值模型!$D$33:$D$42/(1+D$15)^估值模型!$B$33:$B$42)+估值模型!$D$42*(1+估值模型!$D$12)/(D$15-估值模型!$D$12)/(1+D$15)^10)*$A22/估值模型!$D$9+估值模型!$D$48+估值模型!$D$49)/估值模型!$D$19 -> 32.207117 | E22: =((SUMPRODUCT(估值模型!$D$33:$D$42/(1+E$15)^估值模型!$B$33:$B$42)+估值模型!$D$42*(1+估值模型!$D$12)/(E$15-估值模型!$D$12)/(1+E$15)^10)*$A22/估值模型!$D$9+估值模型!$D$48+估值模型!$D$49)/估值模型!$D$19 -> 28.386115 | F22: =((SUMPRODUCT(估值模型!$D$33:$D$42/(1+F$15)^估值模型!$B$33:$B$42)+估值模型!$D$42*(1+估值模型!$D$12)/(F$15-估值模型!$D$12)/(1+F$15)^10)*$A22/估值模型!$D$9+估值模型!$D$48+估值模型!$D$49)/估值模型!$D$19 -> 25.414819
A24: 表3 PE法每股价值：正常化归母净利润 × PE
A25: 净利润(亿) ↓ / PE → | B25: 8 | C25: 10 | D25: 11 | E25: 12 | F25: 13 | G25: 14 | H25: 16
A26: 150 | B26: =$A26/估值模型!$D$19*B$25 -> 12.970056 | C26: =$A26/估值模型!$D$19*C$25 -> 16.21257 | D26: =$A26/估值模型!$D$19*D$25 -> 17.833827 | E26: =$A26/估值模型!$D$19*E$25 -> 19.455084 | F26: =$A26/估值模型!$D$19*F$25 -> 21.076341 | G26: =$A26/估值模型!$D$19*G$25 -> 22.697598 | H26: =$A26/估值模型!$D$19*H$25 -> 25.940112 | J26: 读法：现价≈正常化净利185亿×10倍。市场只给10倍左右，隐含“利润不增长甚至下滑”的预期。
A27: 165 | B27: =$A27/估值模型!$D$19*B$25 -> 14.267062 | C27: =$A27/估值模型!$D$19*C$25 -> 17.833827 | D27: =$A27/估值模型!$D$19*D$25 -> 19.61721 | E27: =$A27/估值模型!$D$19*E$25 -> 21.400592 | F27: =$A27/估值模型!$D$19*F$25 -> 23.183975 | G27: =$A27/估值模型!$D$19*G$25 -> 24.967358 | H27: =$A27/估值模型!$D$19*H$25 -> 28.534123
A28: 175 | B28: =$A28/估值模型!$D$19*B$25 -> 15.131732 | C28: =$A28/估值模型!$D$19*C$25 -> 18.914665 | D28: =$A28/估值模型!$D$19*D$25 -> 20.806131 | E28: =$A28/估值模型!$D$19*E$25 -> 22.697598 | F28: =$A28/估值模型!$D$19*F$25 -> 24.589064 | G28: =$A28/估值模型!$D$19*G$25 -> 26.480531 | H28: =$A28/估值模型!$D$19*H$25 -> 30.263464
A29: 185 | B29: =$A29/估值模型!$D$19*B$25 -> 15.996402 | C29: =$A29/估值模型!$D$19*C$25 -> 19.995503 | D29: =$A29/估值模型!$D$19*D$25 -> 21.995053 | E29: =$A29/估值模型!$D$19*E$25 -> 23.994604 | F29: =$A29/估值模型!$D$19*F$25 -> 25.994154 | G29: =$A29/估值模型!$D$19*G$25 -> 27.993704 | H29: =$A29/估值模型!$D$19*H$25 -> 31.992805
A30: 195 | B30: =$A30/估值模型!$D$19*B$25 -> 16.861073 | C30: =$A30/估值模型!$D$19*C$25 -> 21.076341 | D30: =$A30/估值模型!$D$19*D$25 -> 23.183975 | E30: =$A30/估值模型!$D$19*E$25 -> 25.291609 | F30: =$A30/估值模型!$D$19*F$25 -> 27.399243 | G30: =$A30/估值模型!$D$19*G$25 -> 29.506877 | H30: =$A30/估值模型!$D$19*H$25 -> 33.722145
A31: 205 | B31: =$A31/估值模型!$D$19*B$25 -> 17.725743 | C31: =$A31/估值模型!$D$19*C$25 -> 22.157179 | D31: =$A31/估值模型!$D$19*D$25 -> 24.372897 | E31: =$A31/估值模型!$D$19*E$25 -> 26.588615 | F31: =$A31/估值模型!$D$19*F$25 -> 28.804333 | G31: =$A31/估值模型!$D$19*G$25 -> 31.02005 | H31: =$A31/估值模型!$D$19*H$25 -> 35.451486
A32: 220 | B32: =$A32/估值模型!$D$19*B$25 -> 19.022749 | C32: =$A32/估值模型!$D$19*C$25 -> 23.778436 | D32: =$A32/估值模型!$D$19*D$25 -> 26.156279 | E32: =$A32/估值模型!$D$19*E$25 -> 28.534123 | F32: =$A32/估值模型!$D$19*F$25 -> 30.911967 | G32: =$A32/估值模型!$D$19*G$25 -> 33.28981 | H32: =$A32/估值模型!$D$19*H$25 -> 38.045497
A34: 表4 股息率法：税前DPS × 要求股息率；以及现价对应股息率
A35: DPS(元) ↓ / 要求股息率 → | B35: 0.04 | C35: 0.045 | D35: 0.05 | E35: 0.055 | F35: 0.06 | G35: 0.065 | H35: 现价股息率
A36: 0.95 | B36: =$A36/B$35 -> 23.75 | C36: =$A36/C$35 -> 21.111111 | D36: =$A36/D$35 -> 19 | E36: =$A36/E$35 -> 17.272727 | F36: =$A36/F$35 -> 15.833333 | G36: =$A36/G$35 -> 14.615385 | H36: =$A36/$B$3 -> 0.047240179 | J36: 读法：1.16元≈2025年实际DPS（0.2692中期+0.8915末期）。若派息率升到58–60%且利润不降，DPS可到1.2元左右。
A37: 1.05 | B37: =$A37/B$35 -> 26.25 | C37: =$A37/C$35 -> 23.333333 | D37: =$A37/D$35 -> 21 | E37: =$A37/E$35 -> 19.090909 | F37: =$A37/F$35 -> 17.5 | G37: =$A37/G$35 -> 16.153846 | H37: =$A37/$B$3 -> 0.052212829
A38: 1.16 | B38: =$A38/B$35 -> 29 | C38: =$A38/C$35 -> 25.777778 | D38: =$A38/D$35 -> 23.2 | E38: =$A38/E$35 -> 21.090909 | F38: =$A38/F$35 -> 19.333333 | G38: =$A38/G$35 -> 17.846154 | H38: =$A38/$B$3 -> 0.057682745
A39: 1.25 | B39: =$A39/B$35 -> 31.25 | C39: =$A39/C$35 -> 27.777778 | D39: =$A39/D$35 -> 25 | E39: =$A39/E$35 -> 22.727273 | F39: =$A39/F$35 -> 20.833333 | G39: =$A39/G$35 -> 19.230769 | H39: =$A39/$B$3 -> 0.06215813
A40: 1.35 | B40: =$A40/B$35 -> 33.75 | C40: =$A40/C$35 -> 30 | D40: =$A40/D$35 -> 27 | E40: =$A40/E$35 -> 24.545455 | F40: =$A40/F$35 -> 22.5 | G40: =$A40/G$35 -> 20.769231 | H40: =$A40/$B$3 -> 0.067130781

Sheet 财务五年
A1: 财务五年：业绩、现金与资产负债（亿元）
A2: 年度=完整财年；H1=半年度实际（不年化）；TTM=2025年报+2026H1−2025H1，资产负债为2026-06-30时点。毛利率：2023年起部分费用重分类进营业成本，2022及以前不可比。
A4: 指标（亿元/比率） | B4: 2021 | C4: 2022 | D4: 2023 | E4: 2024 | F4: 2025 | G4: 2025H1 | H4: 2026H1 | I4: TTM | J4: 说明
A5: 一、成长与利润
A6: 营业收入 | B6: =(数据与来源!$C$23/100000000) -> 2271.0582 | C6: =(数据与来源!$D$23/100000000) -> 2435.7892 | D6: =(数据与来源!$E$23/100000000) -> 2742.0452 | E6: =(数据与来源!$F$23/100000000) -> 2860.1529 | F6: =(数据与来源!$G$23/100000000) -> 3023.4678 | G6: =(数据与来源!$H$23/100000000) -> 1564.9403 | H6: =(数据与来源!$I$23/100000000) -> 1521.1505 | I6: =((数据与来源!$G$23+数据与来源!$I$23-数据与来源!$H$23)/100000000) -> 2979.678
A7: 营收同比 | B7: =(数据与来源!$C$23/100000000)/(数据与来源!$B$23/100000000)-1 -> 0.08288243 | C7: =(数据与来源!$D$23/100000000)/(数据与来源!$C$23/100000000)-1 -> 0.072534942 | D7: =(数据与来源!$E$23/100000000)/(数据与来源!$D$23/100000000)-1 -> 0.12573171 | E7: =(数据与来源!$F$23/100000000)/(数据与来源!$E$23/100000000)-1 -> 0.043072864 | F7: =(数据与来源!$G$23/100000000)/(数据与来源!$F$23/100000000)-1 -> 0.057100055 | G7: — | H7: =(数据与来源!$I$23/100000000)/(数据与来源!$H$23/100000000)-1 -> -0.027981796 | I7: — | J7: H1对上年同期；TTM不计同比
A8: 毛利率 | B8: =1-(数据与来源!$C$24/100000000)/(数据与来源!$C$23/100000000) -> 0.31331769 | C8: =1-(数据与来源!$D$24/100000000)/(数据与来源!$D$23/100000000) -> 0.31330946 | D8: =1-(数据与来源!$E$24/100000000)/(数据与来源!$E$23/100000000) -> 0.27485342 | E8: =1-(数据与来源!$F$24/100000000)/(数据与来源!$F$23/100000000) -> 0.27822236 | F8: =1-(数据与来源!$G$24/100000000)/(数据与来源!$G$23/100000000) -> 0.26660786 | G8: =1-(数据与来源!$H$24/100000000)/(数据与来源!$H$23/100000000) -> 0.26873933 | H8: =1-(数据与来源!$I$24/100000000)/(数据与来源!$I$23/100000000) -> 0.27229326 | I8: =1-((数据与来源!$G$24+数据与来源!$I$24-数据与来源!$H$24)/100000000)/((数据与来源!$G$23+数据与来源!$I$23-数据与来源!$H$23)/100000000) -> 0.26839085 | J8: 2023起口径变化
A9: 销售费用率 | B9: =(数据与来源!$C$25/100000000)/(数据与来源!$C$23/100000000) -> 0.16108984 | C9: =(数据与来源!$D$25/100000000)/(数据与来源!$D$23/100000000) -> 0.15847142 | D9: =(数据与来源!$E$25/100000000)/(数据与来源!$E$23/100000000) -> 0.11935155 | E9: =(数据与来源!$F$25/100000000)/(数据与来源!$F$23/100000000) -> 0.11750707 | F9: =(数据与来源!$G$25/100000000)/(数据与来源!$G$23/100000000) -> 0.11204953 | G9: =(数据与来源!$H$25/100000000)/(数据与来源!$H$23/100000000) -> 0.10106976 | H9: =(数据与来源!$I$25/100000000)/(数据与来源!$I$23/100000000) -> 0.10806786 | I9: =((数据与来源!$G$25+数据与来源!$I$25-数据与来源!$H$25)/100000000)/((数据与来源!$G$23+数据与来源!$I$23-数据与来源!$H$23)/100000000) -> 0.11578348
A10: 管理费用率 | B10: =(数据与来源!$C$26/100000000)/(数据与来源!$C$23/100000000) -> 0.046108603 | C10: =(数据与来源!$D$26/100000000)/(数据与来源!$D$23/100000000) -> 0.044529086 | D10: =(数据与来源!$E$26/100000000)/(数据与来源!$E$23/100000000) -> 0.043304979 | E10: =(数据与来源!$F$26/100000000)/(数据与来源!$F$23/100000000) -> 0.042427755 | F10: =(数据与来源!$G$26/100000000)/(数据与来源!$G$23/100000000) -> 0.045518772 | G10: =(数据与来源!$H$26/100000000)/(数据与来源!$H$23/100000000) -> 0.037643907 | H10: =(数据与来源!$I$26/100000000)/(数据与来源!$I$23/100000000) -> 0.03960525 | I10: =((数据与来源!$G$26+数据与来源!$I$26-数据与来源!$H$26)/100000000)/((数据与来源!$G$23+数据与来源!$I$23-数据与来源!$H$23)/100000000) -> 0.046635784
A11: 研发费用率 | B11: =(数据与来源!$C$27/100000000)/(数据与来源!$C$23/100000000) -> 0.03682807 | C11: =(数据与来源!$D$27/100000000)/(数据与来源!$D$23/100000000) -> 0.03903205 | D11: =(数据与来源!$E$27/100000000)/(数据与来源!$E$23/100000000) -> 0.037855757 | E11: =(数据与来源!$F$27/100000000)/(数据与来源!$F$23/100000000) -> 0.037654966 | F11: =(数据与来源!$G$27/100000000)/(数据与来源!$G$23/100000000) -> 0.033391902 | G11: =(数据与来源!$H$27/100000000)/(数据与来源!$H$23/100000000) -> 0.037001007 | H11: =(数据与来源!$I$27/100000000)/(数据与来源!$I$23/100000000) -> 0.033341158 | I11: =((数据与来源!$G$27+数据与来源!$I$27-数据与来源!$H$27)/100000000)/((数据与来源!$G$23+数据与来源!$I$23-数据与来源!$H$23)/100000000) -> 0.031470478
A12: 归母净利润 | B12: =(数据与来源!$C$33/100000000) -> 130.78841 | C12: =(数据与来源!$D$33/100000000) -> 147.12055 | D12: =(数据与来源!$E$33/100000000) -> 165.96615 | E12: =(数据与来源!$F$33/100000000) -> 187.31046 | F12: =(数据与来源!$G$33/100000000) -> 195.52798 | G12: =(数据与来源!$H$33/100000000) -> 120.32996 | H12: =(数据与来源!$I$33/100000000) -> 103.16255 | I12: =((数据与来源!$G$33+数据与来源!$I$33-数据与来源!$H$33)/100000000) -> 178.36057
A13: 归母净利同比 | B13: =(数据与来源!$C$33/100000000)/(数据与来源!$B$33/100000000)-1 -> 0.4723236 | C13: =(数据与来源!$D$33/100000000)/(数据与来源!$C$33/100000000)-1 -> 0.12487454 | D13: =(数据与来源!$E$33/100000000)/(数据与来源!$D$33/100000000)-1 -> 0.12809633 | E13: =(数据与来源!$F$33/100000000)/(数据与来源!$E$33/100000000)-1 -> 0.12860642 | F13: =(数据与来源!$G$33/100000000)/(数据与来源!$F$33/100000000)-1 -> 0.043871118 | G13: — | H13: =(数据与来源!$I$33/100000000)/(数据与来源!$H$33/100000000)-1 -> -0.14266945 | I13: — | J13: 2021同比基数含私有化前少数股东影响，偏高
A14: 扣非归母净利润 | B14: =(数据与来源!$C$34/100000000) -> 118.31273 | C14: =(数据与来源!$D$34/100000000) -> 139.62932 | D14: =(数据与来源!$E$34/100000000) -> 158.24164 | E14: =(数据与来源!$F$34/100000000) -> 178.04733 | F14: =(数据与来源!$G$34/100000000) -> 186.03632 | G14: =(数据与来源!$H$34/100000000) -> 117.02409 | H14: =(数据与来源!$I$34/100000000) -> 92.987506 | I14: =((数据与来源!$G$34+数据与来源!$I$34-数据与来源!$H$34)/100000000) -> 161.99974
A15: 扣非/归母 | B15: =(数据与来源!$C$34/100000000)/(数据与来源!$C$33/100000000) -> 0.90461173 | C15: =(数据与来源!$D$34/100000000)/(数据与来源!$D$33/100000000) -> 0.94908101 | D15: =(数据与来源!$E$34/100000000)/(数据与来源!$E$33/100000000) -> 0.95345732 | E15: =(数据与来源!$F$34/100000000)/(数据与来源!$F$33/100000000) -> 0.95054662 | F15: =(数据与来源!$G$34/100000000)/(数据与来源!$G$33/100000000) -> 0.95145623 | G15: =(数据与来源!$H$34/100000000)/(数据与来源!$H$33/100000000) -> 0.9725266 | H15: =(数据与来源!$I$34/100000000)/(数据与来源!$I$33/100000000) -> 0.90136883 | I15: =((数据与来源!$G$34+数据与来源!$I$34-数据与来源!$H$34)/100000000)/((数据与来源!$G$33+数据与来源!$I$33-数据与来源!$H$33)/100000000) -> 0.908271 | J15: 2026H1非经常性损益约10亿，扣非占比明显下降
A16: 归母净利率 | B16: =(数据与来源!$C$33/100000000)/(数据与来源!$C$23/100000000) -> 0.057589192 | C16: =(数据与来源!$D$33/100000000)/(数据与来源!$D$23/100000000) -> 0.060399539 | D16: =(数据与来源!$E$33/100000000)/(数据与来源!$E$23/100000000) -> 0.060526409 | E16: =(数据与来源!$F$33/100000000)/(数据与来源!$F$23/100000000) -> 0.065489666 | F16: =(数据与来源!$G$33/100000000)/(数据与来源!$G$23/100000000) -> 0.064670105 | G16: =(数据与来源!$H$33/100000000)/(数据与来源!$H$23/100000000) -> 0.076891083 | H16: =(数据与来源!$I$33/100000000)/(数据与来源!$I$23/100000000) -> 0.067818766 | I16: =((数据与来源!$G$33+数据与来源!$I$33-数据与来源!$H$33)/100000000)/((数据与来源!$G$23+数据与来源!$I$23-数据与来源!$H$23)/100000000) -> 0.059859009
A17: 加权ROE(披露) | B17: =数据与来源!$C$36 -> 0.1726 | C17: =数据与来源!$D$36 -> 0.1681 | D17: =数据与来源!$E$36 -> 0.1724 | E17: =数据与来源!$F$36 -> 0.1761 | F17: =数据与来源!$G$36 -> 0.1698 | G17: =数据与来源!$H$36 -> 0.1034 | H17: =数据与来源!$I$36 -> 0.0836 | I17: — | J17: H1为半年值，不年化
A18: 近似ROIC | B18: — | C18: =((数据与来源!$D$30+数据与来源!$D$29)*(1-数据与来源!$D$31/数据与来源!$D$30))/(((数据与来源!$D$61+数据与来源!$D$62+数据与来源!$D$52+数据与来源!$D$53+数据与来源!$D$54+数据与来源!$D$55-数据与来源!$D$44-N(数据与来源!$D$45))+(数据与来源!$C$61+数据与来源!$C$62+数据与来源!$C$52+数据与来源!$C$53+数据与来源!$C$54+数据与来源!$C$55-数据与来源!$C$44-N(数据与来源!$C$45)))/2) -> 0.24105827 | D18: =((数据与来源!$E$30+数据与来源!$E$29)*(1-数据与来源!$E$31/数据与来源!$E$30))/(((数据与来源!$E$61+数据与来源!$E$62+数据与来源!$E$52+数据与来源!$E$53+数据与来源!$E$54+数据与来源!$E$55-数据与来源!$E$44-N(数据与来源!$E$45))+(数据与来源!$D$61+数据与来源!$D$62+数据与来源!$D$52+数据与来源!$D$53+数据与来源!$D$54+数据与来源!$D$55-数据与来源!$D$44-N(数据与来源!$D$45)))/2) -> 0.24852919 | E18: =((数据与来源!$F$30+数据与来源!$F$29)*(1-数据与来源!$F$31/数据与来源!$F$30))/(((数据与来源!$F$61+数据与来源!$F$62+数据与来源!$F$52+数据与来源!$F$53+数据与来源!$F$54+数据与来源!$F$55-数据与来源!$F$44-N(数据与来源!$F$45))+(数据与来源!$E$61+数据与来源!$E$62+数据与来源!$E$52+数据与来源!$E$53+数据与来源!$E$54+数据与来源!$E$55-数据与来源!$E$44-N(数据与来源!$E$45)))/2) -> 0.23745651 | F18: =((数据与来源!$G$30+数据与来源!$G$29)*(1-数据与来源!$G$31/数据与来源!$G$30))/(((数据与来源!$G$61+数据与来源!$G$62+数据与来源!$G$52+数据与来源!$G$53+数据与来源!$G$54+数据与来源!$G$55-数据与来源!$G$44-N(数据与来源!$G$45))+(数据与来源!$F$61+数据与来源!$F$62+数据与来源!$F$52+数据与来源!$F$53+数据与来源!$F$54+数据与来源!$F$55-数据与来源!$F$44-N(数据与来源!$F$45)))/2) -> 0.20512026 | G18: — | H18: — | I18: — | J18: (利润总额+利息)×(1−实际税率)÷平均(权益+有息负债−现金及交易性金融资产)；含商誉；不含租赁负债
A19: 二、利润变现金（所有者收益）
A20: 经营现金流 | B20: =(数据与来源!$C$37/100000000) -> 232.35381 | C20: =(数据与来源!$D$37/100000000) -> 202.56557 | D20: =(数据与来源!$E$37/100000000) -> 265.35781 | E20: =(数据与来源!$F$37/100000000) -> 263.18091 | F20: =(数据与来源!$G$37/100000000) -> 260.02942 | G20: =(数据与来源!$H$37/100000000) -> 111.39046 | H20: =(数据与来源!$I$37/100000000) -> 97.52034 | I20: =((数据与来源!$G$37+数据与来源!$I$37-数据与来源!$H$37)/100000000) -> 246.1593
A21: 经营现金流/合并净利润 | B21: =(数据与来源!$C$37/100000000)/(数据与来源!$C$32/100000000) -> 1.7559647 | C21: =(数据与来源!$D$37/100000000)/(数据与来源!$D$32/100000000) -> 1.3748814 | D21: =(数据与来源!$E$37/100000000)/(数据与来源!$E$32/100000000) -> 1.5528461 | E21: =(数据与来源!$F$37/100000000)/(数据与来源!$F$32/100000000) -> 1.3451248 | F21: =(数据与来源!$G$37/100000000)/(数据与来源!$G$32/100000000) -> 1.2896306 | G21: =(数据与来源!$H$37/100000000)/(数据与来源!$H$32/100000000) -> 0.89218602 | H21: =(数据与来源!$I$37/100000000)/(数据与来源!$I$32/100000000) -> 0.89665522 | I21: =((数据与来源!$G$37+数据与来源!$I$37-数据与来源!$H$37)/100000000)/((数据与来源!$G$32+数据与来源!$I$32-数据与来源!$H$32)/100000000) -> 1.3267189 | J21: CFO为合并口径，故对比合并净利润
A22: 资本开支 | B22: =(数据与来源!$C$38/100000000) -> 73.724288 | C22: =(数据与来源!$D$38/100000000) -> 82.097862 | D22: =(数据与来源!$E$38/100000000) -> 105.41562 | E22: =(数据与来源!$F$38/100000000) -> 100.80067 | F22: =(数据与来源!$G$38/100000000) -> 88.515639 | G22: =(数据与来源!$H$38/100000000) -> 37.644628 | H22: =(数据与来源!$I$38/100000000) -> 43.667892 | I22: =((数据与来源!$G$38+数据与来源!$I$38-数据与来源!$H$38)/100000000) -> 94.538904
A23: 自由现金流(CFO−资本开支) | B23: =(数据与来源!$C$37/100000000)-(数据与来源!$C$38/100000000) -> 158.62952 | C23: =(数据与来源!$D$37/100000000)-(数据与来源!$D$38/100000000) -> 120.46771 | D23: =(数据与来源!$E$37/100000000)-(数据与来源!$E$38/100000000) -> 159.94219 | E23: =(数据与来源!$F$37/100000000)-(数据与来源!$F$38/100000000) -> 162.38024 | F23: =(数据与来源!$G$37/100000000)-(数据与来源!$G$38/100000000) -> 171.51378 | G23: =(数据与来源!$H$37/100000000)-(数据与来源!$H$38/100000000) -> 73.74583 | H23: =(数据与来源!$I$37/100000000)-(数据与来源!$I$38/100000000) -> 53.852448 | I23: =((数据与来源!$G$37+数据与来源!$I$37-数据与来源!$H$37)/100000000)-((数据与来源!$G$38+数据与来源!$I$38-数据与来源!$H$38)/100000000) -> 151.6204
A24: 使用权资产折旧(租赁现金代理) | B24: — | C24: =(数据与来源!$D$42/100000000) -> 8.9610939 | D24: =(数据与来源!$E$42/100000000) -> 15.987578 | E24: =(数据与来源!$F$42/100000000) -> 15.095942 | F24: =(数据与来源!$G$42/100000000) -> 17.805288 | G24: =(数据与来源!$H$42/100000000) -> 7.7131502 | H24: =(数据与来源!$I$42/100000000) -> 8.8967994 | I24: =((数据与来源!$G$42+数据与来源!$I$42-数据与来源!$H$42)/100000000) -> 18.988937 | J24: 租赁本金在筹资现金流，需另扣
A25: 所有者收益代理 | B25: — | C25: =((数据与来源!$D$37/100000000)-(数据与来源!$D$38/100000000)-(数据与来源!$D$42/100000000))*(数据与来源!$D$33/100000000)/(数据与来源!$D$32/100000000) -> 111.34573 | D25: =((数据与来源!$E$37/100000000)-(数据与来源!$E$38/100000000)-(数据与来源!$E$42/100000000))*(数据与来源!$E$33/100000000)/(数据与来源!$E$32/100000000) -> 139.8111 | E25: =((数据与来源!$F$37/100000000)-(数据与来源!$F$38/100000000)-(数据与来源!$F$42/100000000))*(数据与来源!$F$33/100000000)/(数据与来源!$F$32/100000000) -> 141.00246 | F25: =((数据与来源!$G$37/100000000)-(数据与来源!$G$38/100000000)-(数据与来源!$G$42/100000000))*(数据与来源!$G$33/100000000)/(数据与来源!$G$32/100000000) -> 149.05605 | G25: =((数据与来源!$H$37/100000000)-(数据与来源!$H$38/100000000)-(数据与来源!$H$42/100000000))*(数据与来源!$H$33/100000000)/(数据与来源!$H$32/100000000) -> 63.641457 | H25: =((数据与来源!$I$37/100000000)-(数据与来源!$I$38/100000000)-(数据与来源!$I$42/100000000))*(数据与来源!$I$33/100000000)/(数据与来源!$I$32/100000000) -> 42.641905 | I25: =(((数据与来源!$G$37+数据与来源!$I$37-数据与来源!$H$37)/100000000)-((数据与来源!$G$38+数据与来源!$I$38-数据与来源!$H$38)/100000000)-((数据与来源!$G$42+数据与来源!$I$42-数据与来源!$H$42)/100000000))*((数据与来源!$G$33+数据与来源!$I$33-数据与来源!$H$33)/100000000)/((数据与来源!$G$32+数据与来源!$I$32-数据与来源!$H$32)/100000000) -> 127.49938 | J25: (CFO−全部资本开支−租赁)×归母/合并；扣全部资本开支=保守口径
A26: 所有者收益/归母净利 | B26: — | C26: =C25/(数据与来源!$D$33/100000000) -> 0.75683328 | D26: =D25/(数据与来源!$E$33/100000000) -> 0.8424073 | E26: =E25/(数据与来源!$F$33/100000000) -> 0.75277405 | F26: =F25/(数据与来源!$G$33/100000000) -> 0.76232594 | G26: =G25/(数据与来源!$H$33/100000000) -> 0.52889121 | H26: =H25/(数据与来源!$I$33/100000000) -> 0.41334676 | I26: =I25/((数据与来源!$G$33+数据与来源!$I$33-数据与来源!$H$33)/100000000) -> 0.7148406
A27: 折旧摊销合计 | B27: — | C27: =(数据与来源!$D$39/100000000)+(数据与来源!$D$40/100000000)+(数据与来源!$D$41/100000000)+(数据与来源!$D$42/100000000) -> 60.513816 | D27: =(数据与来源!$E$39/100000000)+(数据与来源!$E$40/100000000)+(数据与来源!$E$41/100000000)+(数据与来源!$E$42/100000000) -> 76.381479 | E27: =(数据与来源!$F$39/100000000)+(数据与来源!$F$40/100000000)+(数据与来源!$F$41/100000000)+(数据与来源!$F$42/100000000) -> 81.026634 | F27: =(数据与来源!$G$39/100000000)+(数据与来源!$G$40/100000000)+(数据与来源!$G$41/100000000)+(数据与来源!$G$42/100000000) -> 87.499325 | G27: =(数据与来源!$H$39/100000000)+(数据与来源!$H$40/100000000)+(数据与来源!$H$41/100000000)+(数据与来源!$H$42/100000000) -> 41.862215 | H27: =(数据与来源!$I$39/100000000)+(数据与来源!$I$40/100000000)+(数据与来源!$I$41/100000000)+(数据与来源!$I$42/100000000) -> 42.694271 | I27: =((数据与来源!$G$39+数据与来源!$I$39-数据与来源!$H$39)/100000000)+((数据与来源!$G$40+数据与来源!$I$40-数据与来源!$H$40)/100000000)+((数据与来源!$G$41+数据与来源!$I$41-数据与来源!$H$41)/100000000)+((数据与来源!$G$42+数据与来源!$I$42-数据与来源!$H$42)/100000000) -> 88.33138 | J27: 固定资产折旧+无形摊销+长摊+使用权
A28: 资本开支/(折旧+无形摊销) | B28: =(数据与来源!$C$38/100000000)/((数据与来源!$C$39/100000000)+(数据与来源!$C$40/100000000)) -> 1.534206 | C28: =(数据与来源!$D$38/100000000)/((数据与来源!$D$39/100000000)+(数据与来源!$D$40/100000000)) -> 1.7305861 | D28: =(数据与来源!$E$38/100000000)/((数据与来源!$E$39/100000000)+(数据与来源!$E$40/100000000)) -> 1.9069063 | E28: =(数据与来源!$F$38/100000000)/((数据与来源!$F$39/100000000)+(数据与来源!$F$40/100000000)) -> 1.6455595 | F28: =(数据与来源!$G$38/100000000)/((数据与来源!$G$39/100000000)+(数据与来源!$G$40/100000000)) -> 1.3181337 | G28: =(数据与来源!$H$38/100000000)/((数据与来源!$H$39/100000000)+(数据与来源!$H$40/100000000)) -> 1.1633051 | H28: =(数据与来源!$I$38/100000000)/((数据与来源!$I$39/100000000)+(数据与来源!$I$40/100000000)) -> 1.3479337 | I28: =((数据与来源!$G$38+数据与来源!$I$38-数据与来源!$H$38)/100000000)/(((数据与来源!$G$39+数据与来源!$I$39-数据与来源!$H$39)/100000000)+((数据与来源!$G$40+数据与来源!$I$40-数据与来源!$H$40)/100000000)) -> 1.4070727 | J28: >1说明仍在扩产（海外工厂建设）
A29: 三、营运资金与资产负债（时点数）
A30: 应收账款+应收票据 | B30: — | C30: =(数据与来源!$D$46/100000000)+N(数据与来源!$D$47)/100000000 -> 255.10941 | D30: =(数据与来源!$E$46/100000000)+N(数据与来源!$E$47)/100000000 -> 314.73073 | E30: =(数据与来源!$F$46/100000000)+N(数据与来源!$F$47)/100000000 -> 386.74702 | F30: =(数据与来源!$G$46/100000000)+N(数据与来源!$G$47)/100000000 -> 335.48192 | G30: — | H30: =(数据与来源!$I$46/100000000)+N(数据与来源!$I$47)/100000000 -> 425.88428 | I30: =(数据与来源!$I$46/100000000)+N(数据与来源!$I$47)/100000000 -> 425.88428 | J30: 2021无票据数据
A31: 存货 | B31: =(数据与来源!$C$48/100000000) -> 399.1395 | C31: =(数据与来源!$D$48/100000000) -> 415.87786 | D31: =(数据与来源!$E$48/100000000) -> 395.24007 | E31: =(数据与来源!$F$48/100000000) -> 431.89856 | F31: =(数据与来源!$G$48/100000000) -> 468.48791 | G31: — | H31: =(数据与来源!$I$48/100000000) -> 453.17406 | I31: =(数据与来源!$I$48/100000000) -> 453.17406
A32: 应付账款+应付票据 | B32: =(数据与来源!$C$49/100000000)+N(数据与来源!$C$50)/100000000 -> 423.63219 | C32: =(数据与来源!$D$49/100000000)+N(数据与来源!$D$50)/100000000 -> 669.83872 | D32: =(数据与来源!$E$49/100000000)+N(数据与来源!$E$50)/100000000 -> 721.78963 | E32: =(数据与来源!$F$49/100000000)+N(数据与来源!$F$50)/100000000 -> 758.85642 | F32: =(数据与来源!$G$49/100000000)+N(数据与来源!$G$50)/100000000 -> 774.15404 | G32: — | H32: =(数据与来源!$I$49/100000000)+N(数据与来源!$I$50)/100000000 -> 842.48053 | I32: =(数据与来源!$I$49/100000000)+N(数据与来源!$I$50)/100000000 -> 842.48053 | J32: 供应链占款是现金流的重要来源
A33: 存货/营收 | B33: =B31/B6 -> 0.17575045 | C33: =C31/C6 -> 0.17073639 | D33: =D31/D6 -> 0.14414061 | E33: =E31/E6 -> 0.15100541 | F33: =F31/F6 -> 0.15495052 | G33: — | H33: — | I33: =I31/I6 -> 0.15208827 | J33: TTM用2026-06-30存货÷TTM营收
A34: 现金+交易性金融资产 | B34: =(数据与来源!$C$44/100000000)+N(数据与来源!$C$45)/100000000 -> 460.97334 | C34: =(数据与来源!$D$44/100000000)+N(数据与来源!$D$45)/100000000 -> 546.82125 | D34: =(数据与来源!$E$44/100000000)+N(数据与来源!$E$45)/100000000 -> 582.12958 | E34: =(数据与来源!$F$44/100000000)+N(数据与来源!$F$45)/100000000 -> 568.33572 | F34: =(数据与来源!$G$44/100000000)+N(数据与来源!$G$45)/100000000 -> 496.55928 | G34: — | H34: =(数据与来源!$I$44/100000000)+N(数据与来源!$I$45)/100000000 -> 586.08784 | I34: =(数据与来源!$I$44/100000000)+N(数据与来源!$I$45)/100000000 -> 586.08784
A35: 有息负债(宽口径) | B35: =(数据与来源!$C$52+数据与来源!$C$53+数据与来源!$C$54+数据与来源!$C$55)/100000000 -> 242.23855 | C35: =(数据与来源!$D$52+数据与来源!$D$53+数据与来源!$D$54+数据与来源!$D$55)/100000000 -> 295.57841 | D35: =(数据与来源!$E$52+数据与来源!$E$53+数据与来源!$E$54+数据与来源!$E$55)/100000000 -> 333.06962 | E35: =(数据与来源!$F$52+数据与来源!$F$53+数据与来源!$F$54+数据与来源!$F$55)/100000000 -> 399.79482 | F35: =(数据与来源!$G$52+数据与来源!$G$53+数据与来源!$G$54+数据与来源!$G$55)/100000000 -> 407.65568 | G35: — | H35: =(数据与来源!$I$52+数据与来源!$I$53+数据与来源!$I$54+数据与来源!$I$55)/100000000 -> 424.79131 | I35: =(数据与来源!$I$52+数据与来源!$I$53+数据与来源!$I$54+数据与来源!$I$55)/100000000 -> 424.79131 | J35: 短借+一年内到期+长借+债券；港股中报口径借款383.2亿
A36: 净金融资产(不含租赁) | B36: =B34-B35 -> 218.73479 | C36: =C34-C35 -> 251.24284 | D36: =D34-D35 -> 249.05996 | E36: =E34-E35 -> 168.5409 | F36: =F34-F35 -> 88.903601 | G36: — | H36: =H34-H35 -> 161.29653 | I36: =I34-I35 -> 161.29653 | J36: 正数=净现金
A37: 商誉/归母权益 | B37: =(数据与来源!$C$57/100000000)/(数据与来源!$C$61/100000000) -> 0.27288964 | C37: =(数据与来源!$D$57/100000000)/(数据与来源!$D$61/100000000) -> 0.25298243 | D37: =(数据与来源!$E$57/100000000)/(数据与来源!$E$61/100000000) -> 0.24176489 | E37: =(数据与来源!$F$57/100000000)/(数据与来源!$F$61/100000000) -> 0.24498375 | F37: =(数据与来源!$G$57/100000000)/(数据与来源!$G$61/100000000) -> 0.22999661 | G37: — | H37: =(数据与来源!$I$57/100000000)/(数据与来源!$I$61/100000000) -> 0.22005144 | I37: =(数据与来源!$I$57/100000000)/(数据与来源!$I$61/100000000) -> 0.22005144 | J37: GEA、Candy、Fisher&Paykel、开利商用冷链等并购形成
A38: 资产负债率 | B38: =(数据与来源!$C$60/100000000)/(数据与来源!$C$59/100000000) -> 0.62673753 | C38: =(数据与来源!$D$60/100000000)/(数据与来源!$D$59/100000000) -> 0.59854585 | D38: =(数据与来源!$E$60/100000000)/(数据与来源!$E$59/100000000) -> 0.58811317 | E38: =(数据与来源!$F$60/100000000)/(数据与来源!$F$59/100000000) -> 0.59137646 | F38: =(数据与来源!$G$60/100000000)/(数据与来源!$G$59/100000000) -> 0.57410716 | G38: — | H38: =(数据与来源!$I$60/100000000)/(数据与来源!$I$59/100000000) -> 0.5852178 | I38: =(数据与来源!$I$60/100000000)/(数据与来源!$I$59/100000000) -> 0.5852178
A39: 每股净资产(元) | B39: =(数据与来源!$C$61/100000000)/(数据与来源!$C$33/数据与来源!$C$35/100000000) -> 8.6230106 | C39: =(数据与来源!$D$61/100000000)/(数据与来源!$D$33/数据与来源!$D$35/100000000) -> 10.037069 | D39: =(数据与来源!$E$61/100000000)/(数据与来源!$E$33/数据与来源!$E$35/100000000) -> 10.921872 | E39: =(数据与来源!$F$61/100000000)/(数据与来源!$F$33/数据与来源!$F$35/100000000) -> 12.054496 | F39: =(数据与来源!$G$61/100000000)/(数据与来源!$G$33/数据与来源!$G$35/100000000) -> 12.8698 | G39: — | H39: =(数据与来源!$I$61/100000000)/数据与来源!$B$15 -> 12.935291 | I39: =(数据与来源!$I$61/100000000)/数据与来源!$B$15 -> 12.935291 | J39: 历年用归母净利/EPS推得的加权股数；2026H1用在外股数

Sheet 分红与回报
A1: 分红与股东回报：DPS、派息率、A/H收息对比、回购
A2: A股口径每股税前股利（元）。派息率(计算)=合计DPS/基本EPS；披露值来自公司公告。2026E为模型假设，未宣告。股息率以2026-10-20现价计算。
A4: 财年 | B4: 中期DPS | C4: 末期DPS | D4: 合计DPS | E4: 基本EPS | F4: 派息率(计算) | G4: 派息率(披露) | H4: 状态 | I4: A股现价股息率 | J4: 来源
A5: 2021 | B5: 0 | C5: 0.46136 | D5: =B5+C5 -> 0.46136 | E5: =数据与来源!$C$35 -> 1.41 | F5: =D5/E5 -> 0.32720567 | G5: 未取得 | H5: 已实施 | I5: =D5/数据与来源!$B$7 -> 0.02294182 | J5: 华盛通分红记录(第三方，派息日2022-08-23)；披露派息率未取得
A6: 2022 | B6: 0 | C6: 0.56692 | D6: =B6+C6 -> 0.56692 | E6: =数据与来源!$D$35 -> 1.58 | F6: =D6/E6 -> 0.35881013 | G6: 0.3601 | H6: 已实施 | I6: =D6/数据与来源!$B$7 -> 0.02819095 | J6: 2022年度利润分配预案(派息率36.01%)及2023-08-15调整公告
A7: 2023 | B7: 0 | C7: 0.80131 | D7: =B7+C7 -> 0.80131 | E7: =数据与来源!$E$35 -> 1.79 | F7: =D7/E7 -> 0.44765922 | G7: 未取得 | H7: 已实施 | I7: =D7/数据与来源!$B$7 -> 0.039846345 | J7: 2023年年度A股权益分派实施公告(上证报2024-08-10)
A8: 2024 | B8: 0 | C8: 0.96504 | D8: =B8+C8 -> 0.96504 | E8: =数据与来源!$F$35 -> 2.02 | F8: =D8/E8 -> 0.47774257 | G8: 0.4801 | H8: 已实施 | I8: =D8/数据与来源!$B$7 -> 0.047988066 | J8: 2024年年度A股权益分派实施公告(上证报2025-07-19)；派息率48.01%
A9: 2025 | B9: 0.2692 | C9: 0.89151 | D9: =B9+C9 -> 1.16071 | E9: =数据与来源!$G$35 -> 2.12 | F9: =D9/E9 -> 0.54750472 | G9: 0.55 | H9: 已实施 | I9: =D9/数据与来源!$B$7 -> 0.057718051 | J9: 2025中期实施公告(上证报2025-11-01)；2025年度实施公告(上证报2026-08-15)；合计派息率55.0%
A10: 2026E | B10: 0 | C10: =估值模型!F58 -> 1.1597392 | D10: =B10+C10 -> 1.1597392 | E10: =估值模型!F54 -> 1.9995503 | F10: =D10/E10 -> 0.58 | G10: 规划≥58% | H10: 假设(未宣告) | I10: =D10/数据与来源!$B$7 -> 0.057669775 | J10: 2026年中报明确不派中期股息；全年按当前情景正常化净利×派息率估算，需等2026年报确认
A12: A股 vs H股：个人投资者收息对比（同股同息，税负不同）
A13: 项目 | B13: A股 | C13: H股 | E13: 说明
A14: 现价(元) | B14: =数据与来源!$B$7 -> 20.11 | C14: =数据与来源!$B$10 -> 17.07698 | E14: H股按港元×汇率折算
A15: LTM税前DPS(元) | B15: =D9 -> 1.16071 | C15: =D9 -> 1.16071 | E15: 过去12个月实际派发：2025中期(2025-11) + 2025末期(2026-08)
A16: 税前股息率 | B16: =B15/B14 -> 0.057718051 | C16: =C15/C14 -> 0.067969278
A17: 个人股息税率 | B17: 0 | C17: 0.2 | E17: A股持股>1年免征；港股通个人持有H股由公司按20%代扣（以实际政策为准，可修改）
A18: 税后股息率 | B18: =B16*(1-B17) -> 0.057718051 | C18: =C16*(1-C17) -> 0.054375422 | E18: 红利账户实际到手口径
A19: 2026E税前股息率(当前情景) | B19: =D10/B14 -> 0.057669775 | C19: =D10/C14 -> 0.067912428 | E19: 模型估算，非公司宣告
A21: 分红能被现金覆盖吗？（亿元）
A22: 财年 | B22: 归母净利 | C22: 分红总额(估算) | D22: 自由现金流 | E22: 所有者收益代理 | F22: FCF覆盖倍数 | G22: 所有者收益覆盖 | J22: 说明
A23: 2022 | B23: =财务五年!C12 -> 147.12055 | C23: =F6*B23 -> 52.788342 | D23: =财务五年!C23 -> 120.46771 | E23: =财务五年!C25 -> 111.34573 | F23: =D23/C23 -> 2.2820893 | G23: =E23/C23 -> 2.1092863
A24: 2023 | B24: =财务五年!D12 -> 165.96615 | C24: =F7*B24 -> 74.296277 | D24: =财务五年!D23 -> 159.94219 | E24: =财务五年!D25 -> 139.8111 | F24: =D24/C24 -> 2.1527618 | G24: =E24/C24 -> 1.8818049
A25: 2024 | B25: =财务五年!E12 -> 187.31046 | C25: =F8*B25 -> 89.486183 | D25: =财务五年!E23 -> 162.38024 | E25: =财务五年!E25 -> 141.00246 | F25: =D25/C25 -> 1.8145845 | G25: =E25/C25 -> 1.5756897
A26: 2025 | B26: =财务五年!F12 -> 195.52798 | C26: =F9*B26 -> 107.05249 | D26: =财务五年!F23 -> 171.51378 | E26: =财务五年!F25 -> 149.05605 | F26: =D26/C26 -> 1.6021465 | G26: =E26/C26 -> 1.3923641 | J26: 分红总额≈派息率(计算)×归母净利；2025年披露约107.5亿(中期约25亿+末期82.48亿)
A28: 回购与股本：用于员工持股，非注销（研究判断：只按部分股东回报看待）
A29: 时间 | B29: 事项 | J29: 来源
A30: 2026-03 | B30: A股回购方案：30–60亿元，集中竞价，1年内实施，用途为员工持股计划；另获H股≤10%、D股≤5%回购授权 | J30: 公司公告(搜狐转述)/第一财经
A31: 2026-03→2026-08 | B31: A股回购专户：74,541,486股 → 124,683,686股（净增约5,014万股） | J31: 观点网：调整2025年度每股分配比例
A32: 2025末→2026H1 | B32: 库存股账面：42.61亿元 → 55.97亿元（+13.36亿元） | J32: 资产负债表
A33: 判断 | B33: 回购股份未来用于员工持股会重新流通，不像注销那样永久减少股数；估值用在外股数，并在风险表监控稀释。 | J33: 研究判断

Sheet 生意拆解
A1: 生意拆解：海尔怎么赚钱？
A2: 收入≈一半中国、一半海外；海外最大的是北美GE Appliances。产品上冰箱、洗衣机是份额最高的现金牛，暖通(空调/水)是增长最快的板块。
A4: 一句话
A5: 海尔把冰箱、洗衣机、空调、厨电、热水器等耐用家电卖给全球家庭：国内靠“海尔+卡萨帝(高端)+统帅(性价比)”多品牌和自有渠道、份额第一的冰洗赚取稳定利润；海外通过收购GE Appliances(美)、Fisher&Paykel(新西兰)、Candy(意)及自建品牌做本土化研发-制造-营销，北美是最大利润池。利润 = 销量 × 均价(高端占比) × 毛利率(原材料/关税/汇率) − 渠道与品牌费用；现金还来自对上游供应商的票据与应付占款。
A7: 2025年分产业收入（亿元）
A8: 产业 | B8: 收入(亿元) | C8: 同比 | D8: 占比 | E8: 观察
A9: =数据与来源!A69 -> 冰箱/冷柜 | B9: =数据与来源!B69 -> 847.6 | C9: =数据与来源!C69 -> 0.014 | D9: =B9/SUM($B$9:$B$13) -> 0.32079328 | E9: 国内冰箱线上/线下零售份额超40%（2026H1）
A10: =数据与来源!A70 -> 洗护 | B10: =数据与来源!B70 -> 655.7 | C10: =数据与来源!C70 -> 0.035 | D10: =B10/SUM($B$9:$B$13) -> 0.24816441 | E10: “懒人三筒”等高端单品放量；国内洗衣机线下份额约48.8%
A11: =数据与来源!A71 -> 厨电 | B11: =数据与来源!B71 -> 415.4 | C11: =数据与来源!C71 -> 0.009 | D11: =B11/SUM($B$9:$B$13) -> 0.15721747 | E11: 国内厨电零售2026H1+10.8%，但基数小
A12: =数据与来源!A72 -> 智慧大暖通：空气 | B12: =数据与来源!B72 -> 543.9 | C12: =数据与来源!C72 -> 0.096 | D12: =B12/SUM($B$9:$B$13) -> 0.20585118 | E12: 增长主力：2025+9.6%；2026H1大暖通+6.1%、分部利润+26.8%；铜价与冷媒涨价压毛利
A13: =数据与来源!A73 -> 智慧大暖通：全屋用水 | B13: =数据与来源!B73 -> 179.6 | C13: =数据与来源!C73 -> 0.111 | D13: =B13/SUM($B$9:$B$13) -> 0.067973658 | E13: 热水器、净水；收购南非Kwikot后份额提升
A14: 注：上述产业合计约2642亿，低于总收入3023亿，差额为装备部品、渠道综合服务等其他业务。
A16: 分地区（2024年金额 + 2025年增速）
A17: 地区 | B17: 2024收入(亿元) | C17: 2024同比 | D17: 占比 | E17: 2025/2026动态
A18: =数据与来源!E69 -> 中国 | B18: =数据与来源!F69 -> 1417 | C18: =数据与来源!G69 -> 0.0312 | D18: =B18/SUM($B$18:$B$22) -> 0.4962979 | E18: 2025年+3.1%；2026H1收入承压；以旧换新补贴退坡、9月行业零售额-13%、均价-11%
A19: =数据与来源!E70 -> 北美 | B19: =数据与来源!F70 -> 795.29 | C19: =数据与来源!G70 -> 未披露 | D19: =B19/SUM($B$18:$B$22) -> 0.27854676 | E19: GEA：2025高端品牌+7%；2026Q1受暴雪、行业需求-10%、关税成本拖累；Q2美元收入恢复增长；工厂整合2027–28年完成
A20: =数据与来源!E71 -> 欧洲 | B20: =数据与来源!F71 -> 320.89 | C20: =数据与来源!G71 -> 0.1242 | D20: =B20/SUM($B$18:$B$22) -> 0.11239029 | E20: 2025年+19.9%；2026H1+4.9%，暖通与商用冷链双位数
A21: =数据与来源!E72 -> 南亚 | B21: =数据与来源!F72 -> 115.25 | C21: =数据与来源!G72 -> 0.2105 | D21: =B21/SUM($B$18:$B$22) -> 0.040365796 | E21: 2025年+23.2%；2026H1+17.1%（印度+20%、巴基斯坦+30%）；2025年底出售海尔印度49%股权
A22: =数据与来源!E73 -> 其他海外(倒算) | B22: =数据与来源!F73 -> 206.71 | C22: =数据与来源!G73 -> 未披露 | D22: =B22/SUM($B$18:$B$22) -> 0.072399252 | E22: 东南亚2025+13.4%、日本+10.3%、中东非+55.8%
A24: 利润驱动与资本需求
A25: 收入 | B25: 国内：存量更新为主（保有量超40亿台），补贴从“扩量”转“稳量”；海外：北美需求疲弱、新兴市场高增
A26: 毛利率 | B26: 2025年26.7%（-1.1pct）；2026H1回升至27.2%。铜价较2025初涨超40%、R32冷媒同比涨超80%；关税成本；套保与自制零部件对冲
A27: 费用 | B27: 销售费用率约11%：国内转直达用户（直单占比约65%）短期抬费用；研发费用率约3.3–3.6%，2026H1压降SKU
A28: 汇兑 | B28: 海外收入占约一半：2026H1汇兑净损失约7.04亿（上年同期为收益），是利润下滑最大单项
A29: 资本开支 | B29: 2023–2025年88–105亿/年，高于固定资产折旧+无形摊销（约55–67亿）：海外12个供应链项目建设；2026H1 43.7亿
A30: 营运资金 | B30: 2026H1应付账款+应付票据约842亿，接近应收(约426亿)+存货(约453亿)之和；对供应商的占款是CFO高于净利润的重要原因，行业下行时可能反向流出

Sheet 巴菲特框架
A1: 巴菲特框架：八问筛选 + 护城河 + 管理层
A2: 结论为“通过 / 存疑 / 未通过 / 证据不足”，未知不当通过，也不机械按失败题数否决。底色：浅绿=事实依据，浅紫=研究判断，浅红=风险。
A4: 1. 八问快速筛选
A5: # | B5: 问题 | C5: 结论 | D5: 依据（事实→判断） | E5: 反证 / 待核实
A6: 1 | B6: 能解释怎么赚钱吗？ | C6: 通过 | D6: 卖白电给全球家庭；收入、产品、地区结构清晰；利润由销量×均价×毛利率−费用决定。 | E6: 海外子公司（尤其GEA）利润未单独披露，北美盈利能力需从管理层表述推断
A7: 2 | B7: 十年后仍有需求吗？ | C7: 通过 | D7: 冰洗空是生活必需耐用品，更新需求刚性；新兴市场渗透率仍低；暖通、水、商用冷链扩大赛道。 | E7: 国内保有量饱和（户均超8台），增长主要靠更新与结构升级
A8: 3 | B8: 对手难复制什么？ | C8: 存疑 | D8: 冰洗份额第一（线上/线下>40%）、卡萨帝高端品牌、全球本土化研发-制造-渠道网络、规模采购。 | E8: 空调份额远低于美的格力；家电技术可复制，价格战下护城河更多是规模与渠道而非不可替代
A9: 4 | B9: 有定价或成本优势吗？ | C9: 存疑 | D9: 高端占比高支撑毛利率27%左右（高于多数同行）；2026H1毛利率逆势+0.4pct。 | E9: 2025年毛利率-1.1pct；美国关税成本难完全转嫁（花旗/里昂）；国内9月行业均价-11%
A10: 5 | B10: 利润能变现金吗？ | C10: 通过 | D10: 2021–2025累计CFO≈1223亿，为同期归母净利(827亿)的1.48倍；扣全部资本开支与租赁后仍有约140–150亿/年。 | E10: CFO部分来自对供应商的应付/票据占款；资本开支仍高于折旧
A11: 6 | B11: 压力情景能存活吗？ | C11: 通过 | D11: 2026-06-30现金+交易性金融资产约586亿，宽口径有息负债约425亿，净现金约161亿；利息覆盖充足。 | E11: 收入下滑30%时，应付占款回流可能消耗大量现金（需看行业下行期营运资金）
A12: 7 | B12: 管理层可信吗？ | C12: 存疑 | D12: 持续提高派息率(32%→55%)并给出58%/60%承诺；审计与披露规范；国际并购整合(GEA)总体成功。 | E12: 海尔集团合计持股约34%，关联交易与集团财务公司往来需持续跟踪；回购用于员工持股而非注销
A13: 8 | B13: 价格有余地吗？ | C13: 存疑 | D13: 基准加权价值约24.4元/股；A股20.11元对应约18%安全边际，H股(折约17.1元)约30%。 | E13: A股未达25%要求安全边际；三季报若利润继续下滑，基准价值需下调
A15: 2. 护城河：证据、反证、趋势与可证伪指标
A16: # | B16: 类型 | C16: 强度/趋势 | D16: 证据 | E16: 可证伪指标（跌破即下调判断）
A17: 1 | B17: 品牌与高端定位 | C17: 中强 / 稳定 | D17: 卡萨帝高端；国内冰洗零售份额>40%；2025年Leader品牌收入超100亿(+30%)。 | E17: 国内冰箱/洗衣机线下份额跌破35%；毛利率连续两年<25%
A18: 2 | B18: 全球本土化网络 | C18: 中强 / 增强 | D18: 北美GEA、欧洲Candy/Hoover、澳新F&P、南亚/东南亚自建；海外收入约50%，新兴市场高增。 | E18: 海外收入连续两年负增长；北美份额下降
A19: 3 | B19: 规模与供应链成本 | C19: 中 / 稳定 | D19: 年收入3000亿级采购规模；SKU压降18%、零部件共享、区域化供应链；原材料套保。 | E19: 毛利率改善持续落后美的；原材料上涨期毛利率下滑幅度大于同行
A20: 4 | B20: 渠道与用户直达 | C20: 中 / 变化中 | D20: 国内直单占比约65%（+8pct），统仓统配订单占64%，破损更换周期15.3天→3.3天。 | E20: 渠道改革期销售费用率持续>12%且收入不增长
A21: 5 | B21: 技术/产品壁垒 | C21: 弱–中 | D21: 持续推出爆品(冰立方、懒人三筒)，但家电技术可复制、迭代快。 | E21: 爆品生命周期<2年、价格带份额回落
A22: 护城河总评（研究判断）：中等、偏规模与渠道型的护城河。它让海尔在行业下行时比二三线品牌更稳、现金流更好，但还不足以在关税、补贴退坡、原材料暴涨时完全守住利润率——所以估值上不给“消费品牌”溢价，按成熟制造业的10–14倍看。
A24: 3. 管理层与资本配置
A25: # | B25: 维度 | C25: 评价 | D25: 事实 | E25: 关注点
A26: 1 | B26: 分红 | C26: 良 | D26: 派息率2021约33%→2022年36%→2024年48%→2025年55%；2026–2028规划≥58%/60%/60%。 | E26: 派息率提升快于利润增长，后续增长空间有限
A27: 2 | B27: 回购 | C27: 中 | D27: 2026年A股回购30–60亿；但用于员工持股，非注销。 | E27: 员工持股解锁与考核目标；是否转为注销
A28: 3 | B28: 并购整合 | C28: 良 | D28: GEA(2016)整合后成为最大利润池；2024年收购开利商用冷链，2025年收购南非Kwikot。 | E28: 商誉约263亿（占归母权益约22%），北美若长期失速有减值风险
A29: 4 | B29: 治理结构 | C29: 中 | D29: 海尔集团及一致行动人合计约33.9%（按2025年报前十大股东计算）；A+H+D三地上市，信息披露较充分。 | E29: 集团关联交易、集团财务公司存款等需在年报附注逐年核对（本次未逐项核查）
A30: 5 | B30: 资产处置 | C30: 中 | D30: 2025年底同意出售海尔印度49%股权给Bharti/华平；2026H1少数股东权益上升。 | E30: 交易对价与资金用途未取得；印度增长的利润将部分归少数股东

Sheet 风险与跟踪
A1: 风险与跟踪：最可能造成永久损失的路径 + 季度监控清单
A2: 监控写成“指标—当前值—触发条件—后续核查”。触发不等于卖出，而是“重新估值”的信号。
A4: 1. 三条永久损失路径
A5: # | B5: 风险 | C5: 机制 | D5: 当前迹象 | E5: 对估值的影响 | F5: 缓冲/对冲
A6: 1 | B6: 北美利润池受损 | C6: 美国关税成本、需求疲弱（2026Q1行业-10%）与竞争（LG/三星/惠而浦）叠加，GEA利润率长期下台阶；北美约占收入1/4以上且商誉集中。 | D6: Q1北美拖累；Q2美元收入恢复增长 | E6: 所有者收益下调10–20亿，价值约-1.5~-2.5元 | F6: GEA本土制造为主；工厂整合2027–28完成；关税退款
A7: 2 | B7: 国内需求与价格战 | C7: 以旧换新补贴退坡后需求透支，行业量价齐跌（9月零售额-13%、均价-11%），高端占比与毛利率被迫让步。 | D7: 2026H1国内收入下滑 | E7: 正常化净利降至165亿以下，进入悲观情景 | F7: 冰洗份额领先、高端占比高、直达用户降本
A8: 3 | B8: 成本/汇率挤压+资本开支不降 | C8: 铜、冷媒等原材料上涨，汇兑损失，同时海外扩产资本开支维持高位，所有者收益长期低于利润的75%。 | D8: 2026H1汇兑净损失7.04亿；资本开支43.7亿 | E8: DCF价值对所有者收益高度敏感 | F8: 套保、区域化供应链、SKU压降
A10: 2. 季度监控清单
A11: # | B11: 指标 | C11: 为什么重要 | D11: 当前值 | E11: 触发条件 | F11: 后续核查
A12: 1 | B12: 营收同比（2026H1） | C12: 量价是否企稳 | D12: =财务五年!H7 -> -0.027981796 | E12: 连续两个季度<-5% | F12: 拆国内/北美/欧洲/新兴市场
A13: 2 | B13: 毛利率 | C13: 定价权与成本转嫁 | D13: =财务五年!H8 -> 0.27229326 | E13: 单季<25% | F13: 原材料、关税、价格战哪个主导
A14: 3 | B14: 扣非归母净利(TTM，亿元) | C14: 正常化利润基准 | D14: =财务五年!I14 -> 161.99974 | E14: <160亿 | F14: 下调正常化净利假设至悲观
A15: 4 | B15: 经营现金流/净利润(TTM) | C15: 利润含金量 | D15: =财务五年!I21 -> 1.3267189 | E15: <1.0x | F15: 应付票据/应付账款是否回流
A16: 5 | B16: 资本开支(TTM，亿元) | C16: 所有者收益是否改善 | D16: =财务五年!I22 -> 94.538904 | E16: >100亿且收入不增 | F16: 海外项目投产节奏
A17: 6 | B17: 净金融资产(亿元) | C17: 安全垫 | D17: =财务五年!H36 -> 161.29653 | E17: <50亿 | F17: 并购、回购、分红资金来源
A18: 7 | B18: 派息率 | C18: 红利承诺兑现 | D18: =分红与回报!F9 -> 0.54750472 | E18: 2026年度<58% | F18: 对照股东回报规划
A19: 8 | B19: 回购进度/用途 | C19: 股东回报真实性 | D19: 30–60亿方案进行中 | E19: 到期完成<30亿或用途变更 | F19: 是否注销、员工持股考核目标
A20: 9 | B20: 商誉(亿元) | C20: 并购资产健康度 | D20: =数据与来源!$I$57/100000000 -> 263.35394 | E20: 出现大额减值 | F20: GEA/Candy分部盈利
A21: 10 | B21: H股相对A股折价 | C21: 选择更便宜的份额 | D21: =数据与来源!$B$11 -> -0.15082148 | E21: 折价<5% | F21: A/H择优：考虑股息税差
A23: 3. 期后事件与下一步
A24: • 2026年三季报（预计10月底前披露）：重点看Q3单季收入能否延续Q2的正增长、毛利率是否守住27%、汇兑与关税退款对非经常性损益的影响。
A25: • 管理层全年目标：收入与净利（含关税退款）大致持平≈195亿。若前三季度归母净利明显低于150亿，基准情景185亿需要下调。
A26: • 10月国内零售数据（奥维云网）与美国AHAM出货：判断补贴退坡后需求是否见底。
A27: • 持有/卖出四项检验：①价格>基准价值 ②生意恶化（上表触发≥3项）③诚信受损 ④出现更优机会（需明确可比对象，如同为红利家电的格力电器）。

Sheet 同业比较
A1: 同业比较：家电龙头估值量级
A2: 海尔一行为本模型自算（TTM），并列出第三方行情页口径供对照；同业为中财网行情页口径（日期见表）。仅作量级参考，不参与内在价值计算。
A4: 公司 | B4: 代码 | C4: 股价(元) | D4: 日期 | E4: PE | F4: PE(扣非) | G4: PB | H4: 备注
A5: 海尔智家（本模型TTM） | B5: 600690 | C5: =数据与来源!$B$7 -> 20.11 | D5: 2026-10-20 | E5: =数据与来源!$B$16/财务五年!I12 -> 10.43164 | F5: =数据与来源!$B$16/财务五年!I14 -> 11.485163 | G5: =数据与来源!$B$7/财务五年!H39 -> 1.5546615 | H5: 市值按A股价×在外股数；TTM归母178亿/扣非162亿；BPS=2026H1
A6: =数据与来源!A82 -> 美的集团 | B6: =数据与来源!B82 -> 000333 | C6: =数据与来源!C82 -> 86.54 | D6: =数据与来源!D82 -> 2026-10-19 | E6: =数据与来源!E82 -> 14.88 | F6: =数据与来源!F82 -> 19.07 | G6: =数据与来源!G82 -> 2.92 | H6: 第三方口径
A7: =数据与来源!A83 -> 格力电器 | B7: =数据与来源!B83 -> 000651 | C7: =数据与来源!C83 -> 39.49 | D7: =数据与来源!D83 -> 2026-10-16 | E7: =数据与来源!E83 -> 7.94 | F7: =数据与来源!F83 -> 8.36 | G7: =数据与来源!G83 -> 1.45 | H7: 第三方口径
A8: =数据与来源!A84 -> 老板电器 | B8: =数据与来源!B84 -> 002508 | C8: =数据与来源!C84 -> 17.05 | D8: =数据与来源!D84 -> 2026-10-19 | E8: =数据与来源!E84 -> 14.35 | F8: =数据与来源!F84 -> 15.74 | G8: =数据与来源!G84 -> 1.38 | H8: 第三方口径
A9: =数据与来源!A85 -> 海尔智家(行情页口径) | B9: =数据与来源!B85 -> 600690 | C9: =数据与来源!C85 -> 20.11 | D9: =数据与来源!D85 -> 2026-10-20 | E9: =数据与来源!E85 -> 10.48 | F9: =数据与来源!F85 -> 11.54 | G9: =数据与来源!G85 -> 1.45 | H9: 行情页口径，与自算TTM接近
A11: 解读（研究判断）：海尔估值位于格力（低PE、高股息、空调单一）与美的（多元化、ToB与机器人、更高ROE）之间。市场给海尔约10倍TTM、11.5倍扣非TTM，反映对北美关税和国内补贴退坡的担忧；同业PE口径（静态/TTM）不统一，不宜直接用于定价。

Sheet 数据与来源
A1: 数据与来源：原始数据底稿
A2: 金额单位：元（原始值，未四舍五入）；每股：元/股。蓝字为可更新输入；其他表格全部从这里引用。研究截止日 2026-10-20；最新财报为2026年半年度报告（2026-08-28披露），2026年三季报尚未披露。
A3: 输入/可改 | B3: 公式计算 | C3: 跨表引用 | D3: 分析假设 | E3: 风险/警示
A5: A. 市场与股本（更新股价只需改本区蓝字）
A6: 指标 | B6: 数值 | C6: 单位 | D6: 日期 | E6: 来源/口径
A7: A股收盘价 | B7: 20.11 | C7: 元/股 | D7: 2026-10-20 | E7: 中财网/华盛通行情，当日-3.13%（延时行情）
A8: H股收盘价 | B8: 19.64 | C8: 港元/股 | D8: 2026-10-20 | E8: 华盛通行情，当日-2.39%
A9: 港元兑人民币 | B9: 0.8695 | C9: CNY/HKD | D9: 2026-08 | E9: 由2025末期股息换算推得：RMB0.89151=HKD1.0253105；可替换为最新汇率
A10: H股股价折人民币 | B10: =B8*B9 -> 17.07698 | C10: 元/股 | D10: 计算 | E10: H股价×汇率
A11: H股相对A股溢(折)价 | B11: =B10/B7-1 -> -0.15082148 | C11: % | D11: 计算 | E11: 负数=H股折价
A12: 流通在外股数（扣回购专户） | B12: 9252080366 | C12: 股 | D12: 2026-08-20 | E12: 2025年度分配实际参与股数（A+H+D），观点网/实施公告
A13: 总股本 | B13: 9377629650 | C13: 股 | D13: 2026-06-30 | E13: 2026年中报资产负债表股本
A14: A股回购专户股份 | B14: 124683686 | C14: 股 | D14: 2026-08 | E14: 2025年度A股权益分派实施公告
A15: 估值用股数 | B15: =B12/100000000 -> 92.520804 | C15: 亿股 | D15: 计算 | E15: 用扣除回购专户后的在外股数；回购股份用于员工持股，未来可能重新流通
A16: A股价计全部股份市值 | B16: =B7*B15 -> 1860.5934 | C16: 亿元 | D16: 计算 | E16: 简化：全部股份按A股价计；H股实际更便宜
A17: 研究截止日 | B17: 2026-10-20 | E17: 仅使用此日前已发布信息
A18: 最新财报 | B18: 2026年半年度报告 | D18: 2026-08-28 | E18: 截至2026-06-30；三季报预计10月底前披露（未发布）
A21: B. 财务原始数据（合并报表，中国会计准则；单位：元）
A22: 项目 | B22: 2020 | C22: 2021 | D22: 2022 | E22: 2023 | F22: 2024 | G22: 2025 | H22: 2025H1 | I22: 2026H1 | J22: 口径/来源
A23: 营业收入 | B23: 2.0972343e+11 | C23: 2.2710582e+11 | D23: 2.4357892e+11 | E23: 2.7420452e+11 | F23: 2.8601529e+11 | G23: 3.0234678e+11 | H23: 1.5649403e+11 | I23: 1.5211505e+11 | J23: 利润表；东方财富F10(取自定期报告，2024为重述后)
A24: 营业成本 | B24: 1.4747192e+11 | C24: 1.5594955e+11 | D24: 1.6726334e+11 | E24: 1.9883847e+11 | F24: 2.0643944e+11 | G24: 2.2173875e+11 | H24: 1.1443793e+11 | I24: 1.1069515e+11 | J24: 利润表；2023起部分费用重分类进成本，2022及以前毛利率不完全可比
A25: 销售费用 | B25: 3.3641711e+10 | C25: 3.6584439e+10 | D25: 3.8600298e+10 | E25: 3.2726736e+10 | F25: 3.360882e+10 | G25: 3.3877815e+10 | H25: 1.5816815e+10 | I25: 1.6438748e+10 | J25: 利润表
A26: 管理费用 | B26: 1.0052645e+10 | C26: 1.0471532e+10 | D26: 1.0846347e+10 | E26: 1.1874421e+10 | F26: 1.2134987e+10 | G26: 1.3762454e+10 | H26: 5.8910469e+09 | I26: 6.0245545e+09 | J26: 利润表
A27: 研发费用 | B27: 6.8528614e+09 | C27: 8.3638689e+09 | D27: 9.5073848e+09 | E27: 1.038022e+10 | F27: 1.0769896e+10 | G27: 1.0095934e+10 | H27: 5.7904368e+09 | I27: 5.071692e+09 | J27: 利润表
A28: 财务费用 | B28: 1.1961993e+09 | C28: 6.8472162e+08 | D28: -2.4175222e+08 | E28: 5.0565853e+08 | F28: 9.7207843e+08 | G28: -50959124 | H28: -3.5085756e+08 | I28: 1.1033887e+09 | J28: 利润表；含汇兑损益。2026H1汇兑净损失约7.04亿(上年同期收益)
A29: 其中：利息费用 | B29: 1.3270914e+09 | C29: 7.1246277e+08 | D29: 9.8803637e+08 | E29: 2.1654676e+09 | F29: 2.7273135e+09 | G29: 2.6794842e+09 | H29: 1.4466157e+09 | I29: 9.6454081e+08 | J29: 利润表附注口径
A30: 利润总额 | B30: 1.3562279e+10 | C30: 1.5937513e+10 | D30: 1.7791136e+10 | E30: 2.0211644e+10 | F30: 2.2722719e+10 | G30: 2.3478744e+10 | H30: 1.4997056e+10 | I30: 1.3071174e+10 | J30: 利润表
A31: 所得税 | B31: 2.2331265e+09 | C31: 2.7052539e+09 | D31: 3.0578229e+09 | E31: 3.1231632e+09 | F31: 3.1571799e+09 | G31: 3.3156503e+09 | H31: 2.5119403e+09 | I31: 2.1951605e+09 | J31: 利润表
A32: 净利润(合并) | B32: 1.1329152e+10 | C32: 1.3232259e+10 | D32: 1.4733313e+10 | E32: 1.7088481e+10 | F32: 1.9565539e+10 | G32: 2.0163094e+10 | H32: 1.2485116e+10 | I32: 1.0876013e+10 | J32: 利润表
A33: 归母净利润 | B33: 8.8831291e+09 | C33: 1.3078841e+10 | D33: 1.4712055e+10 | E33: 1.6596615e+10 | F33: 1.8731046e+10 | G33: 1.9552798e+10 | H33: 1.2032996e+10 | I33: 1.0316255e+10 | J33: 利润表；2020含海尔电器私有化前少数股东影响
A34: 扣非归母净利润 | B34: 6.4578133e+09 | C34: 1.1831273e+10 | D34: 1.3962932e+10 | E34: 1.5824164e+10 | F34: 1.7804733e+10 | G34: 1.8603632e+10 | H34: 1.1702409e+10 | I34: 9.2987506e+09 | J34: 定期报告主要会计数据
A35: 基本每股收益(元/股) | B35: 1.34 | C35: 1.41 | D35: 1.58 | E35: 1.79 | F35: 2.02 | G35: 2.12 | H35: 1.3 | I35: 1.12 | J35: 定期报告
A36: 加权平均ROE(披露) | C36: 0.1726 | D36: 0.1681 | E36: 0.1724 | F36: 0.1761 | G36: 0.1698 | H36: 0.1034 | I36: 0.0836 | J36: 定期报告；2021值按2022年报'减少0.45个百分点'推算
A37: 经营活动现金流净额 | C37: 2.3235381e+10 | D37: 2.0256557e+10 | E37: 2.6535781e+10 | F37: 2.6318091e+10 | G37: 2.6002942e+10 | H37: 1.1139046e+10 | I37: 9.752034e+09 | J37: 现金流量表(合并，最新重述口径)
A38: 购建固定/无形/长期资产支付现金 | C38: 7.3724288e+09 | D38: 8.2097862e+09 | E38: 1.0541562e+10 | F38: 1.0080067e+10 | G38: 8.8515639e+09 | H38: 3.7644628e+09 | I38: 4.3667892e+09 | J38: 现金流量表
